Workbook

Sheet 信托还款明细--0929已还款
A1: 资产包编号 | B1: 当前还款方 | C1: 资产编号(房源) | D1: 托管房源编码 | E1: 计划集中还款日期 | F1: 还款期数 | G1: 当期计划还款金额 | H1: 初始受让装修金额 | I1: 累计已还款金额 | J1: 剩余应还款余额 | K1: 本期还款状态 | L1: 当期实际还款金额 | M1: 当期还款日期 | N1: 本期是否逾期 | O1: 当期逾期天数
A2: 001 | B2: 中国对外经济贸易信托有限公司 | C2: 101127075900-001 | D2: 101127075900 | E2: 45929 | F2: 1 | G2: 0 | H2: 97419 | I2: 0 | J2: =H2-I2 -> 97419 | K2: 已全额还款 | L2: 0 | M2: =E2 -> 45929 | N2: 否 | O2: 0
A3: 001 | B3: 中国对外经济贸易信托有限公司 | C3: 101127311840-001 | D3: 101127311840 | E3: 45929 | F3: 1 | G3: 1211.33 | H3: 49162 | I3: 0 | J3: =H3-I3 -> 49162 | K3: 已全额还款 | L3: 1211.33 | M3: =E3 -> 45929 | N3: 否 | O3: 0
A4: 001 | B4: 中国对外经济贸易信托有限公司 | C4: 101127339909-001 | D4: 101127339909 | E4: 45929 | F4: 1 | G4: 0 | H4: 94060 | I4: 0 | J4: =H4-I4 -> 94060 | K4: 已全额还款 | L4: 0 | M4: =E4 -> 45929 | N4: 否 | O4: 0
A5: 001 | B5: 中国对外经济贸易信托有限公司 | C5: 101127524235-001 | D5: 101127524235 | E5: 45929 | F5: 1 | G5: 2420 | H5: 50000 | I5: 0 | J5: =H5-I5 -> 50000 | K5: 已全额还款 | L5: 2420 | M5: =E5 -> 45929 | N5: 否 | O5: 0
A6: 001 | B6: 中国对外经济贸易信托有限公司 | C6: 101127626459-001 | D6: 101127626459 | E6: 45929 | F6: 1 | G6: 0 | H6: 92990 | I6: 0 | J6: =H6-I6 -> 92990 | K6: 已全额还款 | L6: 0 | M6: =E6 -> 45929 | N6: 否 | O6: 0
A7: 001 | B7: 中国对外经济贸易信托有限公司 | C7: 101127687701-001 | D7: 101127687701 | E7: 45929 | F7: 1 | G7: 0 | H7: 61372 | I7: 0 | J7: =H7-I7 -> 61372 | K7: 已全额还款 | L7: 0 | M7: =E7 -> 45929 | N7: 否 | O7: 0
A8: 001 | B8: 中国对外经济贸易信托有限公司 | C8: 101127876784-001 | D8: 101127876784 | E8: 45929 | F8: 1 | G8: 4160 | H8: 74642 | I8: 0 | J8: =H8-I8 -> 74642 | K8: 已全额还款 | L8: 4160 | M8: =E8 -> 45929 | N8: 否 | O8: 0
A9: 001 | B9: 中国对外经济贸易信托有限公司 | C9: 101127962550-001 | D9: 101127962550 | E9: 45929 | F9: 1 | G9: 2835 | H9: 84000 | I9: 0 | J9: =H9-I9 -> 84000 | K9: 已全额还款 | L9: 2835 | M9: =E9 -> 45929 | N9: 否 | O9: 0
A10: 001 | B10: 中国对外经济贸易信托有限公司 | C10: 101128141006-001 | D10: 101128141006 | E10: 45929 | F10: 1 | G10: 9263 | H10: 164000 | I10: 0 | J10: =H10-I10 -> 164000 | K10: 已全额还款 | L10: 9263 | M10: =E10 -> 45929 | N10: 否 | O10: 0
A11: 001 | B11: 中国对外经济贸易信托有限公司 | C11: 101128199395-001 | D11: 101128199395 | E11: 45929 | F11: 1 | G11: 1719.33 | H11: 109806 | I11: 0 | J11: =H11-I11 -> 109806 | K11: 已全额还款 | L11: 1719.33 | M11: =E11 -> 45929 | N11: 否 | O11: 0
A12: 001 | B12: 中国对外经济贸易信托有限公司 | C12: 101128199843-001 | D12: 101128199843 | E12: 45929 | F12: 1 | G12: 3200 | H12: 93677 | I12: 0 | J12: =H12-I12 -> 93677 | K12: 已全额还款 | L12: 3200 | M12: =E12 -> 45929 | N12: 否 | O12: 0
A13: 001 | B13: 中国对外经济贸易信托有限公司 | C13: 101128209031-001 | D13: 101128209031 | E13: 45929 | F13: 1 | G13: 1840 | H13: 55000 | I13: 0 | J13: =H13-I13 -> 55000 | K13: 已全额还款 | L13: 1840 | M13: =E13 -> 45929 | N13: 否 | O13: 0
... A1161: 001 | B1161: 中国对外经济贸易信托有限公司 | C1161: 101127339909-001 | D1161: 101127339909 | E1161: 45929 | F1161: 8 | G1161: 6885 | H1161: 94060 | I1161: 0 | J1161: =H1161-I1161 -> 94060 | K1161: 已全额还款 | L1161: 6885 | M1161: =E1161 -> 45929 | N1161: 否 | O1161: 0

Sheet 还款明细--1017已还款
A1: 资产包编号 | B1: 当前还款方 | C1: 资产编号(房源) | D1: 托管房源编码 | E1: 计划集中还款日期 | F1: 还款期数 | G1: 当期计划还款金额 | H1: 初始受让装修金额 | I1: 累计已还款金额 | J1: 剩余应还款余额 | K1: 本期还款状态 | L1: 当期实际还款金额 | M1: 本期是否逾期 | N1: 当期逾期天数
A2: 1 | B2: 中国对外经济贸易信托有限公司 | C2: 101127876784-001 | D2: 101127876784 | E2: 45933 | F2: 2 | G2: 4160 | H2: 74642 | I2: 8320 | J2: 66322 | K2: 已全额还款 | L2: 4160 | M2: 否 | N2: 0
A3: 1 | B3: 中国对外经济贸易信托有限公司 | C3: 101128199843-001 | D3: 101128199843 | E3: 45933 | F3: 2 | G3: 3200 | H3: 93677 | I3: 6400 | J3: 87277 | K3: 已全额还款 | L3: 3200 | M3: 否 | N3: 0
A4: 1 | B4: 中国对外经济贸易信托有限公司 | C4: 101128371669-001 | D4: 101128371669 | E4: 45933 | F4: 2 | G4: 4625 | H4: 166113 | I4: 9250 | J4: 156863 | K4: 已全额还款 | L4: 4625 | M4: 否 | N4: 0
A5: 1 | B5: 中国对外经济贸易信托有限公司 | C5: 101128568095-001 | D5: 101128568095 | E5: 45933 | F5: 2 | G5: 5035 | H5: 149000 | I5: 10070 | J5: 138930 | K5: 已全额还款 | L5: 5035 | M5: 否 | N5: 0
A6: 1 | B6: 中国对外经济贸易信托有限公司 | C6: 101130798182-001 | D6: 101130798182 | E6: 45933 | F6: 2 | G6: 5160 | H6: 95000 | I6: 9560 | J6: 85440 | K6: 已全额还款 | L6: 5160 | M6: 否 | N6: 0
A7: 1 | B7: 中国对外经济贸易信托有限公司 | C7: 107112417266-001 | D7: 107112417266 | E7: 45940 | F7: 2 | G7: 1155 | H7: 20000 | I7: 2310 | J7: 17690 | K7: 已全额还款 | L7: 1155 | M7: 否 | N7: 0
A8: 1 | B8: 中国对外经济贸易信托有限公司 | C8: 107112493987-001 | D8: 107112493987 | E8: 45933 | F8: 2 | G8: 1118 | H8: 19456 | I8: 2236 | J8: 17220 | K8: 已全额还款 | L8: 1118 | M8: 否 | N8: 0
A9: 1 | B9: 中国对外经济贸易信托有限公司 | C9: 107112594084-001 | D9: 107112594084 | E9: 45933 | F9: 2 | G9: 3472 | H9: 106500 | I9: 5902 | J9: 100598 | K9: 已全额还款 | L9: 3472 | M9: 否 | N9: 0
A10: 1 | B10: 中国对外经济贸易信托有限公司 | C10: 107112621983-001 | D10: 107112621983 | E10: 45940 | F10: 2 | G10: 3822 | H10: 110923 | I10: 7644 | J10: 103279 | K10: 已全额还款 | L10: 3822 | M10: 否 | N10: 0
A11: 1 | B11: 中国对外经济贸易信托有限公司 | C11: 107112652329-001 | D11: 107112652329 | E11: 45933 | F11: 2 | G11: 6624 | H11: 192989 | I11: 13248 | J11: 179741 | K11: 已全额还款 | L11: 6624 | M11: 否 | N11: 0
A12: 1 | B12: 中国对外经济贸易信托有限公司 | C12: 107112719541-001 | D12: 107112719541 | E12: 45933 | F12: 2 | G12: 864 | H12: 15000 | I12: 1728 | J12: 13272 | K12: 已全额还款 | L12: 864 | M12: 否 | N12: 0
A13: 1 | B13: 中国对外经济贸易信托有限公司 | C13: 107112784036-001 | D13: 107112784036 | E13: 45940 | F13: 2 | G13: 5292 | H13: 161888 | I13: 9112 | J13: 152776 | K13: 已全额还款 | L13: 5292 | M13: 否 | N13: 0
... A186: 1 | B186: 中国对外经济贸易信托有限公司 | C186: 107111539618-001 | D186: 107111539618 | E186: 45940 | F186: 7 | G186: 2790 | H186: 77507.5 | I186: 11160 | J186: 66347.5 | K186: 已全额还款 | L186: 2790 | M186: 否 | N186: 0

Sheet 还款明细-1031已还款
A1: 资产包编号 | B1: 当前还款方 | C1: 资产编号(房源) | D1: 托管房源编码 | E1: 计划集中还款日期 | F1: 还款期数 | G1: 当期计划还款金额 | H1: 初始受让装修金额 | I1: 累计已还款金额 | J1: 剩余应还款余额 | K1: 本期还款状态 | L1: 当期实际还款金额 | M1: 本期是否逾期 | N1: 当期逾期天数
A2: 1 | B2: 中国对外经济贸易信托有限公司 | C2: 101128141006-001 | D2: 101128141006 | E2: 45947 | F2: 2 | G2: 9263 | H2: 164000 | I2: 18526 | J2: 145474 | K2: 已全额还款 | L2: 9263 | M2: 否 | N2: 0
A3: 1 | B3: 中国对外经济贸易信托有限公司 | C3: 107112707011-001 | D3: 107112707011 | E3: 45947 | F3: 2 | G3: 1300 | H3: 23000 | I3: 2600 | J3: 20400 | K3: 已全额还款 | L3: 1300 | M3: 否 | N3: 0
A4: 1 | B4: 中国对外经济贸易信托有限公司 | C4: 107112777756-001 | D4: 107112777756 | E4: 45947 | F4: 2 | G4: 2923 | H4: 84279 | I4: 5846 | J4: 78433 | K4: 已全额还款 | L4: 2923 | M4: 否 | N4: 0
A5: 1 | B5: 中国对外经济贸易信托有限公司 | C5: 107112803579-001 | D5: 107112803579 | E5: 45947 | F5: 2 | G5: 2225 | H5: 67500 | I5: 3225 | J5: 64275 | K5: 已全额还款 | L5: 2225 | M5: 否 | N5: 0
A6: 1 | B6: 中国对外经济贸易信托有限公司 | C6: 107112913803-001 | D6: 107112913803 | E6: 45947 | F6: 2 | G6: 1575 | H6: 45000 | I6: 2910 | J6: 42090 | K6: 已全额还款 | L6: 1575 | M6: 否 | N6: 0
A7: 1 | B7: 中国对外经济贸易信托有限公司 | C7: 107112954373-001 | D7: 107112954373 | E7: 45947 | F7: 2 | G7: 3550 | H7: 105700 | I7: 5550 | J7: 100150 | K7: 已全额还款 | L7: 3550 | M7: 否 | N7: 0
A8: 1 | B8: 中国对外经济贸易信托有限公司 | C8: 107113022670-001 | D8: 107113022670 | E8: 45954 | F8: 2 | G8: 4620 | H8: 137000 | I8: 7420 | J8: 129580 | K8: 已全额还款 | L8: 4620 | M8: 否 | N8: 0
A9: 1 | B9: 中国对外经济贸易信托有限公司 | C9: 101127311840-001 | D9: 101127311840 | E9: 45954 | F9: 3 | G9: 1211.33 | H9: 49162 | I9: 3633.99 | J9: 45528.01 | K9: 已全额还款 | L9: 1211.33 | M9: 否 | N9: 0
A10: 1 | B10: 中国对外经济贸易信托有限公司 | C10: 101127524235-001 | D10: 101127524235 | E10: 45954 | F10: 3 | G10: 2420 | H10: 50000 | I10: 7260 | J10: 42740 | K10: 已全额还款 | L10: 2420 | M10: 否 | N10: 0
A11: 1 | B11: 中国对外经济贸易信托有限公司 | C11: 101127962550-001 | D11: 101127962550 | E11: 45954 | F11: 3 | G11: 2835 | H11: 84000 | I11: 8505 | J11: 75495 | K11: 已全额还款 | L11: 2835 | M11: 否 | N11: 0
A12: 1 | B12: 中国对外经济贸易信托有限公司 | C12: 101130375783-001 | D12: 101130375783 | E12: 45954 | F12: 3 | G12: 2800 | H12: 83560 | I12: 8400 | J12: 75160 | K12: 已全额还款 | L12: 2800 | M12: 否 | N12: 0
A13: 1 | B13: 中国对外经济贸易信托有限公司 | C13: 101130590769-001 | D13: 101130590769 | E13: 45947 | F13: 3 | G13: 2940 | H13: 77000 | I13: 7410 | J13: 69590 | K13: 已全额还款 | L13: 2940 | M13: 否 | N13: 0
... A216: 1 | B216: 中国对外经济贸易信托有限公司 | C216: 101127339909-001 | D216: 101127339909 | E216: 45947 | F216: 9 | G216: 6885 | H216: 94060 | I216: 27540 | J216: 66520 | K216: 已全额还款 | L216: 6885 | M216: 否 | N216: 0

Sheet 还款明细-1114已还款
A1: 资产包编号 | B1: 当前还款方 | C1: 资产编号(房源) | D1: 托管房源编码 | E1: 计划集中还款日期 | F1: 还款期数 | G1: 当期计划还款金额 | H1: 初始受让装修金额 | I1: 累计已还款金额 | J1: 剩余应还款余额 | K1: 本期还款状态 | L1: 当期实际还款金额 | M1: 本期是否逾期 | N1: 当期逾期天数
A2: 1 | B2: 中国对外经济贸易信托有限公司 | C2: 101127876784-001 | D2: 101127876784 | E2: 45961 | F2: 3 | G2: 4160 | H2: 74642 | I2: 12480 | J2: 62162 | K2: 已全额还款 | L2: 4160 | M2: 已全额还款 | N2: 0
A3: 1 | B3: 中国对外经济贸易信托有限公司 | C3: 101128199843-001 | D3: 101128199843 | E3: 45968 | F3: 3 | G3: 3200 | H3: 93677 | I3: 9600 | J3: 84077 | K3: 已全额还款 | L3: 3200 | M3: 已全额还款 | N3: 0
A4: 1 | B4: 中国对外经济贸易信托有限公司 | C4: 101128371669-001 | D4: 101128371669 | E4: 45968 | F4: 3 | G4: 4625 | H4: 166113 | I4: 13875 | J4: 152238 | K4: 已全额还款 | L4: 4625 | M4: 已全额还款 | N4: 0
A5: 1 | B5: 中国对外经济贸易信托有限公司 | C5: 101128409796-001 | D5: 101128409796 | E5: 45961 | F5: 3 | G5: 4853.33 | H5: 98000 | I5: 14559.99 | J5: 83440.01 | K5: 已全额还款 | L5: 4853.33 | M5: 已全额还款 | N5: 0
A6: 1 | B6: 中国对外经济贸易信托有限公司 | C6: 101128568095-001 | D6: 101128568095 | E6: 45968 | F6: 3 | G6: 5035 | H6: 149000 | I6: 15105 | J6: 133895 | K6: 已全额还款 | L6: 5035 | M6: 已全额还款 | N6: 0
A7: 1 | B7: 中国对外经济贸易信托有限公司 | C7: 107112417266-001 | D7: 107112417266 | E7: 45968 | F7: 3 | G7: 1155 | H7: 20000 | I7: 3465 | J7: 16535 | K7: 已全额还款 | L7: 1155 | M7: 已全额还款 | N7: 0
A8: 1 | B8: 中国对外经济贸易信托有限公司 | C8: 107112493987-001 | D8: 107112493987 | E8: 45968 | F8: 3 | G8: 1118 | H8: 19456 | I8: 3354 | J8: 16102 | K8: 已全额还款 | L8: 1118 | M8: 已全额还款 | N8: 0
A9: 1 | B9: 中国对外经济贸易信托有限公司 | C9: 107112594084-001 | D9: 107112594084 | E9: 45961 | F9: 3 | G9: 3472 | H9: 106500 | I9: 9374 | J9: 97126 | K9: 已全额还款 | L9: 3472 | M9: 已全额还款 | N9: 0
A10: 1 | B10: 中国对外经济贸易信托有限公司 | C10: 107112621983-001 | D10: 107112621983 | E10: 45968 | F10: 3 | G10: 3822 | H10: 110923 | I10: 11466 | J10: 99457 | K10: 已全额还款 | L10: 3822 | M10: 已全额还款 | N10: 0
A11: 1 | B11: 中国对外经济贸易信托有限公司 | C11: 107112652329-001 | D11: 107112652329 | E11: 45968 | F11: 3 | G11: 6624 | H11: 192989 | I11: 19872 | J11: 173117 | K11: 已全额还款 | L11: 6624 | M11: 已全额还款 | N11: 0
A12: 1 | B12: 中国对外经济贸易信托有限公司 | C12: 107112719541-001 | D12: 107112719541 | E12: 45961 | F12: 3 | G12: 864 | H12: 15000 | I12: 2592 | J12: 12408 | K12: 已全额还款 | L12: 864 | M12: 已全额还款 | N12: 0
A13: 1 | B13: 中国对外经济贸易信托有限公司 | C13: 107112784036-001 | D13: 107112784036 | E13: 45968 | F13: 3 | G13: 5292 | H13: 161888 | I13: 14404 | J13: 147484 | K13: 已全额还款 | L13: 5292 | M13: 已全额还款 | N13: 0
... A167: 1 | B167: 中国对外经济贸易信托有限公司 | C167: 107111539618-001 | D167: 107111539618 | E167: 45968 | F167: 8 | G167: 2790 | H167: 77507.5 | I167: 13950 | J167: 63557.5 | K167: 已全额还款 | L167: 2790 | M167: 已全额还款 | N167: 0

Sheet 还款明细-1128已还款
A1: 资产包编号 | B1: 当前还款方 | C1: 资产编号(房源) | D1: 托管房源编码 | E1: 计划集中还款日期 | F1: 还款期数 | G1: 当期计划还款金额 | H1: 初始受让装修金额 | I1: 累计已还款金额 | J1: 剩余应还款余额 | K1: 本期还款状态 | L1: 当期实际还款金额 | M1: 本期是否逾期 | N1: 当期逾期天数
A2: 1 | B2: 中国对外经济贸易信托有限公司 | C2: 101128141006-001 | D2: 101128141006 | E2: 45975 | F2: 3 | G2: 9263 | H2: 164000 | I2: 27789 | J2: 136211 | K2: 已全额还款 | L2: 9263 | M2: 已全额还款 | N2: 0
A3: 1 | B3: 中国对外经济贸易信托有限公司 | C3: 107112707011-001 | D3: 107112707011 | E3: 45975 | F3: 3 | G3: 1300 | H3: 23000 | I3: 3900 | J3: 19100 | K3: 已全额还款 | L3: 1300 | M3: 已全额还款 | N3: 0
A4: 1 | B4: 中国对外经济贸易信托有限公司 | C4: 107112777756-001 | D4: 107112777756 | E4: 45975 | F4: 3 | G4: 2923 | H4: 84279 | I4: 8769 | J4: 75510 | K4: 已全额还款 | L4: 2923 | M4: 已全额还款 | N4: 0
A5: 1 | B5: 中国对外经济贸易信托有限公司 | C5: 107112803579-001 | D5: 107112803579 | E5: 45975 | F5: 3 | G5: 2225 | H5: 67500 | I5: 5450 | J5: 62050 | K5: 已全额还款 | L5: 2225 | M5: 已全额还款 | N5: 0
A6: 1 | B6: 中国对外经济贸易信托有限公司 | C6: 107112954373-001 | D6: 107112954373 | E6: 45975 | F6: 3 | G6: 3550 | H6: 105700 | I6: 9100 | J6: 96600 | K6: 已全额还款 | L6: 3550 | M6: 已全额还款 | N6: 0
A7: 1 | B7: 中国对外经济贸易信托有限公司 | C7: 107113022670-001 | D7: 107113022670 | E7: 45982 | F7: 3 | G7: 4620 | H7: 137000 | I7: 12040 | J7: 124960 | K7: 已全额还款 | L7: 4620 | M7: 已全额还款 | N7: 0
A8: 1 | B8: 中国对外经济贸易信托有限公司 | C8: 101127311840-001 | D8: 101127311840 | E8: 45982 | F8: 4 | G8: 1211.33 | H8: 49162 | I8: 4845.32 | J8: 44316.68 | K8: 已全额还款 | L8: 1211.33 | M8: 已全额还款 | N8: 0
A9: 1 | B9: 中国对外经济贸易信托有限公司 | C9: 101127524235-001 | D9: 101127524235 | E9: 45982 | F9: 4 | G9: 2420 | H9: 50000 | I9: 9680 | J9: 40320 | K9: 已全额还款 | L9: 2420 | M9: 已全额还款 | N9: 0
A10: 1 | B10: 中国对外经济贸易信托有限公司 | C10: 101130133837-001 | D10: 101130133837 | E10: 45975 | F10: 4 | G10: 4080 | H10: 79275 | I10: 15190 | J10: 64085 | K10: 已全额还款 | L10: 4080 | M10: 已全额还款 | N10: 0
A11: 1 | B11: 中国对外经济贸易信托有限公司 | C11: 101130434119-001 | D11: 101130434119 | E11: 45975 | F11: 4 | G11: 2850 | H11: 85800 | I11: 11300 | J11: 74500 | K11: 已全额还款 | L11: 2850 | M11: 已全额还款 | N11: 0
A12: 1 | B12: 中国对外经济贸易信托有限公司 | C12: 101130590769-001 | D12: 101130590769 | E12: 45975 | F12: 4 | G12: 2940 | H12: 77000 | I12: 10350 | J12: 66650 | K12: 已全额还款 | L12: 2940 | M12: 已全额还款 | N12: 0
A13: 1 | B13: 中国对外经济贸易信托有限公司 | C13: 101130614595-001 | D13: 101130614595 | E13: 45975 | F13: 4 | G13: 2409 | H13: 74625 | I13: 9636 | J13: 64989 | K13: 已全额还款 | L13: 2409 | M13: 已全额还款 | N13: 0
... A214: 1 | B214: 中国对外经济贸易信托有限公司 | C214: 101127339909-001 | D214: 101127339909 | E214: 45982 | F214: 10 | G214: 6885 | H214: 94060 | I214: 34425 | J214: 59635 | K214: 已全额还款 | L214: 6885 | M214: 已全额还款 | N214: 0

Sheet 还款明细-1212已还款
A1: 资产包编号 | B1: 当前还款方 | C1: 资产编号(房源) | D1: 托管房源编码 | E1: 计划集中还款日期 | F1: 还款期数 | G1: 当期计划还款金额 | H1: 初始受让装修金额 | I1: 累计已还款金额 | J1: 剩余应还款余额 | K1: 本期还款状态 | L1: 当期实际还款金额 | M1: 本期是否逾期 | N1: 当期逾期天数
A2: 1 | B2: 中国对外经济贸易信托有限公司 | C2: 101131458617-001 | D2: 101131458617 | E2: 45996 | F2: 3 | G2: 2470 | H2: 74000 | I2: 9880 | J2: 64120 | K2: 已全额还款 | L2: 2470 | M2: 已全额还款 | N2: 0
A3: 1 | B3: 中国对外经济贸易信托有限公司 | C3: 101127876784-001 | D3: 101127876784 | E3: 45996 | F3: 4 | G3: 4160 | H3: 74642 | I3: 16640 | J3: 58002 | K3: 已全额还款 | L3: 4160 | M3: 已全额还款 | N3: 0
A4: 1 | B4: 中国对外经济贸易信托有限公司 | C4: 101127962550-001 | D4: 101127962550 | E4: 45989 | F4: 4 | G4: 2835 | H4: 84000 | I4: 11340 | J4: 72660 | K4: 已全额还款 | L4: 2835 | M4: 已全额还款 | N4: 0
A5: 1 | B5: 中国对外经济贸易信托有限公司 | C5: 101128199843-001 | D5: 101128199843 | E5: 45996 | F5: 4 | G5: 3200 | H5: 93677 | I5: 12800 | J5: 80877 | K5: 已全额还款 | L5: 3200 | M5: 已全额还款 | N5: 0
A6: 1 | B6: 中国对外经济贸易信托有限公司 | C6: 101128371669-001 | D6: 101128371669 | E6: 45996 | F6: 4 | G6: 4625 | H6: 166113 | I6: 18500 | J6: 147613 | K6: 已全额还款 | L6: 4625 | M6: 已全额还款 | N6: 0
A7: 1 | B7: 中国对外经济贸易信托有限公司 | C7: 101128409796-001 | D7: 101128409796 | E7: 45989 | F7: 4 | G7: 4853.33 | H7: 98000 | I7: 19413.32 | J7: 78586.68 | K7: 已全额还款 | L7: 4853.33 | M7: 已全额还款 | N7: 0
A8: 1 | B8: 中国对外经济贸易信托有限公司 | C8: 101128568095-001 | D8: 101128568095 | E8: 45996 | F8: 4 | G8: 5035 | H8: 149000 | I8: 20140 | J8: 128860 | K8: 已全额还款 | L8: 5035 | M8: 已全额还款 | N8: 0
A9: 1 | B9: 中国对外经济贸易信托有限公司 | C9: 101130375783-001 | D9: 101130375783 | E9: 45989 | F9: 4 | G9: 2800 | H9: 83560 | I9: 11200 | J9: 72360 | K9: 已全额还款 | L9: 2800 | M9: 已全额还款 | N9: 0
A10: 1 | B10: 中国对外经济贸易信托有限公司 | C10: 101130763989-001 | D10: 101130763989 | E10: 45989 | F10: 4 | G10: 3850 | H10: 115960 | I10: 15400 | J10: 100560 | K10: 已全额还款 | L10: 3850 | M10: 已全额还款 | N10: 0
A11: 1 | B11: 中国对外经济贸易信托有限公司 | C11: 107112493987-001 | D11: 107112493987 | E11: 45996 | F11: 4 | G11: 1118 | H11: 19456 | I11: 4472 | J11: 14984 | K11: 已全额还款 | L11: 1118 | M11: 已全额还款 | N11: 0
A12: 1 | B12: 中国对外经济贸易信托有限公司 | C12: 107112590250-001 | D12: 107112590250 | E12: 45989 | F12: 4 | G12: 2970 | H12: 84000 | I12: 11880 | J12: 72120 | K12: 已全额还款 | L12: 2970 | M12: 已全额还款 | N12: 0
A13: 1 | B13: 中国对外经济贸易信托有限公司 | C13: 107112594084-001 | D13: 107112594084 | E13: 45989 | F13: 4 | G13: 3472 | H13: 106500 | I13: 12846 | J13: 93654 | K13: 已全额还款 | L13: 3472 | M13: 已全额还款 | N13: 0
... A169: 1 | B169: 中国对外经济贸易信托有限公司 | C169: 107111539618-001 | D169: 107111539618 | E169: 45996 | F169: 9 | G169: 2790 | H169: 77507.5 | I169: 16740 | J169: 60767.5 | K169: 已全额还款 | L169: 2790 | M169: 已全额还款 | N169: 0

Sheet 还款明细-1226已还款
A1: 资产包编号 | B1: 当前还款方 | C1: 资产编号(房源) | D1: 托管房源编码 | E1: 计划集中还款日期 | F1: 还款期数 | G1: 当期计划还款金额 | H1: 初始受让装修金额 | I1: 累计已还款金额 | J1: 剩余应还款余额 | K1: 本期还款状态 | L1: 当期实际还款金额 | M1: 本期是否逾期 | N1: 当期逾期天数
A2: 1 | B2: 中国对外经济贸易信托有限公司 | C2: 101128141006-001 | D2: 101128141006 | E2: 46003 | F2: 4 | G2: 9263 | H2: 164000 | I2: 37052 | J2: 126948 | K2: 已全额还款 | L2: 9263 | M2: 已全额还款 | N2: 0
A3: 1 | B3: 中国对外经济贸易信托有限公司 | C3: 107112417266-001 | D3: 107112417266 | E3: 46003 | F3: 4 | G3: 1155 | H3: 20000 | I3: 4620 | J3: 15380 | K3: 已全额还款 | L3: 1155 | M3: 已全额还款 | N3: 0
A4: 1 | B4: 中国对外经济贸易信托有限公司 | C4: 107112621983-001 | D4: 107112621983 | E4: 46003 | F4: 4 | G4: 3822 | H4: 110923 | I4: 15288 | J4: 95635 | K4: 已全额还款 | L4: 3822 | M4: 已全额还款 | N4: 0
A5: 1 | B5: 中国对外经济贸易信托有限公司 | C5: 107112707011-001 | D5: 107112707011 | E5: 46003 | F5: 4 | G5: 1300 | H5: 23000 | I5: 5200 | J5: 17800 | K5: 已全额还款 | L5: 1300 | M5: 已全额还款 | N5: 0
A6: 1 | B6: 中国对外经济贸易信托有限公司 | C6: 107112777756-001 | D6: 107112777756 | E6: 46010 | F6: 4 | G6: 2923 | H6: 84279 | I6: 11692 | J6: 72587 | K6: 已全额还款 | L6: 2923 | M6: 已全额还款 | N6: 0
A7: 1 | B7: 中国对外经济贸易信托有限公司 | C7: 107112784036-001 | D7: 107112784036 | E7: 46003 | F7: 4 | G7: 5292 | H7: 161888 | I7: 19696 | J7: 142192 | K7: 已全额还款 | L7: 5292 | M7: 已全额还款 | N7: 0
A8: 1 | B8: 中国对外经济贸易信托有限公司 | C8: 107112803579-001 | D8: 107112803579 | E8: 46003 | F8: 4 | G8: 2225 | H8: 67500 | I8: 7675 | J8: 59825 | K8: 已全额还款 | L8: 2225 | M8: 已全额还款 | N8: 0
A9: 1 | B9: 中国对外经济贸易信托有限公司 | C9: 107112954373-001 | D9: 107112954373 | E9: 46003 | F9: 4 | G9: 3550 | H9: 105700 | I9: 12650 | J9: 93050 | K9: 已全额还款 | L9: 3550 | M9: 已全额还款 | N9: 0
A10: 1 | B10: 中国对外经济贸易信托有限公司 | C10: 107113022670-001 | D10: 107113022670 | E10: 46010 | F10: 4 | G10: 4620 | H10: 137000 | I10: 16660 | J10: 120340 | K10: 已全额还款 | L10: 4620 | M10: 已全额还款 | N10: 0
A11: 1 | B11: 中国对外经济贸易信托有限公司 | C11: 101130133837-001 | D11: 101130133837 | E11: 46003 | F11: 5 | G11: 4080 | H11: 79275 | I11: 19270 | J11: 60005 | K11: 已全额还款 | L11: 4080 | M11: 已全额还款 | N11: 0
A12: 1 | B12: 中国对外经济贸易信托有限公司 | C12: 101130434119-001 | D12: 101130434119 | E12: 46003 | F12: 5 | G12: 2850 | H12: 85800 | I12: 14150 | J12: 71650 | K12: 已全额还款 | L12: 2850 | M12: 已全额还款 | N12: 0
A13: 1 | B13: 中国对外经济贸易信托有限公司 | C13: 101130525509-001 | D13: 101130525509 | E13: 46003 | F13: 5 | G13: 6952 | H13: 120000 | I13: 31478 | J13: 88522 | K13: 已全额还款 | L13: 6952 | M13: 已全额还款 | N13: 0
... A219: 1 | B219: 中国对外经济贸易信托有限公司 | C219: 101127339909-001 | D219: 101127339909 | E219: 46010 | F219: 11 | G219: 6885 | H219: 94060 | I219: 41310 | J219: 52750 | K219: 已全额还款 | L219: 6885 | M219: 已全额还款 | N219: 0

Sheet 还款明细-0109已还款
A1: 资产包编号 | B1: 当前还款方 | C1: 资产编号(房源) | D1: 托管房源编码 | E1: 计划集中还款日期 | F1: 还款期数 | G1: 当期计划还款金额 | H1: 初始受让装修金额 | I1: 累计已还款金额 | J1: 剩余应还款余额 | K1: 本期还款状态 | L1: 当期实际还款金额 | M1: 本期是否逾期 | N1: 当期逾期天数
A2: 1 | B2: 中国对外经济贸易信托有限公司 | C2: 101131458617-001 | D2: 101131458617 | E2: 46024 | F2: 4 | G2: 2470 | H2: 74000 | I2: 12350 | J2: 61650 | K2: 已全额还款 | L2: 2470 | M2: 已全额还款 | N2: 0
A3: 1 | B3: 中国对外经济贸易信托有限公司 | C3: 101127311840-001 | D3: 101127311840 | E3: 46017 | F3: 5 | G3: 1211.33 | H3: 49162 | I3: 6056.65 | J3: 43105.35 | K3: 已全额还款 | L3: 1211.33 | M3: 已全额还款 | N3: 0
A4: 1 | B4: 中国对外经济贸易信托有限公司 | C4: 101127524235-001 | D4: 101127524235 | E4: 46017 | F4: 5 | G4: 2420 | H4: 50000 | I4: 12100 | J4: 37900 | K4: 已全额还款 | L4: 2420 | M4: 已全额还款 | N4: 0
A5: 1 | B5: 中国对外经济贸易信托有限公司 | C5: 101127876784-001 | D5: 101127876784 | E5: 46024 | F5: 5 | G5: 4160 | H5: 74642 | I5: 20800 | J5: 53842 | K5: 已全额还款 | L5: 4160 | M5: 已全额还款 | N5: 0
A6: 1 | B6: 中国对外经济贸易信托有限公司 | C6: 101127962550-001 | D6: 101127962550 | E6: 46017 | F6: 5 | G6: 2835 | H6: 84000 | I6: 14175 | J6: 69825 | K6: 已全额还款 | L6: 2835 | M6: 已全额还款 | N6: 0
A7: 1 | B7: 中国对外经济贸易信托有限公司 | C7: 101128371669-001 | D7: 101128371669 | E7: 46024 | F7: 5 | G7: 4625 | H7: 166113 | I7: 23125 | J7: 142988 | K7: 已全额还款 | L7: 4625 | M7: 已全额还款 | N7: 0
A8: 1 | B8: 中国对外经济贸易信托有限公司 | C8: 101128409796-001 | D8: 101128409796 | E8: 46017 | F8: 5 | G8: 4853.33 | H8: 98000 | I8: 24266.65 | J8: 73733.35 | K8: 已全额还款 | L8: 4853.33 | M8: 已全额还款 | N8: 0
A9: 1 | B9: 中国对外经济贸易信托有限公司 | C9: 101128568095-001 | D9: 101128568095 | E9: 46024 | F9: 5 | G9: 5035 | H9: 149000 | I9: 25175 | J9: 123825 | K9: 已全额还款 | L9: 5035 | M9: 已全额还款 | N9: 0
A10: 1 | B10: 中国对外经济贸易信托有限公司 | C10: 101130375783-001 | D10: 101130375783 | E10: 46017 | F10: 5 | G10: 2800 | H10: 83560 | I10: 14000 | J10: 69560 | K10: 已全额还款 | L10: 2800 | M10: 已全额还款 | N10: 0
A11: 1 | B11: 中国对外经济贸易信托有限公司 | C11: 101130525509-001 | D11: 101130525509 | E11: 46024 | F11: 5 | G11: 6952 | H11: 120000 | I11: 38430 | J11: 81570 | K11: 已全额还款 | L11: 6952 | M11: 已全额还款 | N11: 0
A12: 1 | B12: 中国对外经济贸易信托有限公司 | C12: 101130763989-001 | D12: 101130763989 | E12: 46017 | F12: 5 | G12: 3850 | H12: 115960 | I12: 19250 | J12: 96710 | K12: 已全额还款 | L12: 3850 | M12: 已全额还款 | N12: 0
A13: 1 | B13: 中国对外经济贸易信托有限公司 | C13: 101131094358-001 | D13: 101131094358 | E13: 46017 | F13: 5 | G13: 2856 | H13: 85872 | I13: 13917.33 | J13: 71954.67 | K13: 已全额还款 | L13: 2856 | M13: 已全额还款 | N13: 0
... A152: 1 | B152: 中国对外经济贸易信托有限公司 | C152: 101129291267-001 | D152: 101129291267 | E152: 46024 | F152: 9 | G152: 4165 | H152: 78585 | I152: 32388 | J152: 46197 | K152: 已全额还款 | L152: 4165 | M152: 已全额还款 | N152: 0

Sheet 还款明细-0123已还款
A1: 资产包编号 | B1: 当前还款方 | C1: 资产编号(房源) | D1: 托管房源编码 | E1: 计划集中还款日期 | F1: 还款期数 | G1: 当期计划还款金额 | H1: 初始受让装修金额 | I1: 累计已还款金额 | J1: 剩余应还款余额 | K1: 本期还款状态 | L1: 当期实际还款金额 | M1: 本期是否逾期 | N1: 当期逾期天数
A2: 1 | B2: 中国对外经济贸易信托有限公司 | C2: 101128141006-001 | D2: 101128141006 | E2: 46038 | F2: 5 | G2: 9263 | H2: 164000 | I2: 37052 | J2: 126948 | K2: 已全额还款 | L2: 9263 | M2: 已全额还款 | N2: 0
A3: 1 | B3: 中国对外经济贸易信托有限公司 | C3: 101128199843-001 | D3: 101128199843 | E3: 46031 | F3: 5 | G3: 3200 | H3: 93677 | I3: 12800 | J3: 80877 | K3: 已全额还款 | L3: 3200 | M3: 已全额还款 | N3: 0
A4: 1 | B4: 中国对外经济贸易信托有限公司 | C4: 101130950078-001 | D4: 101130950078 | E4: 46038 | F4: 5 | G4: 4216 | H4: 85000 | I4: 16771 | J4: 68229 | K4: 已全额还款 | L4: 4216 | M4: 已全额还款 | N4: 0
A5: 1 | B5: 中国对外经济贸易信托有限公司 | C5: 107112417266-001 | D5: 107112417266 | E5: 46031 | F5: 5 | G5: 1155 | H5: 20000 | I5: 4620 | J5: 15380 | K5: 已全额还款 | L5: 1155 | M5: 已全额还款 | N5: 0
A6: 1 | B6: 中国对外经济贸易信托有限公司 | C6: 107112621983-001 | D6: 107112621983 | E6: 46031 | F6: 5 | G6: 3822 | H6: 110923 | I6: 15288 | J6: 95635 | K6: 已全额还款 | L6: 3822 | M6: 已全额还款 | N6: 0
A7: 1 | B7: 中国对外经济贸易信托有限公司 | C7: 107112707011-001 | D7: 107112707011 | E7: 46038 | F7: 5 | G7: 1300 | H7: 23000 | I7: 5200 | J7: 17800 | K7: 已全额还款 | L7: 1300 | M7: 已全额还款 | N7: 0
A8: 1 | B8: 中国对外经济贸易信托有限公司 | C8: 107112784036-001 | D8: 107112784036 | E8: 46031 | F8: 5 | G8: 5292 | H8: 161888 | I8: 19696 | J8: 142192 | K8: 已全额还款 | L8: 5292 | M8: 已全额还款 | N8: 0
A9: 1 | B9: 中国对外经济贸易信托有限公司 | C9: 107112803579-001 | D9: 107112803579 | E9: 46038 | F9: 5 | G9: 2225 | H9: 67500 | I9: 7675 | J9: 59825 | K9: 已全额还款 | L9: 2225 | M9: 已全额还款 | N9: 0
A10: 1 | B10: 中国对外经济贸易信托有限公司 | C10: 107112951037-001 | D10: 107112951037 | E10: 46031 | F10: 5 | G10: 3075 | H10: 89698 | I10: 12300 | J10: 77398 | K10: 已全额还款 | L10: 3075 | M10: 已全额还款 | N10: 0
A11: 1 | B11: 中国对外经济贸易信托有限公司 | C11: 107112954373-001 | D11: 107112954373 | E11: 46038 | F11: 5 | G11: 3550 | H11: 105700 | I11: 12650 | J11: 93050 | K11: 已全额还款 | L11: 3550 | M11: 已全额还款 | N11: 0
A12: 1 | B12: 中国对外经济贸易信托有限公司 | C12: 107112974183-001 | D12: 107112974183 | E12: 46031 | F12: 5 | G12: 4576 | H12: 138000 | I12: 15808 | J12: 122192 | K12: 已全额还款 | L12: 4576 | M12: 已全额还款 | N12: 0
A13: 1 | B13: 中国对外经济贸易信托有限公司 | C13: 101128228767-001 | D13: 101128228767 | E13: 46031 | F13: 6 | G13: 1334 | H13: 39593 | I13: 6670 | J13: 32923 | K13: 已全额还款 | L13: 1334 | M13: 已全额还款 | N13: 0
... A179: 1 | B179: 中国对外经济贸易信托有限公司 | C179: 101127339909-001 | D179: 101127339909 | E179: 46038 | F179: 12 | G179: 6885 | H179: 94060 | I179: 41310 | J179: 52750 | K179: 已全额还款 | L179: 6885 | M179: 已全额还款 | N179: 0

Sheet 还款明细-0206已还款
A1: 资产包编号 | B1: 当前还款方 | C1: 资产编号(房源) | D1: 托管房源编码 | E1: 计划集中还款日期 | F1: 还款期数 | G1: 当期计划还款金额 | H1: 初始受让装修金额 | I1: 累计已还款金额 | J1: 剩余应还款余额 | K1: 本期还款状态 | L1: 当期实际还款金额 | M1: 本期是否逾期 | N1: 当期逾期天数
A2: 001 | B2: 中国对外经济贸易信托有限公司 | C2: 107112464864-001 | D2: 107112464864 | E2: 46045 | F2: 5 | G2: 2736 | H2: 89000 | I2: 11706 | J2: 77294 | K2: 已全额还款 | L2: 2736 | M2: 已全额还款 | N2: 0
A3: 001 | B3: 中国对外经济贸易信托有限公司 | C3: 107113022670-001 | D3: 107113022670 | E3: 46045 | F3: 5 | G3: 4620 | H3: 137000 | I3: 21280 | J3: 115720 | K3: 已全额还款 | L3: 4620 | M3: 已全额还款 | N3: 0
A4: 001 | B4: 中国对外经济贸易信托有限公司 | C4: 107113105964-001 | D4: 107113105964 | E4: 46045 | F4: 5 | G4: 3600 | H4: 98000 | I4: 17240 | J4: 80760 | K4: 已全额还款 | L4: 3600 | M4: 已全额还款 | N4: 0
A5: 001 | B5: 中国对外经济贸易信托有限公司 | C5: 101127524235-001 | D5: 101127524235 | E5: 46045 | F5: 6 | G5: 2420 | H5: 50000 | I5: 14520 | J5: 35480 | K5: 已全额还款 | L5: 2420 | M5: 已全额还款 | N5: 0
A6: 001 | B6: 中国对外经济贸易信托有限公司 | C6: 101127876784-001 | D6: 101127876784 | E6: 46052 | F6: 6 | G6: 4160 | H6: 74642 | I6: 24960 | J6: 49682 | K6: 已全额还款 | L6: 4160 | M6: 已全额还款 | N6: 0
A7: 001 | B7: 中国对外经济贸易信托有限公司 | C7: 101127962550-001 | D7: 101127962550 | E7: 46045 | F7: 6 | G7: 2835 | H7: 84000 | I7: 17010 | J7: 66990 | K7: 已全额还款 | L7: 2835 | M7: 已全额还款 | N7: 0
A8: 001 | B8: 中国对外经济贸易信托有限公司 | C8: 101128409796-001 | D8: 101128409796 | E8: 46052 | F8: 6 | G8: 4853.33 | H8: 98000 | I8: 29119.98 | J8: 68880.02 | K8: 已全额还款 | L8: 4853.33 | M8: 已全额还款 | N8: 0
A9: 001 | B9: 中国对外经济贸易信托有限公司 | C9: 101130375783-001 | D9: 101130375783 | E9: 46045 | F9: 6 | G9: 2800 | H9: 83560 | I9: 16800 | J9: 66760 | K9: 已全额还款 | L9: 2800 | M9: 已全额还款 | N9: 0
A10: 001 | B10: 中国对外经济贸易信托有限公司 | C10: 101130620233-001 | D10: 101130620233 | E10: 46045 | F10: 6 | G10: 3840 | H10: 115413 | I10: 23040 | J10: 92373 | K10: 已全额还款 | L10: 3840 | M10: 已全额还款 | N10: 0
A11: 001 | B11: 中国对外经济贸易信托有限公司 | C11: 101130708066-001 | D11: 101130708066 | E11: 46045 | F11: 6 | G11: 2660 | H11: 78299 | I11: 15960 | J11: 62339 | K11: 已全额还款 | L11: 2660 | M11: 已全额还款 | N11: 0
A12: 001 | B12: 中国对外经济贸易信托有限公司 | C12: 101130763989-001 | D12: 101130763989 | E12: 46045 | F12: 6 | G12: 3850 | H12: 115960 | I12: 23100 | J12: 92860 | K12: 已全额还款 | L12: 3850 | M12: 已全额还款 | N12: 0
A13: 001 | B13: 中国对外经济贸易信托有限公司 | C13: 101130959533-001 | D13: 101130959533 | E13: 46045 | F13: 6 | G13: 2250 | H13: 78580 | I13: 13500 | J13: 65080 | K13: 已全额还款 | L13: 2250 | M13: 已全额还款 | N13: 0
... A156: 001 | B156: 中国对外经济贸易信托有限公司 | C156: 101129291267-001 | D156: 101129291267 | E156: 46052 | F156: 10 | G156: 4165 | H156: 78585 | I156: 36553 | J156: 42032 | K156: 已全额还款 | L156: 4165 | M156: 已全额还款 | N156: 0

Sheet 还款明细-0228已还款
A1: 资产包编号 | B1: 当前还款方 | C1: 资产编号(房源) | D1: 托管房源编码 | E1: 计划集中还款日期 | F1: 还款期数 | G1: 当期计划还款金额 | H1: 初始受让装修金额 | I1: 累计已还款金额 | J1: 剩余应还款余额 | K1: 本期还款状态 | L1: 当期实际还款金额 | M1: 本期是否逾期 | N1: 当期逾期天数
A2: 1 | B2: 中国对外经济贸易信托有限公司 | C2: 107112637443-001 | D2: 107112637443 | E2: 46059 | F2: 4 | G2: 3240 | H2: 96000 | I2: 9720 | J2: 86280 | K2: 已全额还款 | L2: 3240 | M2: 已全额还款 | N2: 0
A3: 1 | B3: 中国对外经济贸易信托有限公司 | C3: 101131458617-001 | D3: 101131458617 | E3: 46059 | F3: 5 | G3: 2470 | H3: 74000 | I3: 14820 | J3: 59180 | K3: 已全额还款 | L3: 2470 | M3: 已全额还款 | N3: 0
A4: 1 | B4: 中国对外经济贸易信托有限公司 | C4: 107112637443-001 | D4: 107112637443 | E4: 46073 | F4: 5 | G4: 3240 | H4: 96000 | I4: 12960 | J4: 83040 | K4: 已全额还款 | L4: 3240 | M4: 已全额还款 | N4: 0
A5: 1 | B5: 中国对外经济贸易信托有限公司 | C5: 101127311840-001 | D5: 101127311840 | E5: 46073 | F5: 6 | G5: 1132.33 | H5: 49162 | I5: 7188.98 | J5: 41973.02 | K5: 已全额还款 | L5: 1132.33 | M5: 已全额还款 | N5: 0
A6: 1 | B6: 中国对外经济贸易信托有限公司 | C6: 101128141006-001 | D6: 101128141006 | E6: 46066 | F6: 6 | G6: 9263 | H6: 164000 | I6: 55578 | J6: 108422 | K6: 已全额还款 | L6: 9263 | M6: 已全额还款 | N6: 0
A7: 1 | B7: 中国对外经济贸易信托有限公司 | C7: 101128199843-001 | D7: 101128199843 | E7: 46059 | F7: 6 | G7: 3200 | H7: 93677 | I7: 19200 | J7: 74477 | K7: 已全额还款 | L7: 3200 | M7: 已全额还款 | N7: 0
A8: 1 | B8: 中国对外经济贸易信托有限公司 | C8: 101128371669-001 | D8: 101128371669 | E8: 46059 | F8: 6 | G8: 4625 | H8: 166113 | I8: 27750 | J8: 138363 | K8: 已全额还款 | L8: 4625 | M8: 已全额还款 | N8: 0
A9: 1 | B9: 中国对外经济贸易信托有限公司 | C9: 101128568095-001 | D9: 101128568095 | E9: 46059 | F9: 6 | G9: 5035 | H9: 149000 | I9: 30210 | J9: 118790 | K9: 已全额还款 | L9: 5035 | M9: 已全额还款 | N9: 0
A10: 1 | B10: 中国对外经济贸易信托有限公司 | C10: 101130950078-001 | D10: 101130950078 | E10: 46073 | F10: 6 | G10: 4216 | H10: 85000 | I10: 25203 | J10: 59797 | K10: 已全额还款 | L10: 4216 | M10: 已全额还款 | N10: 0
A11: 1 | B11: 中国对外经济贸易信托有限公司 | C11: 107112417266-001 | D11: 107112417266 | E11: 46066 | F11: 6 | G11: 1155 | H11: 20000 | I11: 6930 | J11: 13070 | K11: 已全额还款 | L11: 1155 | M11: 已全额还款 | N11: 0
A12: 1 | B12: 中国对外经济贸易信托有限公司 | C12: 107112493987-001 | D12: 107112493987 | E12: 46059 | F12: 6 | G12: 1118 | H12: 19456 | I12: 6708 | J12: 12748 | K12: 已全额还款 | L12: 1118 | M12: 已全额还款 | N12: 0
A13: 1 | B13: 中国对外经济贸易信托有限公司 | C13: 107112621983-001 | D13: 107112621983 | E13: 46059 | F13: 6 | G13: 3822 | H13: 110923 | I13: 22932 | J13: 87991 | K13: 已全额还款 | L13: 3822 | M13: 已全额还款 | N13: 0
... A320: 1 | B320: 中国对外经济贸易信托有限公司 | C320: 101127339909-001 | D320: 101127339909 | E320: 46073 | F320: 13 | G320: 3200 | H320: 94060 | I320: 51395 | J320: 42665 | K320: 已全额还款 | L320: 3200 | M320: 已全额还款 | N320: 0

Sheet 还款明细-0320已还款
A1: 资产包编号 | B1: 当前还款方 | C1: 资产编号(房源) | D1: 托管房源编码 | E1: 当期计划还款金额 | F1: 初始受让装修金额 | G1: 累计已还款金额 | H1: 剩余应还款余额 | I1: 本期还款状态 | J1: 当期实际还款金额 | K1: 本期是否逾期 | L1: 当期逾期天数
A2: 1 | B2: 中国对外经济贸易信托有限公司 | C2: 101130107192-001 | D2: 101130107192 | E2: 3933 | F2: =IFERROR(VLOOKUP(C2,回款计划!B:E,4,0),0) -> 74625 | G2: =IFERROR(VLOOKUP(C2,回款计划!B:E,5,0),0) -> 0 | H2: =IFERROR(VLOOKUP(C2,回款计划!B:E,6,0),0) -> 0 | I2: 已全额还款 | J2: 3933 | K2: 已全额还款 | L2: 0
A3: 1 | B3: 中国对外经济贸易信托有限公司 | C3: 101129954626-001 | D3: 101129954626 | E3: 2805 | F3: =IFERROR(VLOOKUP(C3,回款计划!B:E,4,0),0) -> 83860 | G3: =IFERROR(VLOOKUP(C3,回款计划!B:E,5,0),0) -> 0 | H3: =IFERROR(VLOOKUP(C3,回款计划!B:E,6,0),0) -> 0 | I3: 已全额还款 | J3: 2805 | K3: 已全额还款 | L3: 0
A4: 1 | B4: 中国对外经济贸易信托有限公司 | C4: 107112460003-001 | D4: 107112460003 | E4: 3705 | F4: =IFERROR(VLOOKUP(C4,回款计划!B:E,4,0),0) -> 112715 | G4: =IFERROR(VLOOKUP(C4,回款计划!B:E,5,0),0) -> 0 | H4: =IFERROR(VLOOKUP(C4,回款计划!B:E,6,0),0) -> 0 | I4: 已全额还款 | J4: 3705 | K4: 已全额还款 | L4: 0
A5: 1 | B5: 中国对外经济贸易信托有限公司 | C5: 101130216363-001 | D5: 101130216363 | E5: 2640 | F5: =IFERROR(VLOOKUP(C5,回款计划!B:E,4,0),0) -> 78314 | G5: =IFERROR(VLOOKUP(C5,回款计划!B:E,5,0),0) -> 0 | H5: =IFERROR(VLOOKUP(C5,回款计划!B:E,6,0),0) -> 0 | I5: 已全额还款 | J5: 2640 | K5: 已全额还款 | L5: 0
A6: 1 | B6: 中国对外经济贸易信托有限公司 | C6: 107112557175-001 | D6: 107112557175 | E6: 2967 | F6: =IFERROR(VLOOKUP(C6,回款计划!B:E,4,0),0) -> 90192 | G6: =IFERROR(VLOOKUP(C6,回款计划!B:E,5,0),0) -> 0 | H6: =IFERROR(VLOOKUP(C6,回款计划!B:E,6,0),0) -> 0 | I6: 已全额还款 | J6: 2967 | K6: 已全额还款 | L6: 0
A7: 1 | B7: 中国对外经济贸易信托有限公司 | C7: 107113004258-001 | D7: 107113004258 | E7: 4500 | F7: =IFERROR(VLOOKUP(C7,回款计划!B:E,4,0),0) -> 106935 | G7: =IFERROR(VLOOKUP(C7,回款计划!B:E,5,0),0) -> 0 | H7: =IFERROR(VLOOKUP(C7,回款计划!B:E,6,0),0) -> 0 | I7: 已全额还款 | J7: 4500 | K7: 已全额还款 | L7: 0
A8: 1 | B8: 中国对外经济贸易信托有限公司 | C8: 107112568721-001 | D8: 107112568721 | E8: 2500 | F8: =IFERROR(VLOOKUP(C8,回款计划!B:E,4,0),0) -> 44480 | G8: =IFERROR(VLOOKUP(C8,回款计划!B:E,5,0),0) -> 0 | H8: =IFERROR(VLOOKUP(C8,回款计划!B:E,6,0),0) -> 0 | I8: 已全额还款 | J8: 2500 | K8: 已全额还款 | L8: 0
A9: 1 | B9: 中国对外经济贸易信托有限公司 | C9: 107112278618-001 | D9: 107112278618 | E9: 2585 | F9: =IFERROR(VLOOKUP(C9,回款计划!B:E,4,0),0) -> 93000 | G9: =IFERROR(VLOOKUP(C9,回款计划!B:E,5,0),0) -> 0 | H9: =IFERROR(VLOOKUP(C9,回款计划!B:E,6,0),0) -> 0 | I9: 已全额还款 | J9: 2585 | K9: 已全额还款 | L9: 0
A10: 1 | B10: 中国对外经济贸易信托有限公司 | C10: 107112858272-001 | D10: 107112858272 | E10: 4500 | F10: =IFERROR(VLOOKUP(C10,回款计划!B:E,4,0),0) -> 134461 | G10: =IFERROR(VLOOKUP(C10,回款计划!B:E,5,0),0) -> 0 | H10: =IFERROR(VLOOKUP(C10,回款计划!B:E,6,0),0) -> 0 | I10: 已全额还款 | J10: 4500 | K10: 已全额还款 | L10: 0
A11: 1 | B11: 中国对外经济贸易信托有限公司 | C11: 101129590806-001 | D11: 101129590806 | E11: 3080 | F11: =IFERROR(VLOOKUP(C11,回款计划!B:E,4,0),0) -> 94515 | G11: =IFERROR(VLOOKUP(C11,回款计划!B:E,5,0),0) -> 0 | H11: =IFERROR(VLOOKUP(C11,回款计划!B:E,6,0),0) -> 0 | I11: 已全额还款 | J11: 3080 | K11: 已全额还款 | L11: 0
A12: 1 | B12: 中国对外经济贸易信托有限公司 | C12: 107112612966-001 | D12: 107112612966 | E12: 3050 | F12: =IFERROR(VLOOKUP(C12,回款计划!B:E,4,0),0) -> 91016 | G12: =IFERROR(VLOOKUP(C12,回款计划!B:E,5,0),0) -> 0 | H12: =IFERROR(VLOOKUP(C12,回款计划!B:E,6,0),0) -> 0 | I12: 已全额还款 | J12: 3050 | K12: 已全额还款 | L12: 0
A13: 1 | B13: 中国对外经济贸易信托有限公司 | C13: 107112576388-001 | D13: 107112576388 | E13: 1755 | F13: =IFERROR(VLOOKUP(C13,回款计划!B:E,4,0),0) -> 31400 | G13: =IFERROR(VLOOKUP(C13,回款计划!B:E,5,0),0) -> 0 | H13: =IFERROR(VLOOKUP(C13,回款计划!B:E,6,0),0) -> 0 | I13: 已全额还款 | J13: 1755 | K13: 已全额还款 | L13: 0
... A213: 1 | B213: 中国对外经济贸易信托有限公司 | C213: 107106308722-001 | D213: 107106308722 | E213: 2808 | F213: =IFERROR(VLOOKUP(C213,回款计划!B:E,4,0),0) -> 88414 | G213: =IFERROR(VLOOKUP(C213,回款计划!B:E,5,0),0) -> 0 | H213: =IFERROR(VLOOKUP(C213,回款计划!B:E,6,0),0) -> 0 | I213: 已全额还款 | J213: 2808 | K213: 已全额还款 | L213: 0

Sheet 还款明细-0327已还款
A1: 资产包编号 | B1: 当前还款方 | C1: 资产编号(房源) | D1: 托管房源编码 | E1: 当期计划还款金额 | F1: 初始受让装修金额 | G1: 累计已还款金额 | H1: 剩余应还款余额 | I1: 本期还款状态 | J1: 当期实际还款金额 | K1: 本期是否逾期 | L1: 当期逾期天数
A2: 1 | B2: 中国对外经济贸易信托有限公司 | C2: 107111763962-001 | D2: 107111763962 | E2: 1105 | F2: 19454 | G2: 8840 | H2: 10614 | I2: 已全额还款 | J2: 1105 | K2: 已全额还款 | L2: 0
A3: 1 | B3: 中国对外经济贸易信托有限公司 | C3: 107112602426-001 | D3: 107112602426 | E3: 3339 | F3: 101368 | G3: 25493 | H3: 75875 | I3: 已全额还款 | J3: 3339 | K3: 已全额还款 | L3: 0
A4: 1 | B4: 中国对外经济贸易信托有限公司 | C4: 101129349340-001 | D4: 101129349340 | E4: 2700 | F4: 80000 | G4: 21600 | H4: 58400 | I4: 已全额还款 | J4: 2700 | K4: 已全额还款 | L4: 0
A5: 1 | B5: 中国对外经济贸易信托有限公司 | C5: 107112657404-001 | D5: 107112657404 | E5: 4524 | F5: 136666 | G5: 33748 | H5: 102918 | I5: 已全额还款 | J5: 4524 | K5: 已全额还款 | L5: 0
A6: 1 | B6: 中国对外经济贸易信托有限公司 | C6: 107112246859-001 | D6: 107112246859 | E6: 2914 | F6: 87624 | G6: 25192 | H6: 62432 | I6: 已全额还款 | J6: 2914 | K6: 已全额还款 | L6: 0
A7: 1 | B7: 中国对外经济贸易信托有限公司 | C7: 101128409796-001 | D7: 101128409796 | E7: 4853.33 | F7: 98000 | G7: 29119.98 | H7: 68880.02 | I7: 已全额还款 | J7: 4853.33 | K7: 已全额还款 | L7: 0
A8: 1 | B8: 中国对外经济贸易信托有限公司 | C8: 107112708646-001 | D8: 107112708646 | E8: 1273 | F8: 22732 | G8: 10184 | H8: 12548 | I8: 已全额还款 | J8: 1273 | K8: 已全额还款 | L8: 0
A9: 1 | B9: 中国对外经济贸易信托有限公司 | C9: 107112331524-001 | D9: 107112331524 | E9: 4100 | F9: 70000 | G9: 32409 | H9: 37591 | I9: 已全额还款 | J9: 4100 | K9: 已全额还款 | L9: 0
A10: 1 | B10: 中国对外经济贸易信托有限公司 | C10: 107113116925-001 | D10: 107113116925 | E10: 2254 | F10: 39074 | G10: 15414 | H10: 23660 | I10: 已全额还款 | J10: 2254 | K10: 已全额还款 | L10: 0
A11: 1 | B11: 中国对外经济贸易信托有限公司 | C11: 107112983263-001 | D11: 107112983263 | E11: 3420 | F11: 100900 | G11: 22090 | H11: 78810 | I11: 已全额还款 | J11: 3420 | K11: 已全额还款 | L11: 0
A12: 1 | B12: 中国对外经济贸易信托有限公司 | C12: 107113171713-001 | D12: 107113171713 | E12: 1520 | F12: 77000 | G12: 16796 | H12: 60204 | I12: 已全额还款 | J12: 1520 | K12: 已全额还款 | L12: 0
A13: 1 | B13: 中国对外经济贸易信托有限公司 | C13: 107112813849-001 | D13: 107112813849 | E13: 675 | F13: 16502 | G13: 4725 | H13: 11777 | I13: 已全额还款 | J13: 675 | K13: 已全额还款 | L13: 0
... A28: 1 | B28: 中国对外经济贸易信托有限公司 | C28: 107112705537-001 | D28: 107112705537 | E28: 1399.92 | F28: 24606 | G28: 12599.28 | H28: 12006.72 | I28: 已全额还款 | J28: 1399.92 | K28: 已全额还款 | L28: 0

Sheet 0403已还款
A1: 资产包编号 | B1: 当前还款方 | C1: 资产编号(房源) | D1: 托管房源编码 | E1: 当期计划还款金额 | F1: 初始受让装修金额 | G1: 累计已还款金额 | H1: 剩余应还款余额 | I1: 本期还款状态 | J1: 当期实际还款金额 | K1: 本期是否逾期 | L1: 当期逾期天数
A2: 1 | B2: 中国对外经济贸易信托有限公司 | C2: 101129560839-001 | D2: 101129560839 | E2: 3000 | F2: 89318 | G2: 23750 | H2: 65568 | I2: 已全额还款 | J2: =E2 -> 3000 | K2: 已全额还款 | L2: 0
A3: 1 | B3: 中国对外经济贸易信托有限公司 | C3: 101130387057-001 | D3: 101130387057 | E3: 2652 | F3: 79976 | G3: 18564 | H3: 61412 | I3: 已全额还款 | J3: =E3 -> 2652 | K3: 已全额还款 | L3: 0
A4: 1 | B4: 中国对外经济贸易信托有限公司 | C4: 107112765285-001 | D4: 107112765285 | E4: 4005 | F4: 121500 | G4: 29835 | H4: 91665 | I4: 已全额还款 | J4: =E4 -> 4005 | K4: 已全额还款 | L4: 0
A5: 1 | B5: 中国对外经济贸易信托有限公司 | C5: 107112633794-001 | D5: 107112633794 | E5: 5880 | F5: 179000 | G5: 42158 | H5: 136842 | I5: 已全额还款 | J5: =E5 -> 5880 | K5: 已全额还款 | L5: 0
A6: 1 | B6: 中国对外经济贸易信托有限公司 | C6: 101129963777-001 | D6: 101129963777 | E6: 5635 | F6: 169978 | G6: 43661.67 | H6: 126316.33 | I6: 已全额还款 | J6: =E6 -> 5635 | K6: 已全额还款 | L6: 0
A7: 1 | B7: 中国对外经济贸易信托有限公司 | C7: 107112476987-001 | D7: 107112476987 | E7: 1566 | F7: 29297 | G7: 12876 | H7: 16421 | I7: 已全额还款 | J7: =E7 -> 1566 | K7: 已全额还款 | L7: 0
A8: 1 | B8: 中国对外经济贸易信托有限公司 | C8: 107112926715-001 | D8: 107112926715 | E8: 3285 | F8: 95000 | G8: 21610 | H8: 73390 | I8: 已全额还款 | J8: =E8 -> 3285 | K8: 已全额还款 | L8: 0
A9: 1 | B9: 中国对外经济贸易信托有限公司 | C9: 107113008480-001 | D9: 107113008480 | E9: 3953 | F9: 123000 | G9: 26398 | H9: 96602 | I9: 已全额还款 | J9: =E9 -> 3953 | K9: 已全额还款 | L9: 0
A10: 1 | B10: 中国对外经济贸易信托有限公司 | C10: 107112619000-001 | D10: 107112619000 | E10: 2900 | F10: 87000 | G10: 18500 | H10: 68500 | I10: 已全额还款 | J10: =E10 -> 2900 | K10: 已全额还款 | L10: 0
A11: 1 | B11: 中国对外经济贸易信托有限公司 | C11: 107112653316-001 | D11: 107112653316 | E11: 2772 | F11: 84510 | G11: 21084 | H11: 63426 | I11: 已全额还款 | J11: =E11 -> 2772 | K11: 已全额还款 | L11: 0
A12: 1 | B12: 中国对外经济贸易信托有限公司 | C12: 101129645009-001 | D12: 101129645009 | E12: 4664 | F12: 140559 | G12: 36168 | H12: 104391 | I12: 已全额还款 | J12: =E12 -> 4664 | K12: 已全额还款 | L12: 0
A13: 1 | B13: 中国对外经济贸易信托有限公司 | C13: 107112535561-001 | D13: 107112535561 | E13: 2856 | F13: 101346 | G13: 20116 | H13: 81230 | I13: 已全额还款 | J13: =E13 -> 2856 | K13: 已全额还款 | L13: 0
... A99: 1 | B99: 中国对外经济贸易信托有限公司 | C99: 107112290433-001 | D99: 107112290433 | E99: 3536 | F99: 121325 | G99: 28288 | H99: 93037 | I99: 已全额还款 | J99: =E99 -> 3536 | K99: 已全额还款 | L99: 0

Sheet 0410已还款
A1: 资产包编号 | B1: 当前还款方 | C1: 资产编号(房源) | D1: 托管房源编码 | E1: 当期计划还款金额 | F1: 初始受让装修金额 | G1: 累计已还款金额 | H1: 剩余应还款余额 | I1: 本期还款状态 | J1: 当期实际还款金额 | K1: 本期是否逾期 | L1: 当期逾期天数
A2: 1 | B2: 中国对外经济贸易信托有限公司 | C2: 107112633046-001 | D2: 107112633046 | E2: 1800 | F2: 78888 | G2: 16650 | H2: 62238 | I2: 已全额还款 | J2: 1800 | K2: 已全额还款 | L2: 0
A3: 1 | B3: 中国对外经济贸易信托有限公司 | C3: 107112529588-001 | D3: 107112529588 | E3: 1679 | F3: 30363 | G3: 15111 | H3: 15252 | I3: 已全额还款 | J3: 1679 | K3: 已全额还款 | L3: 0
A4: 1 | B4: 中国对外经济贸易信托有限公司 | C4: 107112456127-001 | D4: 107112456127 | E4: 3692 | F4: 112197 | G4: 31616 | H4: 80581 | I4: 已全额还款 | J4: 3692 | K4: 已全额还款 | L4: 0
A5: 1 | B5: 中国对外经济贸易信托有限公司 | C5: 101128199843-001 | D5: 101128199843 | E5: 3200 | F5: 93677 | G5: 19200 | H5: 74477 | I5: 已全额还款 | J5: 3200 | K5: 已全额还款 | L5: 0
A6: 1 | B6: 中国对外经济贸易信托有限公司 | C6: 107112217965-001 | D6: 107112217965 | E6: 2200 | F6: 66000 | G6: 19200 | H6: 46800 | I6: 已全额还款 | J6: 2200 | K6: 已全额还款 | L6: 0
A7: 1 | B7: 中国对外经济贸易信托有限公司 | C7: 101130796627-001 | D7: 101130796627 | E7: 4872 | F7: 121733 | G7: 37584 | H7: 84149 | I7: 已全额还款 | J7: 4872 | K7: 已全额还款 | L7: 0
A8: 1 | B8: 中国对外经济贸易信托有限公司 | C8: 107112950619-001 | D8: 107112950619 | E8: 4980 | F8: 143403 | G8: 32380 | H8: 111023 | I8: 已全额还款 | J8: 4980 | K8: 已全额还款 | L8: 0
A9: 1 | B9: 中国对外经济贸易信托有限公司 | C9: 107112901979-001 | D9: 107112901979 | E9: 5040 | F9: 149690 | G9: 33301 | H9: 116389 | I9: 已全额还款 | J9: 5040 | K9: 已全额还款 | L9: 0
A10: 1 | B10: 中国对外经济贸易信托有限公司 | C10: 101129734313-001 | D10: 101129734313 | E10: 4352 | F10: 79477 | G10: 30742 | H10: 48735 | I10: 已全额还款 | J10: 4352 | K10: 已全额还款 | L10: 0
A11: 1 | B11: 中国对外经济贸易信托有限公司 | C11: 107113004258-001 | D11: 107113004258 | E11: 4500 | F11: 106935 | G11: 33600 | H11: 73335 | I11: 已全额还款 | J11: 4500 | K11: 已全额还款 | L11: 0
A12: 1 | B12: 中国对外经济贸易信托有限公司 | C12: 107112328931-001 | D12: 107112328931 | E12: 476 | F12: 8410 | G12: 4284 | H12: 4126 | I12: 已全额还款 | J12: 476 | K12: 已全额还款 | L12: 0
A13: 1 | B13: 中国对外经济贸易信托有限公司 | C13: 107113106536-001 | D13: 107113106536 | E13: 1520 | F13: 27939 | G13: 10640 | H13: 17299 | I13: 已全额还款 | J13: 1520 | K13: 已全额还款 | L13: 0
... A105: 1 | B105: 中国对外经济贸易信托有限公司 | C105: 107111707839-001 | D105: 107111707839 | E105: 3330 | F105: 80000 | G105: 28120 | H105: 51880 | I105: 已全额还款 | J105: 3330 | K105: 已全额还款 | L105: 0

Sheet 0417已还款
A1: 资产包编号 | B1: 当前还款方 | C1: 资产编号(房源) | D1: 托管房源编码 | E1: 当期计划还款金额 | F1: 初始受让装修金额 | G1: 累计已还款金额 | H1: 剩余应还款余额 | I1: 本期还款状态 | J1: 当期实际还款金额 | K1: 本期是否逾期 | L1: 当期逾期天数
A2: 1 | B2: 中国对外经济贸易信托有限公司 | C2: 107112719541-001 | D2: 107112719541 | E2: 864 | F2: 15000 | G2: 6048 | H2: 8952 | I2: 已全额还款 | J2: 864 | K2: 已全额还款 | L2: 0
A3: 1 | B3: 中国对外经济贸易信托有限公司 | C3: 107112798785-001 | D3: 107112798785 | E3: 2496 | F3: 75452 | G3: 19392 | H3: 56060 | I3: 已全额还款 | J3: 2496 | K3: 已全额还款 | L3: 0
A4: 1 | B4: 中国对外经济贸易信托有限公司 | C4: 107112205936-001 | D4: 107112205936 | E4: 4015 | F4: 121169 | G4: 34320 | H4: 86849 | I4: 已全额还款 | J4: 4015 | K4: 已全额还款 | L4: 0
A5: 1 | B5: 中国对外经济贸易信托有限公司 | C5: 101130107192-001 | D5: 101130107192 | E5: 3933 | F5: 74625 | G5: 35397 | H5: 39228 | I5: 已全额还款 | J5: 3933 | K5: 已全额还款 | L5: 0
A6: 1 | B6: 中国对外经济贸易信托有限公司 | C6: 107112404846-001 | D6: 107112404846 | E6: 2960 | F6: 106836 | G6: 23640 | H6: 83196 | I6: 已全额还款 | J6: 2960 | K6: 已全额还款 | L6: 0
A7: 1 | B7: 中国对外经济贸易信托有限公司 | C7: 107112470213-001 | D7: 107112470213 | E7: 1330 | F7: 23863 | G7: 12510 | H7: 11353 | I7: 已全额还款 | J7: 1330 | K7: 已全额还款 | L7: 0
A8: 1 | B8: 中国对外经济贸易信托有限公司 | C8: 101130115346-001 | D8: 101130115346 | E8: 4725 | F8: 88848 | G8: 40110 | H8: 48738 | I8: 已全额还款 | J8: 4725 | K8: 已全额还款 | L8: 0
A9: 1 | B9: 中国对外经济贸易信托有限公司 | C9: 107112697786-001 | D9: 107112697786 | E9: 2784 | F9: 89000 | G9: 16672 | H9: 72328 | I9: 已全额还款 | J9: 2784 | K9: 已全额还款 | L9: 0
A10: 1 | B10: 中国对外经济贸易信托有限公司 | C10: 107112670693-001 | D10: 107112670693 | E10: 3034 | F10: 91593 | G10: 22878 | H10: 68715 | I10: 已全额还款 | J10: 3034 | K10: 已全额还款 | L10: 0
A11: 1 | B11: 中国对外经济贸易信托有限公司 | C11: 107112663876-001 | D11: 107112663876 | E11: 1080 | F11: 19087 | G11: 9720 | H11: 9367 | I11: 已全额还款 | J11: 1080 | K11: 已全额还款 | L11: 0
A12: 1 | B12: 中国对外经济贸易信托有限公司 | C12: 101131216709-001 | D12: 101131216709 | E12: 2850 | F12: 84946 | G12: 22700 | H12: 62246 | I12: 已全额还款 | J12: 2850 | K12: 已全额还款 | L12: 0
A13: 1 | B13: 中国对外经济贸易信托有限公司 | C13: 101129590806-001 | D13: 101129590806 | E13: 3080 | F13: 94515 | G13: 30604 | H13: 63911 | I13: 已全额还款 | J13: 3080 | K13: 已全额还款 | L13: 0
... A64: 1 | B64: 中国对外经济贸易信托有限公司 | C64: 101130133766-001 | D64: 101130133766 | E64: 2730 | F64: 84220 | G64: 24523.33 | H64: 59696.67 | I64: 已全额还款 | J64: 2730 | K64: 已全额还款 | L64: 0

Sheet 0424-已还款
A1: 资产包编号 | B1: 当前还款方 | C1: 资产编号(房源) | D1: 托管房源编码 | E1: 当期计划还款金额 | F1: 初始受让装修金额 | G1: 累计已还款金额 | H1: 剩余应还款余额 | I1: 本期还款状态 | J1: 当期实际还款金额 | K1: 本期是否逾期 | L1: 当期逾期天数
A2: 1 | B2: 中国对外经济贸易信托有限公司 | C2: 101127311840-001 | D2: 101127311840 | E2: 1132.33 | F2: 49162 | G2: 8321.31 | H2: 40840.69 | I2: 已全额还款 | J2: 1132.33 | K2: 已全额还款 | L2: 0
A3: 1 | B3: 中国对外经济贸易信托有限公司 | C3: 107112610087-001 | D3: 107112610087 | E3: 1178 | F3: 20715 | G3: 9424 | H3: 11291 | I3: 已全额还款 | J3: 1178 | K3: 已全额还款 | L3: 0
A4: 1 | B4: 中国对外经济贸易信托有限公司 | C4: 101130216363-001 | D4: 101130216363 | E4: 2640 | F4: 78314 | G4: 23760 | H4: 54554 | I4: 已全额还款 | J4: 2640 | K4: 已全额还款 | L4: 0
A5: 1 | B5: 中国对外经济贸易信托有限公司 | C5: 107112497805-001 | D5: 107112497805 | E5: 4120 | F5: 137380 | G5: 33803 | H5: 103577 | I5: 已全额还款 | J5: 4120 | K5: 已全额还款 | L5: 0
A6: 1 | B6: 中国对外经济贸易信托有限公司 | C6: 107112762784-001 | D6: 107112762784 | E6: 1360 | F6: 24696 | G6: 12240 | H6: 12456 | I6: 已全额还款 | J6: 1360 | K6: 已全额还款 | L6: 0
A7: 1 | B7: 中国对外经济贸易信托有限公司 | C7: 107111390157-001 | D7: 107111390157 | E7: 1782 | F7: 52000 | G7: 21384 | H7: 30616 | I7: 已全额还款 | J7: 1782 | K7: 已全额还款 | L7: 0
A8: 1 | B8: 中国对外经济贸易信托有限公司 | C8: 107112784036-001 | D8: 107112784036 | E8: 5292 | F8: 161888 | G8: 35572 | H8: 126316 | I8: 已全额还款 | J8: 5292 | K8: 已全额还款 | L8: 0
A9: 1 | B9: 中国对外经济贸易信托有限公司 | C9: 107112806153-001 | D9: 107112806153 | E9: 1488 | F9: 26555 | G9: 11904 | H9: 14651 | I9: 已全额还款 | J9: 1488 | K9: 已全额还款 | L9: 0
A10: 1 | B10: 中国对外经济贸易信托有限公司 | C10: 107112379629-001 | D10: 107112379629 | E10: 2550 | F10: 79554 | G10: 22610 | H10: 56944 | I10: 已全额还款 | J10: 2550 | K10: 已全额还款 | L10: 0
A11: 1 | B11: 中国对外经济贸易信托有限公司 | C11: 101127524235-001 | D11: 101127524235 | E11: 2383.33 | F11: 50000 | G11: 16903.33 | H11: 33096.67 | I11: 已全额还款 | J11: 2383.33 | K11: 已全额还款 | L11: 0
A12: 1 | B12: 中国对外经济贸易信托有限公司 | C12: 101130607995-001 | D12: 101130607995 | E12: 3432 | F12: 120000 | G12: 34158 | H12: 85842 | I12: 已全额还款 | J12: 3432 | K12: 已全额还款 | L12: 0
A13: 1 | B13: 中国对外经济贸易信托有限公司 | C13: 101129694480-001 | D13: 101129694480 | E13: 2752 | F13: 81225 | G13: 27378 | H13: 53847 | I13: 已全额还款 | J13: 2752 | K13: 已全额还款 | L13: 0
... A108: 1 | B108: 中国对外经济贸易信托有限公司 | C108: 101129349328-001 | D108: 101129349328 | E108: 2700 | F108: 80000 | G108: 27000 | H108: 53000 | I108: 已全额还款 | J108: 2700 | K108: 已全额还款 | L108: 0

Sheet 0501-已还款
A1: 资产包编号 | B1: 当前还款方 | C1: 资产编号(房源) | D1: 托管房源编码 | E1: 当期计划还款金额 | F1: 初始受让装修金额 | G1: 累计已还款金额 | H1: 剩余应还款余额 | I1: 本期还款状态 | J1: 当期实际还款金额 | K1: 本期是否逾期 | L1: 当期逾期天数
A2: 1 | B2: 中国对外经济贸易信托有限公司 | C2: 101130387057-001 | D2: 101130387057 | E2: 2652 | F2: 79976 | G2: 21216 | H2: 58760 | I2: 已全额还款 | J2: 2652 | K2: 已全额还款 | L2: 0
A3: 1 | B3: 中国对外经济贸易信托有限公司 | C3: 101130093956-001 | D3: 101130093956 | E3: 65500 | F3: 88000 | G3: 22500 | H3: 65500 | I3: 已全额还款 | J3: 65500 | K3: 已全额还款 | L3: 0
A4: 1 | B4: 中国对外经济贸易信托有限公司 | C4: 107112476987-001 | D4: 107112476987 | E4: 1566 | F4: 29297 | G4: 14442 | H4: 14855 | I4: 已全额还款 | J4: 1566 | K4: 已全额还款 | L4: 0
A5: 1 | B5: 中国对外经济贸易信托有限公司 | C5: 107112926715-001 | D5: 107112926715 | E5: 3285 | F5: 95000 | G5: 24895 | H5: 70105 | I5: 已全额还款 | J5: 3285 | K5: 已全额还款 | L5: 0
A6: 1 | B6: 中国对外经济贸易信托有限公司 | C6: 107112619000-001 | D6: 107112619000 | E6: 2900 | F6: 87000 | G6: 21400 | H6: 65600 | I6: 已全额还款 | J6: 2900 | K6: 已全额还款 | L6: 0
A7: 1 | B7: 中国对外经济贸易信托有限公司 | C7: 107112653316-001 | D7: 107112653316 | E7: 2772 | F7: 84510 | G7: 23856 | H7: 60654 | I7: 已全额还款 | J7: 2772 | K7: 已全额还款 | L7: 0
A8: 1 | B8: 中国对外经济贸易信托有限公司 | C8: 107111763962-001 | D8: 107111763962 | E8: 1105 | F8: 19454 | G8: 9945 | H8: 9509 | I8: 已全额还款 | J8: 1105 | K8: 已全额还款 | L8: 0
A9: 1 | B9: 中国对外经济贸易信托有限公司 | C9: 107112602426-001 | D9: 107112602426 | E9: 3339 | F9: 101368 | G9: 28832 | H9: 72536 | I9: 已全额还款 | J9: 3339 | K9: 已全额还款 | L9: 0
A10: 1 | B10: 中国对外经济贸易信托有限公司 | C10: 101129349340-001 | D10: 101129349340 | E10: 2700 | F10: 80000 | G10: 24300 | H10: 55700 | I10: 已全额还款 | J10: 2700 | K10: 已全额还款 | L10: 0
A11: 1 | B11: 中国对外经济贸易信托有限公司 | C11: 107112657404-001 | D11: 107112657404 | E11: 4524 | F11: 136666 | G11: 38272 | H11: 98394 | I11: 已全额还款 | J11: 4524 | K11: 已全额还款 | L11: 0
A12: 1 | B12: 中国对外经济贸易信托有限公司 | C12: 107112246859-001 | D12: 107112246859 | E12: 2914 | F12: 87624 | G12: 28106 | H12: 59518 | I12: 已全额还款 | J12: 2914 | K12: 已全额还款 | L12: 0
A13: 1 | B13: 中国对外经济贸易信托有限公司 | C13: 101128409796-001 | D13: 101128409796 | E13: 4853.33 | F13: 98000 | G13: 33973.31 | H13: 64026.69 | I13: 已全额还款 | J13: 4853.33 | K13: 已全额还款 | L13: 0
... A72: 1 | B72: 中国对外经济贸易信托有限公司 | C72: 107112290433-001 | D72: 107112290433 | E72: 3536 | F72: 121325 | G72: 31824 | H72: 89501 | I72: 已全额还款 | J72: 3536 | K72: 已全额还款 | L72: 0

Sheet 0508-已还款
A1: 资产包编号 | B1: 当前还款方 | C1: 资产编号(房源) | D1: 托管房源编码 | E1: 当期计划还款金额 | F1: 初始受让装修金额 | G1: 累计已还款金额 | H1: 剩余应还款余额 | I1: 本期还款状态 | J1: 当期实际还款金额 | K1: 本期是否逾期 | L1: 当期逾期天数
A2: 1 | B2: 中国对外经济贸易信托有限公司 | C2: 107112633046-001 | D2: 107112633046 | E2: 2475 | F2: 78888 | G2: 18450 | H2: 60438 | I2: 已全额还款 | J2: 2475 | K2: 已全额还款 | L2: 0
A3: 1 | B3: 中国对外经济贸易信托有限公司 | C3: 101129560839-001 | D3: 101129560839 | E3: 3000 | F3: 89318 | G3: 26750 | H3: 62568 | I3: 已全额还款 | J3: 3000 | K3: 已全额还款 | L3: 0
A4: 1 | B4: 中国对外经济贸易信托有限公司 | C4: 107112765285-001 | D4: 107112765285 | E4: 4005 | F4: 121500 | G4: 33840 | H4: 87660 | I4: 已全额还款 | J4: 4005 | K4: 已全额还款 | L4: 0
A5: 1 | B5: 中国对外经济贸易信托有限公司 | C5: 107112529588-001 | D5: 107112529588 | E5: 1679 | F5: 30363 | G5: 16790 | H5: 13573 | I5: 已全额还款 | J5: 1679 | K5: 已全额还款 | L5: 0
A6: 1 | B6: 中国对外经济贸易信托有限公司 | C6: 107112456127-001 | D6: 107112456127 | E6: 3692 | F6: 112197 | G6: 35308 | H6: 76889 | I6: 已全额还款 | J6: 3692 | K6: 已全额还款 | L6: 0
A7: 1 | B7: 中国对外经济贸易信托有限公司 | C7: 107112633794-001 | D7: 107112633794 | E7: 5880 | F7: 179000 | G7: 48038 | H7: 130962 | I7: 已全额还款 | J7: 5880 | K7: 已全额还款 | L7: 0
A8: 1 | B8: 中国对外经济贸易信托有限公司 | C8: 101128199843-001 | D8: 101128199843 | E8: 3200 | F8: 93677 | G8: 22400 | H8: 71277 | I8: 已全额还款 | J8: 3200 | K8: 已全额还款 | L8: 0
A9: 1 | B9: 中国对外经济贸易信托有限公司 | C9: 107112217965-001 | D9: 107112217965 | E9: 2200 | F9: 66000 | G9: 21400 | H9: 44600 | I9: 已全额还款 | J9: 2200 | K9: 已全额还款 | L9: 0
A10: 1 | B10: 中国对外经济贸易信托有限公司 | C10: 101130796627-001 | D10: 101130796627 | E10: 4872 | F10: 121733 | G10: 42456 | H10: 79277 | I10: 已全额还款 | J10: 4872 | K10: 已全额还款 | L10: 0
A11: 1 | B11: 中国对外经济贸易信托有限公司 | C11: 107112950619-001 | D11: 107112950619 | E11: 4980 | F11: 143403 | G11: 37360 | H11: 106043 | I11: 已全额还款 | J11: 4980 | K11: 已全额还款 | L11: 0
A12: 1 | B12: 中国对外经济贸易信托有限公司 | C12: 101129963777-001 | D12: 101129963777 | E12: 5635 | F12: 169978 | G12: 49296.67 | H12: 120681.33 | I12: 已全额还款 | J12: 5635 | K12: 已全额还款 | L12: 0
A13: 1 | B13: 中国对外经济贸易信托有限公司 | C13: 101129734313-001 | D13: 101129734313 | E13: 4352 | F13: 79477 | G13: 35094 | H13: 44383 | I13: 已全额还款 | J13: 4352 | K13: 已全额还款 | L13: 0
... A151: 1 | B151: 中国对外经济贸易信托有限公司 | C151: 107111707839-001 | D151: 107111707839 | E151: 3330 | F151: 80000 | G151: 31450 | H151: 48550 | I151: 已全额还款 | J151: 3330 | K151: 已全额还款 | L151: 0

Sheet 0515-已还款
A1: 资产包编号 | B1: 当前还款方 | C1: 资产编号(房源) | D1: 托管房源编码 | E1: 当期计划还款金额 | F1: 初始受让装修金额 | G1: 累计已还款金额 | H1: 剩余应还款余额 | I1: 本期还款状态 | J1: 当期实际还款金额 | K1: 本期是否逾期 | L1: 当期逾期天数
A2: 1 | B2: 中国对外经济贸易信托有限公司 | C2: 107112719541-001 | D2: 107112719541 | E2: 864 | F2: 15000 | G2: 6912 | H2: 8088 | I2: 已全额还款 | J2: 864 | K2: 已全额还款 | L2: 0
A3: 1 | B3: 中国对外经济贸易信托有限公司 | C3: 107112798785-001 | D3: 107112798785 | E3: 2496 | F3: 75452 | G3: 21888 | H3: 53564 | I3: 已全额还款 | J3: 2496 | K3: 已全额还款 | L3: 0
A4: 1 | B4: 中国对外经济贸易信托有限公司 | C4: 107112205936-001 | D4: 107112205936 | E4: 4015 | F4: 121169 | G4: 38335 | H4: 82834 | I4: 已全额还款 | J4: 4015 | K4: 已全额还款 | L4: 0
A5: 1 | B5: 中国对外经济贸易信托有限公司 | C5: 107112404846-001 | D5: 107112404846 | E5: 2960 | F5: 106836 | G5: 26600 | H5: 80236 | I5: 已全额还款 | J5: 2960 | K5: 已全额还款 | L5: 0
A6: 1 | B6: 中国对外经济贸易信托有限公司 | C6: 107112470213-001 | D6: 107112470213 | E6: 1330 | F6: 23863 | G6: 13840 | H6: 10023 | I6: 已全额还款 | J6: 1330 | K6: 已全额还款 | L6: 0
A7: 1 | B7: 中国对外经济贸易信托有限公司 | C7: 107112697786-001 | D7: 107112697786 | E7: 2784 | F7: 89000 | G7: 19456 | H7: 69544 | I7: 已全额还款 | J7: 2784 | K7: 已全额还款 | L7: 0
A8: 1 | B8: 中国对外经济贸易信托有限公司 | C8: 107112663876-001 | D8: 107112663876 | E8: 1140 | F8: 19087 | G8: 10800 | H8: 8287 | I8: 已全额还款 | J8: 1140 | K8: 已全额还款 | L8: 0
A9: 1 | B9: 中国对外经济贸易信托有限公司 | C9: 101129727695-001 | D9: 101129727695 | E9: 3445 | F9: 104637 | G9: 36833.33 | H9: 67803.67 | I9: 已全额还款 | J9: 3445 | K9: 已全额还款 | L9: 0
A10: 1 | B10: 中国对外经济贸易信托有限公司 | C10: 101129590806-001 | D10: 101129590806 | E10: 3080 | F10: 94515 | G10: 33684 | H10: 60831 | I10: 已全额还款 | J10: 3080 | K10: 已全额还款 | L10: 0
A11: 1 | B11: 中国对外经济贸易信托有限公司 | C11: 107112967766-001 | D11: 107112967766 | E11: 3402 | F11: 103000 | G11: 25974 | H11: 77026 | I11: 已全额还款 | J11: 3402 | K11: 已全额还款 | L11: 0
A12: 1 | B12: 中国对外经济贸易信托有限公司 | C12: 101129405710-001 | D12: 101129405710 | E12: 5460 | F12: 100000 | G12: 57150 | H12: 42850 | I12: 已全额还款 | J12: 5460 | K12: 已全额还款 | L12: 0
A13: 1 | B13: 中国对外经济贸易信托有限公司 | C13: 101128209031-001 | D13: 101128209031 | E13: 1840 | F13: 55000 | G13: 20240 | H13: 34760 | I13: 已全额还款 | J13: 1840 | K13: 已全额还款 | L13: 0
... A51: 1 | B51: 中国对外经济贸易信托有限公司 | C51: 107111936214-001 | D51: 107111936214 | E51: 1920 | F51: 102530 | G51: 31671 | H51: 70859 | I51: 已全额还款 | J51: 1920 | K51: 已全额还款 | L51: 0

Sheet 0522-已还款
A1: 资产包编号 | B1: 当前还款方 | C1: 资产编号(房源) | D1: 托管房源编码 | E1: 当期计划还款金额 | F1: 初始受让装修金额 | G1: 累计已还款金额 | H1: 剩余应还款余额 | I1: 本期还款状态 | J1: 当期实际还款金额 | K1: 本期是否逾期 | L1: 当期逾期天数
A2: 1 | B2: 中国对外经济贸易信托有限公司 | C2: 101130387057-001 | D2: 101130387057 | E2: 53456 | F2: 79976 | G2: 23868 | H2: 56108 | I2: 已全额还款 | J2: 53456 | K2: 已全额还款 | L2: 0
A3: 1 | B3: 中国对外经济贸易信托有限公司 | C3: 101130216363-001 | D3: 101130216363 | E3: 2640 | F3: 78314 | G3: 26400 | H3: 51914 | I3: 已全额还款 | J3: 2640 | K3: 已全额还款 | L3: 0
A4: 1 | B4: 中国对外经济贸易信托有限公司 | C4: 107112762784-001 | D4: 107112762784 | E4: 1360 | F4: 24696 | G4: 13600 | H4: 11096 | I4: 已全额还款 | J4: 1360 | K4: 已全额还款 | L4: 0
A5: 1 | B5: 中国对外经济贸易信托有限公司 | C5: 101127524235-001 | D5: 101127524235 | E5: 2383.33 | F5: 50000 | G5: 19286.66 | H5: 30713.34 | I5: 已全额还款 | J5: 2383.33 | K5: 已全额还款 | L5: 0
A6: 1 | B6: 中国对外经济贸易信托有限公司 | C6: 101130107192-001 | D6: 101130107192 | E6: 3933 | F6: 74625 | G6: 39330 | H6: 35295 | I6: 已全额还款 | J6: 3933 | K6: 已全额还款 | L6: 0
A7: 1 | B7: 中国对外经济贸易信托有限公司 | C7: 101129694480-001 | D7: 101129694480 | E7: 2752 | F7: 81225 | G7: 30130 | H7: 51095 | I7: 已全额还款 | J7: 2752 | K7: 已全额还款 | L7: 0
A8: 1 | B8: 中国对外经济贸易信托有限公司 | C8: 101130228216-001 | D8: 101130228216 | E8: 2990 | F8: 90000 | G8: 29674 | H8: 60326 | I8: 已全额还款 | J8: 2990 | K8: 已全额还款 | L8: 0
A9: 1 | B9: 中国对外经济贸易信托有限公司 | C9: 101130717373-001 | D9: 101130717373 | E9: 2592 | F9: 78645 | G9: 25920 | H9: 52725 | I9: 已全额还款 | J9: 2592 | K9: 已全额还款 | L9: 0
A10: 1 | B10: 中国对外经济贸易信托有限公司 | C10: 107111983093-001 | D10: 107111983093 | E10: 4002 | F10: 119788 | G10: 36619.78 | H10: 83168.22 | I10: 已全额还款 | J10: 4002 | K10: 已全额还款 | L10: 0
A11: 1 | B11: 中国对外经济贸易信托有限公司 | C11: 101130115346-001 | D11: 101130115346 | E11: 4725 | F11: 88848 | G11: 44835 | H11: 44013 | I11: 已全额还款 | J11: 4725 | K11: 已全额还款 | L11: 0
A12: 1 | B12: 中国对外经济贸易信托有限公司 | C12: 107112670693-001 | D12: 107112670693 | E12: 3034 | F12: 91593 | G12: 25912 | H12: 65681 | I12: 已全额还款 | J12: 3034 | K12: 已全额还款 | L12: 0
A13: 1 | B13: 中国对外经济贸易信托有限公司 | C13: 107112908287-001 | D13: 107112908287 | E13: 2982 | F13: 86000 | G13: 25636 | H13: 60364 | I13: 已全额还款 | J13: 2982 | K13: 已全额还款 | L13: 0
... A88: 1 | B88: 中国对外经济贸易信托有限公司 | C88: 101129349328-001 | D88: 101129349328 | E88: 2400 | F88: 80000 | G88: 29700 | H88: 50300 | I88: 已全额还款 | J88: 2400 | K88: 已全额还款 | L88: 0

Sheet 0529-已还款
A1: 资产包编号 | B1: 当前还款方 | C1: 资产编号(房源) | D1: 托管房源编码 | E1: 当期计划还款金额 | F1: 初始受让装修金额 | G1: 累计已还款金额 | H1: 剩余应还款余额 | I1: 本期还款状态 | J1: 当期实际还款金额 | K1: 本期是否逾期 | L1: 当期逾期天数
A2: 1 | B2: 中国对外经济贸易信托有限公司 | C2: 101127311840-001 | D2: 101127311840 | E2: 1132.33 | F2: 49162 | G2: 9453.64 | H2: 39708.36 | I2: 已全额还款 | J2: 1132.33 | K2: 已全额还款 | L2: 0
A3: 1 | B3: 中国对外经济贸易信托有限公司 | C3: 107112610087-001 | D3: 107112610087 | E3: 1178 | F3: 20715 | G3: 10602 | H3: 10113 | I3: 已全额还款 | J3: 1178 | K3: 已全额还款 | L3: 0
A4: 1 | B4: 中国对外经济贸易信托有限公司 | C4: 107112497805-001 | D4: 107112497805 | E4: 4120 | F4: 137380 | G4: 37923 | H4: 99457 | I4: 已全额还款 | J4: 4120 | K4: 已全额还款 | L4: 0
A5: 1 | B5: 中国对外经济贸易信托有限公司 | C5: 107111390157-001 | D5: 107111390157 | E5: 1782 | F5: 52000 | G5: 23166 | H5: 28834 | I5: 已全额还款 | J5: 1782 | K5: 已全额还款 | L5: 0
A6: 1 | B6: 中国对外经济贸易信托有限公司 | C6: 101130796627-001 | D6: 101130796627 | E6: 1656 | F6: 121733 | G6: 47328 | H6: 74405 | I6: 已全额还款 | J6: 1656 | K6: 已全额还款 | L6: 0
A7: 1 | B7: 中国对外经济贸易信托有限公司 | C7: 107112784036-001 | D7: 107112784036 | E7: 5292 | F7: 161888 | G7: 40864 | H7: 121024 | I7: 已全额还款 | J7: 5292 | K7: 已全额还款 | L7: 0
A8: 1 | B8: 中国对外经济贸易信托有限公司 | C8: 107112806153-001 | D8: 107112806153 | E8: 1488 | F8: 26555 | G8: 13392 | H8: 13163 | I8: 已全额还款 | J8: 1488 | K8: 已全额还款 | L8: 0
A9: 1 | B9: 中国对外经济贸易信托有限公司 | C9: 107112379629-001 | D9: 107112379629 | E9: 2100 | F9: 79554 | G9: 25160 | H9: 54394 | I9: 已全额还款 | J9: 2100 | K9: 已全额还款 | L9: 0
A10: 1 | B10: 中国对外经济贸易信托有限公司 | C10: 107112476987-001 | D10: 107112476987 | E10: 1566 | F10: 29297 | G10: 16008 | H10: 13289 | I10: 已全额还款 | J10: 1566 | K10: 已全额还款 | L10: 0
A11: 1 | B11: 中国对外经济贸易信托有限公司 | C11: 101130607995-001 | D11: 101130607995 | E11: 3000 | F11: 120000 | G11: 37590 | H11: 82410 | I11: 已全额还款 | J11: 3000 | K11: 已全额还款 | L11: 0
A12: 1 | B12: 中国对外经济贸易信托有限公司 | C12: 107112926715-001 | D12: 107112926715 | E12: 3285 | F12: 95000 | G12: 28180 | H12: 66820 | I12: 已全额还款 | J12: 3285 | K12: 已全额还款 | L12: 0
A13: 1 | B13: 中国对外经济贸易信托有限公司 | C13: 101130228216-001 | D13: 101130228216 | E13: 191.39 | F13: 90000 | G13: 32664 | H13: 57336 | I13: 已全额还款 | J13: 191.39 | K13: 已全额还款 | L13: 0
... A112: 1 | B112: 中国对外经济贸易信托有限公司 | C112: 107112316953-001 | D112: 107112316953 | E112: 1734 | F112: 50000 | G112: 19074 | H112: 30926 | I112: 已全额还款 | J112: 1734 | K112: 已全额还款 | L112: 0
A113: 1 | B113: 中国对外经济贸易信托有限公司 | C113: 107112757529-001 | D113: 107114866922 | E113: 12000 | F113: 119100 | G113: 17496 | H113: 101604 | I113: 已全额还款 | J113: 12000 | K113: 已全额还款 | L113: 0 | M113: 解约重签房源

Sheet 0605已还款
A1: 资产包编号 | B1: 当前还款方 | C1: 资产编号(房源) | D1: 托管房源编码 | E1: 当期计划还款金额 | F1: 初始受让装修金额 | G1: 累计已还款金额 | H1: 剩余应还款余额 | I1: 本期还款状态 | J1: 当期实际还款金额 | K1: 本期是否逾期 | L1: 当期逾期天数
A2: 1 | B2: 中国对外经济贸易信托有限公司 | C2: 107112633046-001 | D2: 107112633046 | E2: 2475 | F2: 78888 | G2: 20925 | H2: 57963 | I2: 已全额还款 | J2: 2475 | K2: 已全额还款 | L2: 0
A3: 1 | B3: 中国对外经济贸易信托有限公司 | C3: 101129560839-001 | D3: 101129560839 | E3: 3000 | F3: 89318 | G3: 29750 | H3: 59568 | I3: 已全额还款 | J3: 3000 | K3: 已全额还款 | L3: 0
A4: 1 | B4: 中国对外经济贸易信托有限公司 | C4: 107112765285-001 | D4: 107112765285 | E4: 4005 | F4: 121500 | G4: 37845 | H4: 83655 | I4: 已全额还款 | J4: 4005 | K4: 已全额还款 | L4: 0
A5: 1 | B5: 中国对外经济贸易信托有限公司 | C5: 107112633794-001 | D5: 107112633794 | E5: 5880 | F5: 179000 | G5: 53918 | H5: 125082 | I5: 已全额还款 | J5: 5880 | K5: 已全额还款 | L5: 0
A6: 1 | B6: 中国对外经济贸易信托有限公司 | C6: 101128199843-001 | D6: 101128199843 | E6: 3200 | F6: 93677 | G6: 25600 | H6: 68077 | I6: 已全额还款 | J6: 3200 | K6: 已全额还款 | L6: 0
A7: 1 | B7: 中国对外经济贸易信托有限公司 | C7: 107112217965-001 | D7: 107112217965 | E7: 2200 | F7: 66000 | G7: 23600 | H7: 42400 | I7: 已全额还款 | J7: 2200 | K7: 已全额还款 | L7: 0
A8: 1 | B8: 中国对外经济贸易信托有限公司 | C8: 107112950619-001 | D8: 107112950619 | E8: 4980 | F8: 143403 | G8: 42340 | H8: 101063 | I8: 已全额还款 | J8: 4980 | K8: 已全额还款 | L8: 0
A9: 1 | B9: 中国对外经济贸易信托有限公司 | C9: 101129963777-001 | D9: 101129963777 | E9: 5635 | F9: 169978 | G9: 54931.67 | H9: 115046.33 | I9: 已全额还款 | J9: 5635 | K9: 已全额还款 | L9: 0
A10: 1 | B10: 中国对外经济贸易信托有限公司 | C10: 101129734313-001 | D10: 101129734313 | E10: 4352 | F10: 79477 | G10: 39446 | H10: 40031 | I10: 已全额还款 | J10: 4352 | K10: 已全额还款 | L10: 0
A11: 1 | B11: 中国对外经济贸易信托有限公司 | C11: 107112619000-001 | D11: 107112619000 | E11: 2000 | F11: 87000 | G11: 24300 | H11: 62700 | I11: 已全额还款 | J11: 2000 | K11: 已全额还款 | L11: 0
A12: 1 | B12: 中国对外经济贸易信托有限公司 | C12: 107112328931-001 | D12: 107112328931 | E12: 476 | F12: 8410 | G12: 5236 | H12: 3174 | I12: 已全额还款 | J12: 476 | K12: 已全额还款 | L12: 0
A13: 1 | B13: 中国对外经济贸易信托有限公司 | C13: 107113106536-001 | D13: 107113106536 | E13: 1520 | F13: 27939 | G13: 13680 | H13: 14259 | I13: 已全额还款 | J13: 1520 | K13: 已全额还款 | L13: 0
... A113: 1 | B113: 中国对外经济贸易信托有限公司 | C113: 107112828521-001 | D113: 107112828521 | E113: 3870 | F113: 115000 | G113: 32760 | H113: 82240 | I113: 已全额还款 | J113: 3870 | K113: 已全额还款 | L113: 0

Sheet 0612已还款
A1: 资产包编号 | B1: 当前还款方 | C1: 资产编号(房源) | D1: 托管房源编码 | E1: 当期计划还款金额 | F1: 初始受让装修金额 | G1: 累计已还款金额 | H1: 剩余应还款余额 | I1: 本期还款状态 | J1: 当期实际还款金额 | K1: 本期是否逾期 | L1: 当期逾期天数
A2: 1 | B2: 中国对外经济贸易信托有限公司 | C2: 107112529588-001 | D2: 107112529588 | E2: 1679 | F2: 30363 | G2: 18469 | H2: 11894 | I2: 已全额还款 | J2: 1679 | K2: 已全额还款 | L2: 0
A3: 1 | B3: 中国对外经济贸易信托有限公司 | C3: 107112798785-001 | D3: 107112798785 | E3: 2496 | F3: 75452 | G3: 24384 | H3: 51068 | I3: 已全额还款 | J3: 2496 | K3: 已全额还款 | L3: 0
A4: 1 | B4: 中国对外经济贸易信托有限公司 | C4: 107112901979-001 | D4: 107112901979 | E4: 2620 | F4: 149690 | G4: 38341 | H4: 111349 | I4: 已全额还款 | J4: 2620 | K4: 已全额还款 | L4: 0
A5: 1 | B5: 中国对外经济贸易信托有限公司 | C5: 101130107192-001 | D5: 101130107192 | E5: 3933 | F5: 74625 | G5: 43263 | H5: 31362 | I5: 已全额还款 | J5: 3933 | K5: 已全额还款 | L5: 0
A6: 1 | B6: 中国对外经济贸易信托有限公司 | C6: 107113004258-001 | D6: 107113004258 | E6: 4500 | F6: 106935 | G6: 42600 | H6: 64335 | I6: 已全额还款 | J6: 4500 | K6: 已全额还款 | L6: 0
