Workbook

Sheet 1全量还款明细汇总
A1: 所属文件名称 | B1: 所属Sheet名称 | C1: 资产包编号 | D1: 托管房源编号1 | E1: 当期计划还款金额 | F1: 当期实际还款金额 | G1: 托管房源编号 | H1: 还款日期 | I1: 当前信托计划（已发行）
A2: 美润1号_还款明细表_0529.xlsx | B2: 0325已还款 | C2: 单一-001 | D2: 107113471357 | E2: 3264 | F2: 3264 | G2: 107113471357 | H2: 46106 | I2: =VLOOKUP(G2,'3已发行数据0610（明道云数据）'!B:N,13,FALSE) -> 单一信托,信托3号
A3: 美润1号_还款明细表_0529.xlsx | B3: 0325已还款 | C3: 单一-001 | D3: 107113694737 | E3: 11343.88 | F3: 11343.88 | G3: 107113694737 | H3: 46106 | I3: =VLOOKUP(G3,'3已发行数据0610（明道云数据）'!B:N,13,FALSE) -> 单一信托,信托3号
A4: 美润1号_还款明细表_0529.xlsx | B4: 0325已还款 | C4: 单一-001 | D4: 107113385212 | E4: 10132.92 | F4: 10132.92 | G4: 107113385212 | H4: 46106 | I4: =VLOOKUP(G4,'3已发行数据0610（明道云数据）'!B:N,13,FALSE) -> 单一信托,信托3号
A5: 美润1号_还款明细表_0529.xlsx | B5: 0325已还款 | C5: 单一-001 | D5: 107114212209 | E5: 4920 | F5: 4920 | G5: 107114212209 | H5: 46106 | I5: =VLOOKUP(G5,'3已发行数据0610（明道云数据）'!B:N,13,FALSE) -> 单一信托,信托3号
A6: 美润1号_还款明细表_0529.xlsx | B6: 0325已还款 | C6: 单一-001 | D6: 107113045363 | E6: 4353.1 | F6: 4353.1 | G6: 107113045363 | H6: 46106 | I6: =VLOOKUP(G6,'3已发行数据0610（明道云数据）'!B:N,13,FALSE) -> 单一信托,信托3号
A7: 美润1号_还款明细表_0529.xlsx | B7: 0325已还款 | C7: 单一-001 | D7: 107114495649 | E7: 9136.9 | F7: 9136.9 | G7: 107114495649 | H7: 46106 | I7: =VLOOKUP(G7,'3已发行数据0610（明道云数据）'!B:N,13,FALSE) -> 单一信托,信托3号
A8: 美润1号_还款明细表_0529.xlsx | B8: 0325已还款 | C8: 单一-001 | D8: 107113193877 | E8: 6486 | F8: 6486 | G8: 107113193877 | H8: 46106 | I8: =VLOOKUP(G8,'3已发行数据0610（明道云数据）'!B:N,13,FALSE) -> 单一信托,信托3号
A9: 美润1号_还款明细表_0529.xlsx | B9: 0325已还款 | C9: 单一-001 | D9: 107112417471 | E9: 12384 | F9: 12384 | G9: 107112417471 | H9: 46106 | I9: =VLOOKUP(G9,'3已发行数据0610（明道云数据）'!B:N,13,FALSE) -> 单一信托,信托3号
A10: 美润1号_还款明细表_0529.xlsx | B10: 0325已还款 | C10: 单一-001 | D10: 107114226759 | E10: 12810 | F10: 12810 | G10: 107114226759 | H10: 46106 | I10: =VLOOKUP(G10,'3已发行数据0610（明道云数据）'!B:N,13,FALSE) -> 单一信托,信托3号
A11: 美润1号_还款明细表_0529.xlsx | B11: 0325已还款 | C11: 单一-001 | D11: 107113184658 | E11: 17466 | F11: 17466 | G11: 107113184658 | H11: 46106 | I11: =VLOOKUP(G11,'3已发行数据0610（明道云数据）'!B:N,13,FALSE) -> 单一信托,信托3号
A12: 美润1号_还款明细表_0529.xlsx | B12: 0325已还款 | C12: 单一-001 | D12: 101128210944 | E12: 56000 | F12: 56000 | G12: 101128210944 | H12: 46106 | I12: =VLOOKUP(G12,'3已发行数据0610（明道云数据）'!B:N,13,FALSE) -> 单一信托,信托3号
A13: 美润1号_还款明细表_0529.xlsx | B13: 0325已还款 | C13: 单一-001 | D13: 107114205966 | E13: 8404.71 | F13: 8404.71 | G13: 107114205966 | H13: 46106 | I13: =VLOOKUP(G13,'3已发行数据0610（明道云数据）'!B:N,13,FALSE) -> 单一信托,信托3号
... A215: 美润1号_还款明细表_0529.xlsx | B215: 0529已还款 | C215: 单一-001 | D215: 107112416762 | E215: 1600 | F215: 1600 | G215: 107112416762 | H215: 46171 | I215: =VLOOKUP(G215,'3已发行数据0610（明道云数据）'!B:N,13,FALSE) -> 单一信托
A216: 美好生活3号-还款明细披露信息_20260529_已更新0601.xlsx | B216: 0430已还款 | C216: 3 | D216: 101134445166 | E216: 6861.37 | F216: 6861.37 | G216: 101134445166 | H216: 46142 | I216: =VLOOKUP(G216,'3已发行数据0610（明道云数据）'!B:N,13,FALSE) -> 信托3号
A217: 美好生活3号-还款明细披露信息_20260529_已更新0601.xlsx | B217: 0430已还款 | C217: 3 | D217: 101133822347 | E217: 6650 | F217: 6650 | G217: 101133822347 | H217: 46142 | I217: =VLOOKUP(G217,'3已发行数据0610（明道云数据）'!B:N,13,FALSE) -> 信托3号
A218: 美好生活3号-还款明细披露信息_20260529_已更新0601.xlsx | B218: 0430已还款 | C218: 3 | D218: 107114291360 | E218: 5140 | F218: 5140 | G218: 107114291360 | H218: 46142 | I218: =VLOOKUP(G218,'3已发行数据0610（明道云数据）'!B:N,13,FALSE) -> 信托3号
A219: 美好生活3号-还款明细披露信息_20260529_已更新0601.xlsx | B219: 0430已还款 | C219: 3 | D219: 107114474902 | E219: 5329.87 | F219: 5329.87 | G219: 107114474902 | H219: 46142 | I219: =VLOOKUP(G219,'3已发行数据0610（明道云数据）'!B:N,13,FALSE) -> 信托3号
A220: 美好生活3号-还款明细披露信息_20260529_已更新0601.xlsx | B220: 0430已还款 | C220: 3 | D220: 107114615743 | E220: 4610 | F220: 4610 | G220: 107114615743 | H220: 46142 | I220: =VLOOKUP(G220,'3已发行数据0610（明道云数据）'!B:N,13,FALSE) -> 信托3号
A221: 美好生活3号-还款明细披露信息_20260529_已更新0601.xlsx | B221: 0430已还款 | C221: 3 | D221: 107114233912 | E221: 5743.6 | F221: 5743.6 | G221: 107114233912 | H221: 46142 | I221: =VLOOKUP(G221,'3已发行数据0610（明道云数据）'!B:N,13,FALSE) -> 信托3号
A222: 美好生活3号-还款明细披露信息_20260529_已更新0601.xlsx | B222: 0430已还款 | C222: 3 | D222: 107114591839 | E222: 4632.94 | F222: 4632.94 | G222: 107114591839 | H222: 46142 | I222: =VLOOKUP(G222,'3已发行数据0610（明道云数据）'!B:N,13,FALSE) -> 信托3号
A223: 美好生活3号-还款明细披露信息_20260529_已更新0601.xlsx | B223: 0430已还款 | C223: 3 | D223: 107114187138 | E223: 4662.6 | F223: 4662.6 | G223: 107114187138 | H223: 46142 | I223: =VLOOKUP(G223,'3已发行数据0610（明道云数据）'!B:N,13,FALSE) -> 信托3号
A224: 美好生活3号-还款明细披露信息_20260529_已更新0601.xlsx | B224: 0430已还款 | C224: 3 | D224: 107114218904 | E224: 5580 | F224: 5580 | G224: 107114218904 | H224: 46142 | I224: =VLOOKUP(G224,'3已发行数据0610（明道云数据）'!B:N,13,FALSE) -> 信托3号
A225: 美好生活3号-还款明细披露信息_20260529_已更新0601.xlsx | B225: 0430已还款 | C225: 3 | D225: 107114562119 | E225: 14734.74 | F225: 14734.74 | G225: 107114562119 | H225: 46142 | I225: =VLOOKUP(G225,'3已发行数据0610（明道云数据）'!B:N,13,FALSE) -> 信托3号
A226: 美好生活3号-还款明细披露信息_20260529_已更新0601.xlsx | B226: 0430已还款 | C226: 3 | D226: 107114119448 | E226: 4515 | F226: 4515 | G226: 107114119448 | H226: 46142 | I226: =VLOOKUP(G226,'3已发行数据0610（明道云数据）'!B:N,13,FALSE) -> 信托3号
A227: 美好生活3号-还款明细披露信息_20260529_已更新0601.xlsx | B227: 0430已还款 | C227: 3 | D227: 107114470189 | E227: 4010.14 | F227: 4010.14 | G227: 107114470189 | H227: 46142 | I227: =VLOOKUP(G227,'3已发行数据0610（明道云数据）'!B:N,13,FALSE) -> 信托3号
... A1198: 美好生活2号-还款明细披露信息_20260529_已更新0601.xlsx | B1198: 0119-已还款 | C1198: 2 | D1198: 107113281217 | E1198: 2002.5 | F1198: 2002.5 | G1198: 107113281217 | H1198: 46041 | I1198: =VLOOKUP(G1198,'3已发行数据0610（明道云数据）'!B:N,13,FALSE) -> 信托2号
A1199: 美好生活2号-还款明细披露信息_20260529_已更新0601.xlsx | B1199: 0119-已还款 | C1199: 2 | D1199: 107113281945 | F1199: 2040 | G1199: 107113281945 | H1199: 46041 | I1199: =VLOOKUP(G1199,'3已发行数据0610（明道云数据）'!B:N,13,FALSE) -> 信托2号
A1200: 美好生活2号-还款明细披露信息_20260529_已更新0601.xlsx | B1200: 0119-已还款 | C1200: 2 | D1200: 107113286656 | E1200: 1653 | F1200: 1653 | G1200: 107113286656 | H1200: 46041 | I1200: =VLOOKUP(G1200,'3已发行数据0610（明道云数据）'!B:N,13,FALSE) -> 信托2号
A1201: 美好生活2号-还款明细披露信息_20260529_已更新0601.xlsx | B1201: 0119-已还款 | C1201: 2 | D1201: 107113291829 | E1201: 1840 | F1201: 1840 | G1201: 107113291829 | H1201: 46041 | I1201: =VLOOKUP(G1201,'3已发行数据0610（明道云数据）'!B:N,13,FALSE) -> 信托2号
A1202: 美好生活2号-还款明细披露信息_20260529_已更新0601.xlsx | B1202: 0119-已还款 | C1202: 2 | D1202: 107113296230 | E1202: 2000 | F1202: 2000 | G1202: 107113296230 | H1202: 46041 | I1202: =VLOOKUP(G1202,'3已发行数据0610（明道云数据）'!B:N,13,FALSE) -> 信托2号
A1203: 美好生活2号-还款明细披露信息_20260529_已更新0601.xlsx | B1203: 0119-已还款 | C1203: 2 | D1203: 107113298512 | E1203: 3200 | F1203: 3200 | G1203: 107113298512 | H1203: 46041 | I1203: =VLOOKUP(G1203,'3已发行数据0610（明道云数据）'!B:N,13,FALSE) -> 信托2号
A1204: 美好生活2号-还款明细披露信息_20260529_已更新0601.xlsx | B1204: 0119-已还款 | C1204: 2 | D1204: 107113299896 | E1204: 3528 | F1204: 3528 | G1204: 107113299896 | H1204: 46041 | I1204: =VLOOKUP(G1204,'3已发行数据0610（明道云数据）'!B:N,13,FALSE) -> 信托2号
A1205: 美好生活2号-还款明细披露信息_20260529_已更新0601.xlsx | B1205: 0119-已还款 | C1205: 2 | D1205: 107113304382 | E1205: 2120 | F1205: 2120 | G1205: 107113304382 | H1205: 46041 | I1205: =VLOOKUP(G1205,'3已发行数据0610（明道云数据）'!B:N,13,FALSE) -> 信托2号
A1206: 美好生活2号-还款明细披露信息_20260529_已更新0601.xlsx | B1206: 0119-已还款 | C1206: 2 | D1206: 107113307246 | E1206: 2230 | F1206: 2230 | G1206: 107113307246 | H1206: 46041 | I1206: =VLOOKUP(G1206,'3已发行数据0610（明道云数据）'!B:N,13,FALSE) -> 信托2号
A1207: 美好生活2号-还款明细披露信息_20260529_已更新0601.xlsx | B1207: 0119-已还款 | C1207: 2 | D1207: 107113310327 | E1207: 2450 | F1207: 2450 | G1207: 107113310327 | H1207: 46041 | I1207: =VLOOKUP(G1207,'3已发行数据0610（明道云数据）'!B:N,13,FALSE) -> 信托2号
A1208: 美好生活2号-还款明细披露信息_20260529_已更新0601.xlsx | B1208: 0119-已还款 | C1208: 2 | D1208: 107113314832 | E1208: 2320 | F1208: 2320 | G1208: 107113314832 | H1208: 46041 | I1208: =VLOOKUP(G1208,'3已发行数据0610（明道云数据）'!B:N,13,FALSE) -> 信托2号
A1209: 美好生活2号-还款明细披露信息_20260529_已更新0601.xlsx | B1209: 0119-已还款 | C1209: 2 | D1209: 107113322686 | E1209: 2120 | F1209: 2120 | G1209: 107113322686 | H1209: 46041 | I1209: =VLOOKUP(G1209,'3已发行数据0610（明道云数据）'!B:N,13,FALSE) -> 信托2号
A1210: 美好生活2号-还款明细披露信息_20260529_已更新0601.xlsx | B1210: 0119-已还款 | C1210: 2 | D1210: 107113323285 | E1210: 1720 | F1210: 1720 | G1210: 107113323285 | H1210: 46041 | I1210: =VLOOKUP(G1210,'3已发行数据0610（明道云数据）'!B:N,13,FALSE) -> 信托2号
A1211: 美好生活2号-还款明细披露信息_20260529_已更新0601.xlsx | B1211: 0119-已还款 | C1211: 2 | D1211: 107113323865 | E1211: 2200 | F1211: 2200 | G1211: 107113323865 | H1211: 46041 | I1211: =VLOOKUP(G1211,'3已发行数据0610（明道云数据）'!B:N,13,FALSE) -> 信托2号
...

Sheet 2更新的资产数据表
A1: 文件名 | B1: 资产包编号 | C1: 托管房源编码 | D1: 统计日期 | E1: 初始受让金额 | F1: 已还款金额 | G1: 剩余还款金额 | H1: 资产状态 | I1: 最后一期装修款付款时间 | J1: 城市 | K1: 当前信托计划（已发行）
A2: 美好生活1号-资产监控表_0612 | B2: 1 | C2: 107112824234 | D2: 46185 | E2: 94000 | F2: 32800 | G2: 61200 | H2: 正常 | I2: 46794 | J2: 上海 | K2: =VLOOKUP(C2,'3已发行数据0610（明道云数据）'!B:N,13,FALSE) -> 信托1号
A3: 美好生活1号-资产监控表_0612 | B3: 1 | C3: 107111763962 | D3: 46185 | E3: 19454 | F3: 12155 | G3: 7299 | H3: 正常 | I3: 46367 | J3: 上海 | K3: =VLOOKUP(C3,'3已发行数据0610（明道云数据）'!B:N,13,FALSE) -> 信托1号
A4: 美好生活1号-资产监控表_0612 | B4: 1 | C4: 107112807713 | D4: 46185 | E4: 88800 | F4: 27753 | G4: 61047 | H4: 正常 | I4: 46794 | J4: 上海 | K4: =VLOOKUP(C4,'3已发行数据0610（明道云数据）'!B:N,13,FALSE) -> 信托1号
A5: 美好生活1号-资产监控表_0612 | B5: 1 | C5: 107112466550 | D5: 46185 | E5: 118000 | F5: 44370 | G5: 73630 | H5: 正常 | I5: 46794 | J5: 上海 | K5: =VLOOKUP(C5,'3已发行数据0610（明道云数据）'!B:N,13,FALSE) -> 信托1号
A6: 美好生活1号-资产监控表_0612 | B6: 1 | C6: 101129877193 | D6: 46185 | E6: 100000 | F6: 58703.33 | G6: 41296.67 | H6: 正常 | I6: 46429 | J6: 北京 | K6: =VLOOKUP(C6,'3已发行数据0610（明道云数据）'!B:N,13,FALSE) -> 信托1号
A7: 美好生活1号-资产监控表_0612 | B7: 1 | C7: 101131064033 | D7: 46185 | E7: 82153 | F7: 29700 | G7: 52453 | H7: 正常 | I7: 46732 | J7: 北京 | K7: =VLOOKUP(C7,'3已发行数据0610（明道云数据）'!B:N,13,FALSE) -> 信托1号
A8: 美好生活1号-资产监控表_0612 | B8: 1 | C8: 107113051629 | D8: 46185 | E8: 100146 | F8: 33188 | G8: 66958 | H8: 正常 | I8: 46794 | J8: 上海 | K8: =VLOOKUP(C8,'3已发行数据0610（明道云数据）'!B:N,13,FALSE) -> 信托1号
A9: 美好生活1号-资产监控表_0612 | B9: 1 | C9: 107112808068 | D9: 46185 | E9: 92468 | F9: 29370 | G9: 63098 | H9: 正常 | I9: 46854 | J9: 上海 | K9: =VLOOKUP(C9,'3已发行数据0610（明道云数据）'!B:N,13,FALSE) -> 信托1号
A10: 美好生活1号-资产监控表_0612 | B10: 1 | C10: 101128689163 | D10: 46185 | E10: 160000 | F10: 58000 | G10: 102000 | H10: 正常 | I10: 46732 | J10: 北京 | K10: =VLOOKUP(C10,'3已发行数据0610（明道云数据）'!B:N,13,FALSE) -> 信托1号
A11: 美好生活1号-资产监控表_0612 | B11: 1 | C11: 107112571761 | D11: 46185 | E11: 110000 | F11: 37490 | G11: 72510 | H11: 正常 | I11: 46763 | J11: 上海 | K11: =VLOOKUP(C11,'3已发行数据0610（明道云数据）'!B:N,13,FALSE) -> 信托1号
A12: 美好生活1号-资产监控表_0612 | B12: 1 | C12: 107113057210 | D12: 46185 | E12: 70000 | F12: 20375 | G12: 49625 | H12: 正常 | I12: 46823 | J12: 上海 | K12: =VLOOKUP(C12,'3已发行数据0610（明道云数据）'!B:N,13,FALSE) -> 信托1号
A13: 美好生活1号-资产监控表_0612 | B13: 1 | C13: 107112464864 | D13: 46185 | E13: 89000 | F13: 22650 | G13: 66350 | H13: 正常 | I13: 46854 | J13: 上海 | K13: =VLOOKUP(C13,'3已发行数据0610（明道云数据）'!B:N,13,FALSE) -> 信托1号
... A1130: 美好生活3号-资产监控表_0612 | B1130: 3 | C1130: 107112417471 | D1130: 46185 | E1130: 7267 | F1130: 2304 | G1130: 4963 | H1130: 正常 | I1130: 46272 | J1130: 上海 | K1130: =VLOOKUP(C1130,'3已发行数据0610（明道云数据）'!B:N,13,FALSE) -> 单一信托,信托3号
A1131: 美润1号资产监控表_0612 | B1131: 单一001 | C1131: 107112271059 | D1131: 46185 | E1131: 99000 | F1131: 24570 | G1131: 74430 | H1131: 正常 | I1131: 47294 | J1131: 上海 | K1131: =VLOOKUP(C1131,'3已发行数据0610（明道云数据）'!B:N,13,FALSE) -> 单一信托
A1132: 美润1号资产监控表_0612 | B1132: 单一001 | C1132: 107112256785 | D1132: 46186 | E1132: 96716 | F1132: 27699 | G1132: 69017 | H1132: 正常 | I1132: 47213 | J1132: 上海 | K1132: =VLOOKUP(C1132,'3已发行数据0610（明道云数据）'!B:N,13,FALSE) -> 单一信托
A1133: 美润1号资产监控表_0612 | B1133: 单一001 | C1133: 107112225568 | D1133: 46187 | E1133: 88000 | F1133: 22827 | G1133: 65173 | H1133: 正常 | I1133: 47197 | J1133: 上海 | K1133: =VLOOKUP(C1133,'3已发行数据0610（明道云数据）'!B:N,13,FALSE) -> 单一信托
A1134: 美润1号资产监控表_0612 | B1134: 单一001 | C1134: 107113089723 | D1134: 46188 | E1134: 107797 | F1134: 20850 | G1134: 86947 | H1134: 正常 | I1134: 47148 | J1134: 上海 | K1134: =VLOOKUP(C1134,'3已发行数据0610（明道云数据）'!B:N,13,FALSE) -> 单一信托
A1135: 美润1号资产监控表_0612 | B1135: 单一001 | C1135: 107112317928 | D1135: 46189 | E1135: 83000 | F1135: 20844 | G1135: 62156 | H1135: 正常 | I1135: 47255 | J1135: 上海 | K1135: =VLOOKUP(C1135,'3已发行数据0610（明道云数据）'!B:N,13,FALSE) -> 单一信托
A1136: 美润1号资产监控表_0612 | B1136: 单一001 | C1136: 107112727179 | D1136: 46190 | E1136: 82000 | F1136: 18876 | G1136: 63124 | H1136: 正常 | I1136: 47411 | J1136: 上海 | K1136: =VLOOKUP(C1136,'3已发行数据0610（明道云数据）'!B:N,13,FALSE) -> 单一信托
A1137: 美润1号资产监控表_0612 | B1137: 单一001 | C1137: 107112384180 | D1137: 46191 | E1137: 159424 | F1137: 40262 | G1137: 119162 | H1137: 正常 | I1137: 47283 | J1137: 上海 | K1137: =VLOOKUP(C1137,'3已发行数据0610（明道云数据）'!B:N,13,FALSE) -> 单一信托
A1138: 美润1号资产监控表_0612 | B1138: 单一001 | C1138: 107112483866 | D1138: 46192 | E1138: 80000 | F1138: 19980 | G1138: 60020 | H1138: 正常 | I1138: 47447 | J1138: 上海 | K1138: =VLOOKUP(C1138,'3已发行数据0610（明道云数据）'!B:N,13,FALSE) -> 单一信托
A1139: 美润1号资产监控表_0612 | B1139: 单一001 | C1139: 107112390518 | D1139: 46193 | E1139: 130000 | F1139: 28919 | G1139: 101081 | H1139: 正常 | I1139: 47289 | J1139: 上海 | K1139: =VLOOKUP(C1139,'3已发行数据0610（明道云数据）'!B:N,13,FALSE) -> 单一信托
A1140: 美润1号资产监控表_0612 | B1140: 单一001 | C1140: 107112311362 | D1140: 46194 | E1140: 68500 | F1140: 16416 | G1140: 52084 | H1140: 正常 | I1140: 47389 | J1140: 上海 | K1140: =VLOOKUP(C1140,'3已发行数据0610（明道云数据）'!B:N,13,FALSE) -> 单一信托
A1141: 美润1号资产监控表_0612 | B1141: 单一001 | C1141: 107112488326 | D1141: 46195 | E1141: 97000 | F1141: 24096 | G1141: 72904 | H1141: 正常 | I1141: 47316 | J1141: 上海 | K1141: =VLOOKUP(C1141,'3已发行数据0610（明道云数据）'!B:N,13,FALSE) -> 单一信托
A1142: 美润1号资产监控表_0612 | B1142: 单一001 | C1142: 107112218005 | D1142: 46196 | E1142: 121680 | F1142: 24440 | G1142: 97240 | H1142: 正常 | I1142: 47401 | J1142: 上海 | K1142: =VLOOKUP(C1142,'3已发行数据0610（明道云数据）'!B:N,13,FALSE) -> 单一信托
... A1257: 美润1号资产监控表_0612 | B1257: 单一001 | C1257: 107113468759 | D1257: 46311 | E1257: 385000 | F1257: 29160 | G1257: 355840 | H1257: 正常 | I1257: 47305 | J1257: 上海 | K1257: =VLOOKUP(C1257,'3已发行数据0610（明道云数据）'!B:N,13,FALSE) -> 单一信托（2号）

Sheet 3已发行数据0610（明道云数据）
A1: 预计代扣周期-最初 | B1: 房源编码 | C1: 房源地址 | D1: 所属城市 | E1: 品牌 | F1: 签约日期 | G1: 实际成交价（应收账款合同金额） | H1: 代扣金额 | I1: 装修付款形式 | J1: 业主付款金额 | K1: 施工方名称 | L1: 入池批次 | M1: 信托计划期数 | N1: 当前信托计划（已发行） | O1: 检查核对发行情况
A2: 8 | B2: 107112524298 | C2: 上海市青浦区灿耀星城徐安路28弄21号-1302 | D2: 上海 | E2: 山念 | F2: 45795 | G2: 24963 | H2: 24963 | I2: 租金代扣 | J2: 0 | K2: 天津冠唯装饰工程有限公司 | L2: 412批次 | M2: 412批次 | N2: 信托1号 | O2: =VLOOKUP(B2,'4已发行数据（原始入池数据表格）'!C:C,1,FALSE) -> 107112524298
A3: 9 | B3: 107112765383 | C3: 上海市青浦区徐泾镇沪青平公路1758弄逸品名邸（中铁 虹桥逸都）48号302 | D3: 上海 | E3: 山念 | F3: 45792 | G3: 23283 | H3: 23283 | I3: 租金代扣 | J3: 0 | K3: 天津冠唯装饰工程有限公司 | L3: 412批次 | M3: 412批次 | N3: 信托1号 | O3: =VLOOKUP(B3,'4已发行数据（原始入池数据表格）'!C:C,1,FALSE) -> 107112765383
A4: 7 | B4: 107112708646 | C4: 徐泾镇沪青平公路1758弄48号1001室 | D4: 上海 | E4: 山念 | F4: 45792 | G4: 22732 | H4: 22732 | I4: 租金代扣 | J4: 0 | K4: 天津冠唯装饰工程有限公司 | L4: 412批次 | M4: 412批次 | N4: 信托1号 | O4: =VLOOKUP(B4,'4已发行数据（原始入池数据表格）'!C:C,1,FALSE) -> 107112708646
A5: 10 | B5: 107112795213 | C5: 上海市黄浦区瑞宁路8弄御江廷3号2505 | D5: 上海 | E5: 山念 | F5: 45787 | G5: 25732 | H5: 25732 | I5: 租金代扣 | J5: 0 | K5: 住与家（上海）装饰设计有限公司 | L5: 第二批 | M5: 第二批 | N5: 信托2号 | O5: =VLOOKUP(B5,'4已发行数据（原始入池数据表格）'!C:C,1,FALSE) -> 107112795213
A6: 7 | B6: 107112775650 | C6: 松江区九亭镇伴亭路855弄14号601 | D6: 上海 | E6: 山念 | F6: 45781 | G6: 30538 | H6: 30583 | I6: 租金代扣 | J6: 0 | K6: 天津冠唯装饰工程有限公司 | L6: 412批次 | M6: 412批次 | N6: 信托1号 | O6: =VLOOKUP(B6,'4已发行数据（原始入池数据表格）'!C:C,1,FALSE) -> 107112775650
A7: 20 | B7: 107112675513 | C7: 上海市静安区泰兴路362弄25号103 | D7: 上海 | E7: 山念 | F7: 45770 | G7: 68787 | H7: 68787 | I7: 租金代扣 | J7: 0 | K7: 上海沪慧荣建筑装饰有限公司 | L7: 412批次 | M7: 412批次 | N7: 信托1号 | O7: =VLOOKUP(B7,'4已发行数据（原始入池数据表格）'!C:C,1,FALSE) -> 107112675513
A8: 20 | B8: 101129590806 | C8: 北京市东城区安定门外大街10-1303 | D8: 北京 | E8: 焕新租 | F8: 45769 | G8: 94515.6 | H8: 94515 | I8: 租金代扣 | J8: 0 | K8: 北京致一建设有限公司 | L8: 412批次 | M8: 412批次 | N8: 信托1号 | O8: =VLOOKUP(B8,'4已发行数据（原始入池数据表格）'!C:C,1,FALSE) -> 101129590806
A9: 6 | B9: 107112663876 | C9: 上海市浦东新区中企云萃森林(东区)钟晓路257弄27号2004室 | D9: 上海 | E9: 怡穗 | F9: 45768 | G9: 19087 | H9: 19087 | I9: 租金代扣 | J9: 0 | K9: 上海庆苑建筑装饰集团有限公司 | L9: 412批次 | M9: 412批次 | N9: 信托1号 | O9: =VLOOKUP(B9,'4已发行数据（原始入池数据表格）'!C:C,1,FALSE) -> 107112663876
A10: 20 | B10: 107112654601 | C10: 上海市宝山区宝林八村97号502 | D10: 上海 | E10: 山念 | F10: 45768 | G10: 136196 | H10: 107595 | I10: 业主付款+租金代扣 | J10: 28601 | K10: 上海千盛邦建筑装饰有限公司 | L10: 412批次 | M10: 412批次 | N10: 信托1号 | O10: =VLOOKUP(B10,'4已发行数据（原始入池数据表格）'!C:C,1,FALSE) -> 107112654601
A11: 9 | B11: 101129927216 | C11: 北京市朝阳区裕民路4号院1号楼3单元8号 | D11: 北京 | E11: 焕新租 | F11: 45768 | G11: 86485 | H11: 86485 | I11: 租金代扣 | J11: 0 | K11: 北京致一建设有限公司 | L11: 412批次 | M11: 412批次 | N11: 信托1号 | O11: =VLOOKUP(B11,'4已发行数据（原始入池数据表格）'!C:C,1,FALSE) -> 101129927216
A12: 20 | B12: 107112556607 | C12: 上海市长宁区新泾镇仙霞路1225弄113号302 | D12: 上海 | E12: 山念 | F12: 45768 | G12: 119603 | H12: 119603 | I12: 租金代扣 | J12: 0 | K12: 天津冠唯装饰工程有限公司 | L12: 412批次 | M12: 412批次 | N12: 信托1号 | O12: =VLOOKUP(B12,'4已发行数据（原始入池数据表格）'!C:C,1,FALSE) -> 107112556607
A13: 6 | B13: 107112705537 | C13: 徐泾镇沪青平公路1758弄52号楼1101室 | D13: 上海 | E13: 山念 | F13: 45767 | G13: 24606 | H13: 24606 | I13: 租金代扣 | J13: 0 | K13: 天津冠唯装饰工程有限公司 | L13: 412批次 | M13: 412批次 | N13: 信托1号 | O13: =VLOOKUP(B13,'4已发行数据（原始入池数据表格）'!C:C,1,FALSE) -> 107112705537
A14: 26 | B14: 107112660445 | C14: 上海市普陀区宜川五村47号104室 | D14: 上海 | E14: 山念 | F14: 45767 | G14: 97000 | H14: 95414 | I14: 租金代扣 | K14: 上海千盛邦建筑装饰有限公司 | L14: 412批次 | M14: 412批次 | N14: 信托1号 | O14: =VLOOKUP(B14,'4已发行数据（原始入池数据表格）'!C:C,1,FALSE) -> 107112660445
A15: 8 | B15: 107112610123 | C15: 徐泾镇泾南河路79弄璀璨名邸49号16层1602室 | D15: 上海 | E15: 山念 | F15: 45767 | G15: 25490 | H15: 25490 | I15: 租金代扣 | J15: 0 | K15: 天津冠唯装饰工程有限公司 | L15: 412批次 | M15: 412批次 | N15: 信托1号 | O15: =VLOOKUP(B15,'4已发行数据（原始入池数据表格）'!C:C,1,FALSE) -> 107112610123
A16: 6 | B16: 107112587444 | C16: 徐泾镇蟠和路188弄蟠龙云邸25号5层502 | D16: 上海 | E16: 山念 | F16: 45766 | G16: 27578 | H16: 27578 | I16: 租金代扣 | J16: 0 | K16: 天津冠唯装饰工程有限公司 | L16: 412批次 | M16: 412批次 | N16: 信托1号 | O16: =VLOOKUP(B16,'4已发行数据（原始入池数据表格）'!C:C,1,FALSE) -> 107112587444
A17: 7 | B17: 107112575884 | C17: 徐泾镇沪青平公路1758弄逸品名邸26号1层101室 | D17: 上海 | E17: 山念 | F17: 45766 | G17: 23001 | H17: 23001 | I17: 租金代扣 | J17: 0 | K17: 天津冠唯装饰工程有限公司 | L17: 412批次 | M17: 412批次 | N17: 信托1号 | O17: =VLOOKUP(B17,'4已发行数据（原始入池数据表格）'!C:C,1,FALSE) -> 107112575884
A18: 9 | B18: 107112629770 | C18: 上海市闵行区通海路268弄23号701 | D18: 上海 | E18: 山念 | F18: 45766 | G18: 25912 | H18: 25912 | I18: 租金代扣 | J18: 0 | K18: 南京和艺优装饰工程有限公司 | L18: 412批次 | M18: 412批次 | N18: 信托1号 | O18: =VLOOKUP(B18,'4已发行数据（原始入池数据表格）'!C:C,1,FALSE) -> 107112629770
A19: 19 | B19: 107112640254 | C19: 上海宝山中怡家园09号楼09单元2301 | D19: 上海 | E19: 山念 | F19: 45765 | G19: 37493 | H19: 37493 | I19: 租金代扣 | J19: 0 | K19: 上海长聚建筑工程有限公司 | L19: 412批次 | M19: 412批次 | N19: 信托1号 | O19: =VLOOKUP(B19,'4已发行数据（原始入池数据表格）'!C:C,1,FALSE) -> 107112640254
A20: 20 | B20: 107112509729 | C20: 宝山区松南镇一二八纪念路55弄100号401 | D20: 上海 | E20: 山念 | F20: 45764 | G20: 132000 | H20: 132000 | I20: 租金代扣 | J20: 0 | K20: 上海速信佳装饰工程有限公司 | L20: 412批次 | M20: 412批次 | N20: 信托1号 | O20: =VLOOKUP(B20,'4已发行数据（原始入池数据表格）'!C:C,1,FALSE) -> 107112509729
A21: 19 | B21: 107112499423 | C21: 上海市宝山共江小区136号602 | D21: 上海 | E21: 山念 | F21: 45764 | G21: 77000 | H21: 77000 | I21: 租金代扣 | J21: 0 | K21: 上海速信佳装饰工程有限公司 | L21: 412批次 | M21: 412批次 | N21: 信托1号 | O21: =VLOOKUP(B21,'4已发行数据（原始入池数据表格）'!C:C,1,FALSE) -> 107112499423
A22: 20 | B22: 107112602426 | C22: 上海市浦东新区临沂路181弄1号504室 | D22: 上海 | E22: 山念 | F22: 45763 | G22: 101368.6 | H22: 101368 | I22: 租金代扣 | J22: 0 | K22: 上海庆苑建筑装饰集团有限公司 | L22: 412批次 | M22: 412批次 | N22: 信托1号 | O22: =VLOOKUP(B22,'4已发行数据（原始入池数据表格）'!C:C,1,FALSE) -> 107112602426
A23: 8 | B23: 107112617499 | C23: 上海市闵行区通海路268弄2号楼101室 | D23: 上海 | E23: 山念 | F23: 45762 | G23: 25912 | H23: 25912 | I23: 租金代扣 | K23: 南京和艺优装饰工程有限公司 | L23: 412批次 | M23: 412批次 | N23: 信托1号 | O23: =VLOOKUP(B23,'4已发行数据（原始入池数据表格）'!C:C,1,FALSE) -> 107112617499
A24: 8 | B24: 107112652640 | C24: 徐泾镇沪青平公路1758弄逸品名邸12号7层702室 | D24: 上海 | E24: 山念 | F24: 45762 | G24: 27758 | H24: 27758 | I24: 租金代扣 | J24: 0 | K24: 天津冠唯装饰工程有限公司 | L24: 412批次 | M24: 412批次 | N24: 信托1号 | O24: =VLOOKUP(B24,'4已发行数据（原始入池数据表格）'!C:C,1,FALSE) -> 107112652640
A25: 22 | B25: 107112596941 | C25: 上海市徐汇区大木小区237弄8号501室 | D25: 上海 | E25: 山念 | F25: 45761 | G25: 106330 | H25: 106330 | I25: 租金代扣 | J25: 0 | K25: 上海沪慧荣建筑装饰有限公司 | L25: 第二批 | M25: 第二批 | N25: 信托2号 | O25: =VLOOKUP(B25,'4已发行数据（原始入池数据表格）'!C:C,1,FALSE) -> 107112596941
A26: 19 | B26: 107112608464 | C26: 上海市中山南一路1109弄康衢小区1号307室 | D26: 上海 | E26: 山念 | F26: 45761 | G26: 78025 | H26: 78025 | I26: 租金代扣 | J26: 0 | K26: 上海沪慧荣建筑装饰有限公司 | L26: 412批次 | M26: 412批次 | N26: 信托1号 | O26: =VLOOKUP(B26,'4已发行数据（原始入池数据表格）'!C:C,1,FALSE) -> 107112608464
A27: 19 | B27: 101129954626 | C27: 北京市朝阳区东大桥路57号楼3门10 | D27: 北京 | E27: 焕新租 | F27: 45761 | G27: 83860 | H27: 83860 | I27: 租金代扣 | J27: 0 | K27: 北京贝乐禾装饰有限公司 | L27: 412批次 | M27: 412批次 | N27: 信托1号 | O27: =VLOOKUP(B27,'4已发行数据（原始入池数据表格）'!C:C,1,FALSE) -> 101129954626
A28: 20 | B28: 107112587852 | C28: 上海市长宁区仙霞新村街道茅台路 500 弄茅台花苑小区 6-1109 | D28: 上海 | E28: 山念 | F28: 45761 | G28: 135731 | H28: 135731 | I28: 租金代扣 | J28: 0 | K28: 天津冠唯装饰工程有限公司 | L28: 412批次 | M28: 412批次 | N28: 信托1号 | O28: =VLOOKUP(B28,'4已发行数据（原始入池数据表格）'!C:C,1,FALSE) -> 107112587852
A29: 27 | B29: 107112535561 | C29: 上海静安区长乐路1232弄610 | D29: 上海 | E29: 山念 | F29: 45760 | G29: 101346 | H29: 101346 | I29: 租金代扣 | J29: 0 | K29: 上海沪慧荣建筑装饰有限公司 | L29: 412批次 | M29: 412批次 | N29: 信托1号 | O29: =VLOOKUP(B29,'4已发行数据（原始入池数据表格）'!C:C,1,FALSE) -> 107112535561
A30: 8 | B30: 101129460405 | C30: 北京市海淀区中关村南大街12号院四区12号楼2单元405 | D30: 北京 | E30: 焕新租 | F30: 45760 | G30: 73000 | H30: 73000 | I30: 租金代扣 | K30: 上海虬诗建设有限公司 | L30: 412批次 | M30: 412批次 | N30: 信托1号 | O30: =VLOOKUP(B30,'4已发行数据（原始入池数据表格）'!C:C,1,FALSE) -> 101129460405
A31: 6 | B31: 107112568721 | C31: 上海市乐中路 66 弄 10 号 701 | D31: 上海 | E31: 怡穗 | F31: 45759 | G31: 44480 | H31: 44480 | I31: 租金代扣 | K31: 南京和艺优装饰工程有限公司 | L31: 412批次 | M31: 412批次 | N31: 信托1号 | O31: =VLOOKUP(B31,'4已发行数据（原始入池数据表格）'!C:C,1,FALSE) -> 107112568721
A32: 22 | B32: 107112589042 | C32: 上海宝山古北菊翔苑菊联路232弄21单元0403 | D32: 上海 | E32: 山念 | F32: 45759 | G32: 130000 | H32: 130000 | I32: 租金代扣 | J32: 0 | K32: 上海长聚建筑工程有限公司 | L32: 第二批 | M32: 第二批 | N32: 信托2号 | O32: =VLOOKUP(B32,'4已发行数据（原始入池数据表格）'!C:C,1,FALSE) -> 107112589042
A33: 8 | B33: 107112552822 | C33: 上海市松江区广富林路658弄215号402室 | D33: 上海 | E33: 山念 | F33: 45758 | G33: 8910 | H33: 8910 | I33: 租金代扣 | J33: 0 | K33: 上海沪慧荣建筑装饰有限公司 | L33: 412批次 | M33: 412批次 | N33: 信托1号 | O33: =VLOOKUP(B33,'4已发行数据（原始入池数据表格）'!C:C,1,FALSE) -> 107112552822
A34: 7 | B34: 107112504607 | C34: 上海市青浦区赵巷镇佳杰路金地虹桥峯汇23-1101 | D34: 上海 | E34: 山念 | F34: 45758 | G34: 28225 | H34: 28225 | I34: 租金代扣 | J34: 0 | K34: 天津冠唯装饰工程有限公司 | L34: 412批次 | M34: 412批次 | N34: 信托1号 | O34: =VLOOKUP(B34,'4已发行数据（原始入池数据表格）'!C:C,1,FALSE) -> 107112504607
A35: 20 | B35: 107112562410 | C35: 上海市长宁区虹桥街道虹梅路 3888 弄延北小区 23 号 402 | D35: 上海 | E35: 山念 | F35: 45758 | G35: 78200 | H35: 78200 | I35: 租金代扣 | J35: 0 | K35: 天津冠唯装饰工程有限公司 | L35: 412批次 | M35: 412批次 | N35: 信托1号 | O35: =VLOOKUP(B35,'4已发行数据（原始入池数据表格）'!C:C,1,FALSE) -> 107112562410
A36: 7 | B36: 107112576388 | C36: 徐泾镇沪青平公路1758弄虹桥逸都26号1层102室 | D36: 上海 | E36: 山念 | F36: 45758 | G36: 31400 | H36: 31400 | I36: 租金代扣 | J36: 0 | K36: 天津冠唯装饰工程有限公司 | L36: 412批次 | M36: 412批次 | N36: 信托1号 | O36: =VLOOKUP(B36,'4已发行数据（原始入池数据表格）'!C:C,1,FALSE) -> 107112576388
A37: 9 | B37: 101129734313 | C37: 北京市朝阳区麦子店街7号楼5单元401室 | D37: 北京 | E37: 焕新租 | F37: 45758 | G37: 79477 | H37: 79477 | I37: 租金代扣 | J37: 0 | K37: 北京致一建设有限公司 | L37: 412批次 | M37: 412批次 | N37: 信托1号 | O37: =VLOOKUP(B37,'4已发行数据（原始入池数据表格）'!C:C,1,FALSE) -> 101129734313
A38: 20 | B38: 107112538502 | C38: 上海市浦东新区崂山六村浦东大道290弄21号203室 | D38: 上海 | E38: 山念 | F38: 45757 | G38: 99900 | H38: 99900 | I38: 租金代扣 | K38: 上海庆苑建筑装饰集团有限公司 | L38: 412批次 | M38: 412批次 | N38: 信托1号 | O38: =VLOOKUP(B38,'4已发行数据（原始入池数据表格）'!C:C,1,FALSE) -> 107112538502
A39: 20 | B39: 107112557175 | C39: 上海杨浦双阳路 490 弄 03 号楼 03 单元 0504 | D39: 上海 | E39: 山念 | F39: 45757 | G39: 90192 | H39: 90192 | I39: 租金代扣 | K39: 上海美速家建筑装饰有限公司 | L39: 412批次 | M39: 412批次 | N39: 信托1号 | O39: =VLOOKUP(B39,'4已发行数据（原始入池数据表格）'!C:C,1,FALSE) -> 107112557175
A40: -11 | B40: 107112551587 | C40: 上海市普陀区宜川路宜川二村小区124号415室 | D40: 上海 | E40: 山念 | F40: 45756 | G40: 78000 | H40: 78000 | I40: 租金代扣 | J40: 0 | K40: 上海千盛邦建筑装饰有限公司 | L40: 单一信托 | M40: 单一信托 | N40: 单一信托 | O40: =VLOOKUP(B40,'4已发行数据（原始入池数据表格）'!C:C,1,FALSE) -> 107112551587
...

Sheet 4已发行数据（原始入池数据表格）
A1: 文件名 | B1: sheet名称 | C1: 房源编号 | D1: 应收账款合同金额 | E1: 资产转让折扣率 | F1: 应收账款转让价款 | G1: 预计应收账款到期日 | H1: 每期应付金额 | I1: 出房价格 | J1: 当前信托计划 | K1: 代扣金额 | L1: 已代扣未付款 | M1: 贝壳已租金代扣金额合计 | N1: 已代扣已回款 | O1: 首次付款日期
A2: 美润1号服务信托房源明细（首期转让）.xlsx | B2: 合同 | C2: 107112551587 | D2: 78000 | E2: 0.83 | F2: 64740 | G2: 2029-04-16
A3: 美润1号服务信托房源明细（首期转让）.xlsx | B3: 合同 | C3: 107112468531 | D3: 120151 | E3: 0.83 | F3: 99725.33 | G3: 2030-11-22
A4: 美润1号服务信托房源明细（首期转让）.xlsx | B4: 合同 | C4: 107112488326 | D4: 97000 | E4: 0.83 | F4: 80510 | G4: 2029-07-17
A5: 美润1号服务信托房源明细（首期转让）.xlsx | B5: 合同 | C5: 107112518699 | D5: 120000 | E5: 0.83 | F5: 99600 | G5: 2029-09-07
A6: 美润1号服务信托房源明细（首期转让）.xlsx | B6: 合同 | C6: 107112483866 | D6: 80000 | E6: 0.83 | F6: 66400 | G6: 2029-11-25
A7: 美润1号服务信托房源明细（首期转让）.xlsx | B7: 合同 | C7: 107112428344 | D7: 92000 | E7: 0.83 | F7: 76360 | G7: 2029-10-25
A8: 美润1号服务信托房源明细（首期转让）.xlsx | B8: 合同 | C8: 107112362852 | D8: 111526 | E8: 0.83 | F8: 92566.58 | G8: 2029-06-10
A9: 美润1号服务信托房源明细（首期转让）.xlsx | B9: 合同 | C9: 107112271059 | D9: 99000 | E9: 0.83 | F9: 82170 | G9: 2029-06-25
A10: 美润1号服务信托房源明细（首期转让）.xlsx | B10: 合同 | C10: 107112452710 | D10: 104141 | E10: 0.83 | F10: 86437.03 | G10: 2029-07-20
A11: 美润1号服务信托房源明细（首期转让）.xlsx | B11: 合同 | C11: 107112453175 | D11: 147377 | E11: 0.83 | F11: 122322.91 | G11: 2029-11-05
A12: 美润1号服务信托房源明细（首期转让）.xlsx | B12: 合同 | C12: 107112439381 | D12: 145000 | E12: 0.83 | F12: 120350 | G12: 2029-04-25
A13: 美润1号服务信托房源明细（首期转让）.xlsx | B13: 合同 | C13: 107112424527 | D13: 93500 | E13: 0.83 | F13: 77605 | G13: 2029-07-10
... A111: 美润1号服务信托房源明细（首期转让）.xlsx | B111: 合同 | C111: 101130770124 | D111: 25000 | E111: 0.95 | F111: 23750 | G111: 2026-06-27
A112: 附件1：美好生活3号-基础资产清单.xlsx | B112: 房源维度结算底表 | C112: 107113470959 | D112: 90139 | E112: 0.88 | F112: 71386.48 | G112: 2028-11-15 | H112: 2496 | I112: 5200 | J112: 单一信托 | K112: 90139 | M112: 9018 | N112: 9018 | O112: 2025-11-15
A113: 附件1：美好生活3号-基础资产清单.xlsx | B113: 房源维度结算底表 | C113: 107113475157 | D113: 134976 | E113: 0.88 | F113: 108880.62 | G113: 2028-10-20 | H113: 3749.34 | I113: 4500 | J113: 单一信托 | K113: 134976 | M113: 11248.02 | N113: 11248.02 | O113: 2025-10-20
A114: 附件1：美好生活3号-基础资产清单.xlsx | B114: 房源维度结算底表 | C114: 107113418192 | D114: 84000 | E114: 0.88 | F114: 73920 | G114: 2028-10-07 | H114: 2450 | I114: 3500 | K114: 84000 | L114: 8500 | M114: 8500 | N114: 0 | O114: 2025-11-07
A115: 附件1：美好生活3号-基础资产清单.xlsx | B115: 房源维度结算底表 | C115: 101131715168 | D115: 70000 | E115: 0.88 | F115: 61600 | G115: 2028-10-01 | H115: 2029.5 | I115: 4950 | K115: 70000 | L115: 8118 | M115: 8118 | N115: 0 | O115: 2025-11-01
A116: 附件1：美好生活3号-基础资产清单.xlsx | B116: 房源维度结算底表 | C116: 107113391820 | D116: 118021 | E116: 0.88 | F116: 89412.4 | G116: 2028-09-29 | H116: 3384 | I116: 7200 | J116: 单一信托 | K116: 118021 | M116: 16416 | N116: 16416 | O116: 2025-10-29
A117: 附件1：美好生活3号-基础资产清单.xlsx | B117: 房源维度结算底表 | C117: 107113428544 | D117: 86296 | E117: 0.88 | F117: 67994.08 | G117: 2028-09-28 | H117: 2560 | I117: 4000 | J117: 单一信托 | K117: 86296 | M117: 9030 | N117: 9030 | O117: 2025-11-28
A118: 附件1：美好生活3号-基础资产清单.xlsx | B118: 房源维度结算底表 | C118: 107114425879 | D118: 108645 | E118: 0.88 | F118: 95607.6 | G118: 2028-09-21 | H118: 3333.34 | I118: 4500 | K118: 108645 | L118: 5133.34 | M118: 5133.34 | N118: 0 | O118: 2026-01-21
A119: 附件1：美好生活3号-基础资产清单.xlsx | B119: 房源维度结算底表 | C119: 107114728897 | D119: 96309 | E119: 0.88 | F119: 84751.92 | G119: 2028-09-18 | H119: 3210.3 | I119: 4600 | K119: 96309 | L119: 0 | M119: 0 | N119: 0 | O119: 2026-03-18
A120: 附件1：美好生活3号-基础资产清单.xlsx | B120: 房源维度结算底表 | C120: 107114599756 | D120: 189869 | E120: 0.88 | F120: 167084.72 | G120: 2028-09-16 | H120: 6328.97 | I120: 7200 | K120: 189869 | L120: 0 | M120: 0 | N120: 0 | O120: 2026-03-16
A121: 附件1：美好生活3号-基础资产清单.xlsx | B121: 房源维度结算底表 | C121: 107114578480 | D121: 103000 | E121: 0.88 | F121: 90640 | G121: 2028-09-15 | H121: 3433.34 | I121: 4500 | K121: 103000 | L121: 0 | M121: 0 | N121: 0 | O121: 2026-03-15
A122: 附件1：美好生活3号-基础资产清单.xlsx | B122: 房源维度结算底表 | C122: 107114340868 | D122: 88000 | E122: 0.88 | F122: 77440 | G122: 2028-09-15 | H122: 2933.34 | I122: 6500 | K122: 88000 | L122: 0 | M122: 0 | N122: 0 | O122: 2026-03-15
A123: 附件1：美好生活3号-基础资产清单.xlsx | B123: 房源维度结算底表 | C123: 107114528246 | D123: 85500 | E123: 0.88 | F123: 75240 | G123: 2028-09-14 | H123: 2850 | I123: 5200 | K123: 85500 | L123: 0 | M123: 0 | N123: 0 | O123: 2026-03-14
A124: 附件1：美好生活3号-基础资产清单.xlsx | B124: 房源维度结算底表 | C124: 107114607489 | D124: 105000 | E124: 0.88 | F124: 92400 | G124: 2028-09-14 | H124: 3500 | I124: 6000 | K124: 105000 | L124: 0 | M124: 0 | N124: 0 | O124: 2026-03-14
A125: 附件1：美好生活3号-基础资产清单.xlsx | B125: 房源维度结算底表 | C125: 107114521434 | D125: 78806 | E125: 0.88 | F125: 69349.28 | G125: 2028-09-11 | H125: 2626.87 | I125: 4600 | K125: 78806 | L125: 1840 | M125: 1840 | N125: 0 | O125: 2026-02-11
A126: 附件1：美好生活3号-基础资产清单.xlsx | B126: 房源维度结算底表 | C126: 107114574891 | D126: 99781 | E126: 0.88 | F126: 87807.28 | G126: 2028-09-10 | H126: 3326.04 | I126: 5000 | K126: 99781 | L126: 0 | M126: 0 | N126: 0 | O126: 2026-03-10
A127: 附件1：美好生活3号-基础资产清单.xlsx | B127: 房源维度结算底表 | C127: 107114542517 | D127: 163216 | E127: 0.88 | F127: 143630.08 | G127: 2028-09-10 | H127: 5440.54 | I127: 11500 | K127: 163216 | L127: 0 | M127: 0 | N127: 0 | O127: 2026-03-10
A128: 附件1：美好生活3号-基础资产清单.xlsx | B128: 房源维度结算底表 | C128: 107114694595 | D128: 83000 | E128: 0.88 | F128: 73040 | G128: 2028-09-10 | H128: 2766.67 | I128: 4800 | K128: 83000 | L128: 0 | M128: 0 | N128: 0 | O128: 2026-03-10
A129: 附件1：美好生活3号-基础资产清单.xlsx | B129: 房源维度结算底表 | C129: 107114319301 | D129: 72000 | E129: 0.88 | F129: 63360 | G129: 2028-09-10 | H129: 2400 | I129: 4900 | K129: 72000 | L129: 0 | M129: 0 | N129: 0 | O129: 2026-03-10
... A180: 附件1：美好生活3号-基础资产清单.xlsx | B180: 房源维度结算底表 | C180: 107114464006 | D180: 100000 | E180: 0.88 | F180: 88000 | G180: 2028-09-01 | H180: 3333.34 | I180: 6000 | K180: 100000 | L180: 2400 | M180: 2400 | N180: 0 | O180: 2026-03-01
A181: 附件1：美好生活3号-基础资产清单.xlsx | B181: 房源维度结算底表 | C181: 107113985127 | D181: 83091 | E181: 0.88 | F181: 68949.14 | G181: 2028-09-01 | H181: 2769.7 | I181: 5300 | J181: 单一信托 | K181: 83091 | M181: 4739.7 | N181: 4739.7 | O181: 2026-02-01
A182: 附件1：美好生活3号-基础资产清单.xlsx | B182: 房源维度结算底表 | C182: 107114090684 | D182: 82707 | E182: 0.88 | F182: 72782.16 | G182: 2028-08-31 | H182: 2756.9 | I182: 3400 | K182: 82707 | L182: 4066.9 | M182: 4066.9 | N182: 0 | O182: 2026-01-31
A183: 附件1：美好生活3号-基础资产清单.xlsx | B183: 房源维度结算底表 | C183: 107114451939 | D183: 110000 | E183: 0.88 | F183: 96800 | G183: 2028-08-31 | H183: 3666.67 | I183: 4300 | K183: 110000 | L183: 5486.67 | M183: 5486.67 | N183: 0 | O183: 2026-01-31
A184: 附件1：美好生活3号-基础资产清单.xlsx | B184: 房源维度结算底表 | C184: 107114386970 | D184: 94000 | E184: 0.88 | F184: 82720 | G184: 2028-08-31 | H184: 3133.34 | I184: 3600 | K184: 94000 | L184: 4573.34 | M184: 4573.34 | N184: 0 | O184: 2026-01-31
A185: 附件1：美好生活3号-基础资产清单.xlsx | B185: 房源维度结算底表 | C185: 107114252859 | D185: 83732 | E185: 0.88 | F185: 73684.16 | G185: 2028-08-30 | H185: 2791.07 | I185: 3700 | K185: 83732 | L185: 4121.07 | M185: 4121.07 | N185: 0 | O185: 2026-01-30
A186: 附件1：美好生活3号-基础资产清单.xlsx | B186: 房源维度结算底表 | C186: 107114066861 | D186: 316712 | E186: 0.88 | F186: 278706.56 | G186: 2028-08-30 | H186: 10557.07 | I186: 15500 | K186: 316712 | L186: 16007.07 | M186: 16007.07 | N186: 0 | O186: 2026-01-30
A187: 附件1：美好生活3号-基础资产清单.xlsx | B187: 房源维度结算底表 | C187: 107114562119 | D187: 325000 | E187: 0.88 | F187: 267187.36 | G187: 2028-08-28 | H187: 10120.74 | I187: 12960 | K187: 303622 | L187: 4614 | M187: 4614 | N187: 0 | O187: 2026-02-28
...

Sheet 数量和金额统计
C1: Values | G1: 当前信托计划（已发行） | H1: 求和项:剩余还款金额
A2: 所属文件名称 | B2: 所属Sheet名称 | C2: 计数项:托管房源编号 | D2: 求和项:当期实际还款金额 | G2: 信托1号 | H2: 22377504
A3: 美润1号_还款明细表_0529.xlsx | B3: 0325已还款 | C3: 47 | D3: 525012.9 | G3: 信托2号 | H3: 21481551
B4: 0430已还款 | C4: 60 | D4: 248346.52 | G4: 信托3号 | H4: 30650364
B5: 0508已还款 | C5: 15 | D5: 38367.96 | G5: 单一信托,信托3号 | H5: 3149041.2
B6: 0515已还款 | C6: 14 | D6: 29446 | G6: 单一信托 | H6: 5604531.3
B7: 0522已还款 | C7: 61 | D7: 1293329 | G7: 单一信托（2号） | H7: 1464129.7
B8: 0529已还款 | C8: 17 | D8: 35232.8 | G8: #N/A | H8: 32004
A9: 美润1号_还款明细表_0529.xlsx 汇总 | C9: 214 | D9: 2169735.2 | G9: (空白)
A10: 美好生活3号-还款明细披露信息_20260529_已更新0601.xlsx | B10: 0430已还款 | C10: 392 | D10: 2188927.8 | G10: 总计 | H10: 84759125
B11: 0508已还款 | C11: 154 | D11: 499210.87
B12: 0515已还款 | C12: 71 | D12: 232550.55
B13: 0522已还款 | C13: 76 | D13: 246265.95
B14: 0529已还款 | C14: 73 | D14: 234744.91
A15: 美好生活3号-还款明细披露信息_20260529_已更新0601.xlsx 汇总 | C15: 766 | D15: 3401700.1
A16: 美好生活2号-还款明细披露信息_20260529_已更新0601.xlsx | B16: 0119-已还款 | C16: 1198 | D16: 3720077.7
B17: 0123-已还款 | C17: 138 | D17: 442029.46 | H17: Values
B18: 0206-已还款 | C18: 131 | D18: 454421.13 | G18: 文件名 | H18: 计数项:房源编号 | I18: 求和项:应收账款合同金额 | J18: 求和项:应收账款转让价款 | K18: 平均值项:资产转让折扣率
B19: 0228-已还款 | C19: 216 | D19: 708416.09 | G19: 美润1号服务信托房源明细（首期转让）.xlsx | H19: 110 | I19: 11650165 | J19: 9718918.9 | K19: 0.85127273
B20: 0320-已还款 | C20: 157 | D20: 507948.69 | G20: 附件1：美好生活3号-基础资产清单.xlsx | H20: 407 | I20: 38924635 | J20: 33628584 | K20: 0.88223587
B21: 0327-已还款 | C21: 21 | D21: 61754 | G21: 附件1：美好生活2号-基础资产清单 1120.xlsx | H21: 310 | I21: 30219957 | J21: 26319602 | K21: 0.88
B22: 0403-已还款 | C22: 60 | D22: 198906.2 | G22: 附件1：基础资产清单（美好生活1号）.xlsx | H22: 412 | I22: 36302527 | J22: 31531666 | K22: 0.88
B23: 0410-已还款 | C23: 80 | D23: 256140.75 | G23: (空白)
B24: 0417-已还款 | C24: 48 | D24: 165122.67 | G24: 总计 | H24: 1239 | I24: 1.1709728e+08 | J24: 1.0119877e+08 | K24: 0.87818402
B25: 0424-已还款 | C25: 69 | D25: 233793.9 | H25: =I22/H22 -> 88112.929
B26: 0430-已还款 | C26: 60 | D26: 199421
B27: 0508-已还款 | C27: 93 | D27: 306345.95
B28: 0515-已还款 | C28: 45 | D28: 147068.67
B29: 0522-已还款 | C29: 49 | D29: 167413.16
A30: 美好生活2号-还款明细披露信息_20260529_已更新0601.xlsx 汇总 | C30: 2365 | D30: 7568859.4
A31: 美好生活2号-还款明细披露信息_20260529（0608更新） | B31: 0529-已还款 | C31: 117 | D31: 632993.18
A32: 美好生活2号-还款明细披露信息_20260529（0608更新） 汇总 | C32: 117 | D32: 632993.18
A33: 美好生活1号-还款明细披露信息_20260529_已更新0601_1.xlsx | B33: 0424-已还款 | C33: 107 | D33: 331200.16
B34: 0508-已还款 | C34: 150 | D34: 481547.02
B35: 0515-已还款 | C35: 50 | D35: 161472.5
B36: 0522-已还款 | C36: 87 | D36: 330394.66
B37: 信托还款明细--0929已还款 | C37: 1160 | D37: 3215725.3
B38: 还款明细--1017已还款 | C38: 185 | D38: 586239.92
B39: 还款明细-1031已还款 | C39: 215 | D39: 682172.05
B40: 还款明细-1114已还款 | C40: 166 | D40: 511457.25
...

Sheet 房源最后还款日
A1: 当期实际还款金额 | B1: (全部)
B3: Values
A4: 托管房源编号 | B4: 最大值项:还款日期 | C4: 标准偏差项:当期实际还款金额
A5: 107113471357 | B5: 46185 | C5: 554.17886
A6: 107113694737 | B6: 46178 | C6: 6016.0009
A7: 107113385212 | B7: 46171 | C7: 3377.64
A8: 107114212209 | B8: 46171 | C8: 1766.2673
A9: 107113045363 | B9: 46171 | C9: 1812.3401
A10: 107114495649 | B10: 46185 | C10: 2313.9541
A11: 107113193877 | B11: 46185 | C11: 1811.7111
A12: 107112417471 | B12: 46185 | C12: 7127.6364
A13: 107114226759 | B13: 46178 | C13: 5025
A14: 107113184658 | B14: 46178 | C14: 5867.5092
A15: 101128210944 | B15: 46178 | C15: 24500
A16: 107114205966 | B16: 46185 | C16: 6824.5839
... A111: 107112416833 | B111: 46185 | C111: 6153.9995
A112: 107112381197 | B112: 46164 | C112: #DIV/0!
A113: 107112234817 | B113: 46164 | C113: #DIV/0!
A114: 101134445166 | B114: 46178 | C114: 1339.4526
A115: 101133822347 | B115: 46185 | C115: 1616.5808
A116: 107114291360 | B116: 46178 | C116: 1062.3245
A117: 107114474902 | B117: 46185 | C117: 1223.9826
A118: 107114615743 | B118: 46185 | C118: 993.04246
A119: 107114233912 | B119: 46185 | C119: 1658.0345
A120: 107114591839 | B120: 46185 | C120: 1050.7775
A121: 107114187138 | B121: 46178 | C121: 2391.8594
A122: 107114218904 | B122: 46178 | C122: 1431.8287
A123: 107114562119 | B123: 46178 | C123: 2663.8941
A124: 107114119448 | B124: 46178 | C124: 1010.363
A125: 107114470189 | B125: 46178 | C125: 0
... A339: 107114212597 | B339: 46178 | C339: 4.3158373e-05
A340: 107114216499 | B340: 46142 | C340: #DIV/0!
A341: 107114214318 | B341: 46171 | C341: 2021.1021
A342: 107114217194 | B342: 46171 | C342: 3780.6454
A343: 107114196146 | B343: 46164 | C343: 2233.6089
A344: 107114187667 | B344: 46164 | C344: 1780.6363
A345: 107114173043 | B345: 46164 | C345: 2498.4487
A346: 107114046870 | B346: 46157 | C346: 2021.4769
A347: 107114168313 | B347: 46185 | C347: 1794.7484
A348: 107114163298 | B348: 46185 | C348: 1355.5154
...

Sheet 提前还款
A1: 所属文件名称 | B1: 房源编号
A2: 美润1号 | B2: 107112381197
A3: 美好生活2号 | B3: 107112396048
A4: 美好生活2号 | B4: 101127824384
A5: 美好生活1号 | B5: 107112700446
A6: 美好生活1号 | B6: 101130093956
A7: 美好生活1号 | B7: 101130834372
A8: 美好生活2号 | B8: 107113347933
A9: 美好生活2号 | B9: 101130970695
A10: 美好生活3号 | B10: 101132159673
A11: 美好生活3号 | B11: 101132273734
A12: 美润1号 | B12: 101130772992
... A14: 美好生活3号 | B14: 101130770124

Sheet 逾期自检0618
A1: 托管房源编号 | B1: 发行 | C1: 城市 | D1: 最大值项:还款日期 | E1: 剩余还款金额 | F1: 是否是提前还款 | G1: 信托已经要求逾期反馈
A2: 101116255967 | B2: =VLOOKUP(A2,'3已发行数据0610（明道云数据）'!B:N,13,FALSE) -> 单一信托（2号） | C2: =VLOOKUP(A2,'3已发行数据0610（明道云数据）'!B:D,3,FALSE) -> 北京 | D2: =VLOOKUP(A2,房源最后还款日!A:B,2,FALSE) -> 46178 | E2: =VLOOKUP(A2,'2更新的资产数据表'!C:G,5,FALSE) -> 7480 | F2: =VLOOKUP(A2,提前还款!B:B,1,FALSE) -> #N/A | G2: =VLOOKUP(A2,信托逾期反馈!A:A,1,FALSE) -> #N/A
A3: 101117377965 | B3: =VLOOKUP(A3,'3已发行数据0610（明道云数据）'!B:N,13,FALSE) -> 信托2号 | C3: =VLOOKUP(A3,'3已发行数据0610（明道云数据）'!B:D,3,FALSE) -> 北京 | D3: =VLOOKUP(A3,房源最后还款日!A:B,2,FALSE) -> 46164 | E3: =VLOOKUP(A3,'2更新的资产数据表'!C:G,5,FALSE) -> 36749 | F3: =VLOOKUP(A3,提前还款!B:B,1,FALSE) -> #N/A | G3: =VLOOKUP(A3,信托逾期反馈!A:A,1,FALSE) -> #N/A
A4: 101127075900 | B4: =VLOOKUP(A4,'3已发行数据0610（明道云数据）'!B:N,13,FALSE) -> 信托1号 | C4: =VLOOKUP(A4,'3已发行数据0610（明道云数据）'!B:D,3,FALSE) -> 北京 | D4: =VLOOKUP(A4,房源最后还款日!A:B,2,FALSE) -> 46164 | E4: =VLOOKUP(A4,'2更新的资产数据表'!C:G,5,FALSE) -> 34719 | F4: =VLOOKUP(A4,提前还款!B:B,1,FALSE) -> #N/A | G4: =VLOOKUP(A4,信托逾期反馈!A:A,1,FALSE) -> #N/A
A5: 101127099270 | B5: =VLOOKUP(A5,'3已发行数据0610（明道云数据）'!B:N,13,FALSE) -> 单一信托（2号） | C5: =VLOOKUP(A5,'3已发行数据0610（明道云数据）'!B:D,3,FALSE) -> 北京 | D5: =VLOOKUP(A5,房源最后还款日!A:B,2,FALSE) -> 46178 | E5: =VLOOKUP(A5,'2更新的资产数据表'!C:G,5,FALSE) -> 17140 | F5: =VLOOKUP(A5,提前还款!B:B,1,FALSE) -> #N/A | G5: =VLOOKUP(A5,信托逾期反馈!A:A,1,FALSE) -> #N/A
A6: 101127311840 | B6: =VLOOKUP(A6,'3已发行数据0610（明道云数据）'!B:N,13,FALSE) -> 信托1号 | C6: =VLOOKUP(A6,'3已发行数据0610（明道云数据）'!B:D,3,FALSE) -> 北京 | D6: =VLOOKUP(A6,房源最后还款日!A:B,2,FALSE) -> 46171 | E6: =VLOOKUP(A6,'2更新的资产数据表'!C:G,5,FALSE) -> 38576.03 | F6: =VLOOKUP(A6,提前还款!B:B,1,FALSE) -> #N/A | G6: =VLOOKUP(A6,信托逾期反馈!A:A,1,FALSE) -> 101127311840
A7: 101127339909 | B7: =VLOOKUP(A7,'3已发行数据0610（明道云数据）'!B:N,13,FALSE) -> 信托1号 | C7: =VLOOKUP(A7,'3已发行数据0610（明道云数据）'!B:D,3,FALSE) -> 北京 | D7: =VLOOKUP(A7,房源最后还款日!A:B,2,FALSE) -> 46185 | E7: =VLOOKUP(A7,'2更新的资产数据表'!C:G,5,FALSE) -> 16745 | F7: =VLOOKUP(A7,提前还款!B:B,1,FALSE) -> #N/A | G7: =VLOOKUP(A7,信托逾期反馈!A:A,1,FALSE) -> #N/A
A8: 101127524235 | B8: =VLOOKUP(A8,'3已发行数据0610（明道云数据）'!B:N,13,FALSE) -> 信托1号 | C8: =VLOOKUP(A8,'3已发行数据0610（明道云数据）'!B:D,3,FALSE) -> 北京 | D8: =VLOOKUP(A8,房源最后还款日!A:B,2,FALSE) -> 46164 | E8: =VLOOKUP(A8,'2更新的资产数据表'!C:G,5,FALSE) -> 28330.01 | F8: =VLOOKUP(A8,提前还款!B:B,1,FALSE) -> #N/A | G8: =VLOOKUP(A8,信托逾期反馈!A:A,1,FALSE) -> 101127524235
A9: 101127526338 | B9: =VLOOKUP(A9,'3已发行数据0610（明道云数据）'!B:N,13,FALSE) -> 信托2号 | C9: =VLOOKUP(A9,'3已发行数据0610（明道云数据）'!B:D,3,FALSE) -> 北京 | D9: =VLOOKUP(A9,房源最后还款日!A:B,2,FALSE) -> 46171 | E9: =VLOOKUP(A9,'2更新的资产数据表'!C:G,5,FALSE) -> 63350 | F9: =VLOOKUP(A9,提前还款!B:B,1,FALSE) -> #N/A | G9: =VLOOKUP(A9,信托逾期反馈!A:A,1,FALSE) -> #N/A
A10: 101127626459 | B10: =VLOOKUP(A10,'3已发行数据0610（明道云数据）'!B:N,13,FALSE) -> 信托1号 | C10: =VLOOKUP(A10,'3已发行数据0610（明道云数据）'!B:D,3,FALSE) -> 北京 | D10: =VLOOKUP(A10,房源最后还款日!A:B,2,FALSE) -> 46157 | E10: =VLOOKUP(A10,'2更新的资产数据表'!C:G,5,FALSE) -> 55205 | F10: =VLOOKUP(A10,提前还款!B:B,1,FALSE) -> #N/A | G10: =VLOOKUP(A10,信托逾期反馈!A:A,1,FALSE) -> #N/A
A11: 101127659284 | B11: =VLOOKUP(A11,'3已发行数据0610（明道云数据）'!B:N,13,FALSE) -> 信托2号 | C11: =VLOOKUP(A11,'3已发行数据0610（明道云数据）'!B:D,3,FALSE) -> 北京 | D11: =VLOOKUP(A11,房源最后还款日!A:B,2,FALSE) -> 46185 | E11: =VLOOKUP(A11,'2更新的资产数据表'!C:G,5,FALSE) -> 85640 | F11: =VLOOKUP(A11,提前还款!B:B,1,FALSE) -> #N/A | G11: =VLOOKUP(A11,信托逾期反馈!A:A,1,FALSE) -> #N/A
A12: 101127687701 | B12: =VLOOKUP(A12,'3已发行数据0610（明道云数据）'!B:N,13,FALSE) -> 信托1号 | C12: =VLOOKUP(A12,'3已发行数据0610（明道云数据）'!B:D,3,FALSE) -> 北京 | D12: =VLOOKUP(A12,房源最后还款日!A:B,2,FALSE) -> 46178 | E12: =VLOOKUP(A12,'2更新的资产数据表'!C:G,5,FALSE) -> 34251.33 | F12: =VLOOKUP(A12,提前还款!B:B,1,FALSE) -> #N/A | G12: =VLOOKUP(A12,信托逾期反馈!A:A,1,FALSE) -> #N/A
A13: 101127783856 | B13: =VLOOKUP(A13,'3已发行数据0610（明道云数据）'!B:N,13,FALSE) -> 信托2号 | C13: =VLOOKUP(A13,'3已发行数据0610（明道云数据）'!B:D,3,FALSE) -> 北京 | D13: =VLOOKUP(A13,房源最后还款日!A:B,2,FALSE) -> 46164 | E13: =VLOOKUP(A13,'2更新的资产数据表'!C:G,5,FALSE) -> 64628 | F13: =VLOOKUP(A13,提前还款!B:B,1,FALSE) -> #N/A | G13: =VLOOKUP(A13,信托逾期反馈!A:A,1,FALSE) -> #N/A
... A59: 101129405710 | B59: =VLOOKUP(A59,'3已发行数据0610（明道云数据）'!B:N,13,FALSE) -> 信托1号 | C59: =VLOOKUP(A59,'3已发行数据0610（明道云数据）'!B:D,3,FALSE) -> 北京 | D59: =VLOOKUP(A59,房源最后还款日!A:B,2,FALSE) -> 46157 | E59: =VLOOKUP(A59,'2更新的资产数据表'!C:G,5,FALSE) -> 37390 | F59: =VLOOKUP(A59,提前还款!B:B,1,FALSE) -> #N/A | G59: =VLOOKUP(A59,信托逾期反馈!A:A,1,FALSE) -> #N/A
A60: 101129422479 | B60: =VLOOKUP(A60,'3已发行数据0610（明道云数据）'!B:N,13,FALSE) -> 信托1号 | C60: =VLOOKUP(A60,'3已发行数据0610（明道云数据）'!B:D,3,FALSE) -> 北京 | D60: =VLOOKUP(A60,房源最后还款日!A:B,2,FALSE) -> 46150 | E60: =VLOOKUP(A60,'2更新的资产数据表'!C:G,5,FALSE) -> 33785 | F60: =VLOOKUP(A60,提前还款!B:B,1,FALSE) -> #N/A | G60: =VLOOKUP(A60,信托逾期反馈!A:A,1,FALSE) -> #N/A | H60: =VLOOKUP(G60,信托逾期反馈!A:G,7,FALSE) -> #N/A
A61: 101129442765 | B61: =VLOOKUP(A61,'3已发行数据0610（明道云数据）'!B:N,13,FALSE) -> 信托1号 | C61: =VLOOKUP(A61,'3已发行数据0610（明道云数据）'!B:D,3,FALSE) -> 北京 | D61: =VLOOKUP(A61,房源最后还款日!A:B,2,FALSE) -> 46178 | E61: =VLOOKUP(A61,'2更新的资产数据表'!C:G,5,FALSE) -> 56884 | F61: =VLOOKUP(A61,提前还款!B:B,1,FALSE) -> #N/A | G61: =VLOOKUP(A61,信托逾期反馈!A:A,1,FALSE) -> #N/A
A62: 101129452604 | B62: =VLOOKUP(A62,'3已发行数据0610（明道云数据）'!B:N,13,FALSE) -> 信托1号 | C62: =VLOOKUP(A62,'3已发行数据0610（明道云数据）'!B:D,3,FALSE) -> 北京 | D62: =VLOOKUP(A62,房源最后还款日!A:B,2,FALSE) -> 46185 | E62: =VLOOKUP(A62,'2更新的资产数据表'!C:G,5,FALSE) -> 53865 | F62: =VLOOKUP(A62,提前还款!B:B,1,FALSE) -> #N/A | G62: =VLOOKUP(A62,信托逾期反馈!A:A,1,FALSE) -> #N/A
A63: 101129460405 | B63: =VLOOKUP(A63,'3已发行数据0610（明道云数据）'!B:N,13,FALSE) -> 信托1号 | C63: =VLOOKUP(A63,'3已发行数据0610（明道云数据）'!B:D,3,FALSE) -> 北京 | D63: =VLOOKUP(A63,房源最后还款日!A:B,2,FALSE) -> 46171 | E63: =VLOOKUP(A63,'2更新的资产数据表'!C:G,5,FALSE) -> 30770 | F63: =VLOOKUP(A63,提前还款!B:B,1,FALSE) -> #N/A | G63: =VLOOKUP(A63,信托逾期反馈!A:A,1,FALSE) -> #N/A
A64: 101129472286 | B64: =VLOOKUP(A64,'3已发行数据0610（明道云数据）'!B:N,13,FALSE) -> 信托1号 | C64: =VLOOKUP(A64,'3已发行数据0610（明道云数据）'!B:D,3,FALSE) -> 北京 | D64: =VLOOKUP(A64,房源最后还款日!A:B,2,FALSE) -> 46185 | E64: =VLOOKUP(A64,'2更新的资产数据表'!C:G,5,FALSE) -> 54658 | F64: =VLOOKUP(A64,提前还款!B:B,1,FALSE) -> #N/A | G64: =VLOOKUP(A64,信托逾期反馈!A:A,1,FALSE) -> #N/A
A65: 101129491687 | B65: =VLOOKUP(A65,'3已发行数据0610（明道云数据）'!B:N,13,FALSE) -> 信托1号 | C65: =VLOOKUP(A65,'3已发行数据0610（明道云数据）'!B:D,3,FALSE) -> 北京 | D65: =VLOOKUP(A65,房源最后还款日!A:B,2,FALSE) -> 46164 | E65: =VLOOKUP(A65,'2更新的资产数据表'!C:G,5,FALSE) -> 97211 | F65: =VLOOKUP(A65,提前还款!B:B,1,FALSE) -> #N/A | G65: =VLOOKUP(A65,信托逾期反馈!A:A,1,FALSE) -> #N/A
A66: 101129492083 | B66: =VLOOKUP(A66,'3已发行数据0610（明道云数据）'!B:N,13,FALSE) -> 信托1号 | C66: =VLOOKUP(A66,'3已发行数据0610（明道云数据）'!B:D,3,FALSE) -> 北京 | D66: =VLOOKUP(A66,房源最后还款日!A:B,2,FALSE) -> 46178 | E66: =VLOOKUP(A66,'2更新的资产数据表'!C:G,5,FALSE) -> 37585 | F66: =VLOOKUP(A66,提前还款!B:B,1,FALSE) -> #N/A | G66: =VLOOKUP(A66,信托逾期反馈!A:A,1,FALSE) -> #N/A
A67: 101129508743 | B67: =VLOOKUP(A67,'3已发行数据0610（明道云数据）'!B:N,13,FALSE) -> 信托1号 | C67: =VLOOKUP(A67,'3已发行数据0610（明道云数据）'!B:D,3,FALSE) -> 北京 | D67: =VLOOKUP(A67,房源最后还款日!A:B,2,FALSE) -> 46157 | E67: =VLOOKUP(A67,'2更新的资产数据表'!C:G,5,FALSE) -> 45280 | F67: =VLOOKUP(A67,提前还款!B:B,1,FALSE) -> #N/A | G67: =VLOOKUP(A67,信托逾期反馈!A:A,1,FALSE) -> #N/A
A68: 101129527798 | B68: =VLOOKUP(A68,'3已发行数据0610（明道云数据）'!B:N,13,FALSE) -> 信托1号 | C68: =VLOOKUP(A68,'3已发行数据0610（明道云数据）'!B:D,3,FALSE) -> 北京 | D68: =VLOOKUP(A68,房源最后还款日!A:B,2,FALSE) -> 46178 | E68: =VLOOKUP(A68,'2更新的资产数据表'!C:G,5,FALSE) -> 58920 | F68: =VLOOKUP(A68,提前还款!B:B,1,FALSE) -> #N/A | G68: =VLOOKUP(A68,信托逾期反馈!A:A,1,FALSE) -> #N/A
A69: 101129543144 | B69: =VLOOKUP(A69,'3已发行数据0610（明道云数据）'!B:N,13,FALSE) -> 信托1号 | C69: =VLOOKUP(A69,'3已发行数据0610（明道云数据）'!B:D,3,FALSE) -> 北京 | D69: =VLOOKUP(A69,房源最后还款日!A:B,2,FALSE) -> 46171 | E69: =VLOOKUP(A69,'2更新的资产数据表'!C:G,5,FALSE) -> 30751.33 | F69: =VLOOKUP(A69,提前还款!B:B,1,FALSE) -> #N/A | G69: =VLOOKUP(A69,信托逾期反馈!A:A,1,FALSE) -> #N/A
A70: 101129550929 | B70: =VLOOKUP(A70,'3已发行数据0610（明道云数据）'!B:N,13,FALSE) -> 信托1号 | C70: =VLOOKUP(A70,'3已发行数据0610（明道云数据）'!B:D,3,FALSE) -> 北京 | D70: =VLOOKUP(A70,房源最后还款日!A:B,2,FALSE) -> 46185 | E70: =VLOOKUP(A70,'2更新的资产数据表'!C:G,5,FALSE) -> 48073 | F70: =VLOOKUP(A70,提前还款!B:B,1,FALSE) -> #N/A | G70: =VLOOKUP(A70,信托逾期反馈!A:A,1,FALSE) -> #N/A
A71: 101129554327 | B71: =VLOOKUP(A71,'3已发行数据0610（明道云数据）'!B:N,13,FALSE) -> 信托1号 | C71: =VLOOKUP(A71,'3已发行数据0610（明道云数据）'!B:D,3,FALSE) -> 北京 | D71: =VLOOKUP(A71,房源最后还款日!A:B,2,FALSE) -> 46171 | E71: =VLOOKUP(A71,'2更新的资产数据表'!C:G,5,FALSE) -> 51381.66 | F71: =VLOOKUP(A71,提前还款!B:B,1,FALSE) -> #N/A | G71: =VLOOKUP(A71,信托逾期反馈!A:A,1,FALSE) -> #N/A
A72: 101129560839 | B72: =VLOOKUP(A72,'3已发行数据0610（明道云数据）'!B:N,13,FALSE) -> 信托1号 | C72: =VLOOKUP(A72,'3已发行数据0610（明道云数据）'!B:D,3,FALSE) -> 北京 | D72: =VLOOKUP(A72,房源最后还款日!A:B,2,FALSE) -> 46178 | E72: =VLOOKUP(A72,'2更新的资产数据表'!C:G,5,FALSE) -> 56568 | F72: =VLOOKUP(A72,提前还款!B:B,1,FALSE) -> #N/A | G72: =VLOOKUP(A72,信托逾期反馈!A:A,1,FALSE) -> #N/A
... A101: 101130017111 | B101: =VLOOKUP(A101,'3已发行数据0610（明道云数据）'!B:N,13,FALSE) -> 信托1号 | C101: =VLOOKUP(A101,'3已发行数据0610（明道云数据）'!B:D,3,FALSE) -> 北京 | D101: =VLOOKUP(A101,房源最后还款日!A:B,2,FALSE) -> 46171 | E101: =VLOOKUP(A101,'2更新的资产数据表'!C:G,5,FALSE) -> 39486 | F101: =VLOOKUP(A101,提前还款!B:B,1,FALSE) -> #N/A | G101: =VLOOKUP(A101,信托逾期反馈!A:A,1,FALSE) -> #N/A
A102: 101130021966 | B102: =VLOOKUP(A102,'3已发行数据0610（明道云数据）'!B:N,13,FALSE) -> 信托1号 | C102: =VLOOKUP(A102,'3已发行数据0610（明道云数据）'!B:D,3,FALSE) -> 北京 | D102: =VLOOKUP(A102,房源最后还款日!A:B,2,FALSE) -> 46150 | E102: =VLOOKUP(A102,'2更新的资产数据表'!C:G,5,FALSE) -> 55736.67 | F102: =VLOOKUP(A102,提前还款!B:B,1,FALSE) -> #N/A | G102: =VLOOKUP(A102,信托逾期反馈!A:A,1,FALSE) -> #N/A | H102: =VLOOKUP(G102,信托逾期反馈!A:G,7,FALSE) -> #N/A
A103: 101130063714 | B103: =VLOOKUP(A103,'3已发行数据0610（明道云数据）'!B:N,13,FALSE) -> 信托1号 | C103: =VLOOKUP(A103,'3已发行数据0610（明道云数据）'!B:D,3,FALSE) -> 北京 | D103: =VLOOKUP(A103,房源最后还款日!A:B,2,FALSE) -> 46178 | E103: =VLOOKUP(A103,'2更新的资产数据表'!C:G,5,FALSE) -> 45310 | F103: =VLOOKUP(A103,提前还款!B:B,1,FALSE) -> #N/A | G103: =VLOOKUP(A103,信托逾期反馈!A:A,1,FALSE) -> #N/A
A104: 101130065851 | B104: =VLOOKUP(A104,'3已发行数据0610（明道云数据）'!B:N,13,FALSE) -> 信托1号 | C104: =VLOOKUP(A104,'3已发行数据0610（明道云数据）'!B:D,3,FALSE) -> 北京 | D104: =VLOOKUP(A104,房源最后还款日!A:B,2,FALSE) -> 46178 | E104: =VLOOKUP(A104,'2更新的资产数据表'!C:G,5,FALSE) -> 50842 | F104: =VLOOKUP(A104,提前还款!B:B,1,FALSE) -> #N/A | G104: =VLOOKUP(A104,信托逾期反馈!A:A,1,FALSE) -> #N/A
A105: 101130093956 | B105: =VLOOKUP(A105,'3已发行数据0610（明道云数据）'!B:N,13,FALSE) -> 信托1号 | C105: =VLOOKUP(A105,'3已发行数据0610（明道云数据）'!B:D,3,FALSE) -> 北京 | D105: =VLOOKUP(A105,房源最后还款日!A:B,2,FALSE) -> 46143 | E105: =VLOOKUP(A105,'2更新的资产数据表'!C:G,5,FALSE) -> 0 | F105: =VLOOKUP(A105,提前还款!B:B,1,FALSE) -> 101130093956 | G105: =VLOOKUP(A105,信托逾期反馈!A:A,1,FALSE) -> 101130093956
A106: 101130107192 | B106: =VLOOKUP(A106,'3已发行数据0610（明道云数据）'!B:N,13,FALSE) -> 信托1号 | C106: =VLOOKUP(A106,'3已发行数据0610（明道云数据）'!B:D,3,FALSE) -> 北京 | D106: =VLOOKUP(A106,房源最后还款日!A:B,2,FALSE) -> 46185 | E106: =VLOOKUP(A106,'2更新的资产数据表'!C:G,5,FALSE) -> 27429 | F106: =VLOOKUP(A106,提前还款!B:B,1,FALSE) -> #N/A | G106: =VLOOKUP(A106,信托逾期反馈!A:A,1,FALSE) -> #N/A
A107: 101130115346 | B107: =VLOOKUP(A107,'3已发行数据0610（明道云数据）'!B:N,13,FALSE) -> 信托1号 | C107: =VLOOKUP(A107,'3已发行数据0610（明道云数据）'!B:D,3,FALSE) -> 北京 | D107: =VLOOKUP(A107,房源最后还款日!A:B,2,FALSE) -> 46185 | E107: =VLOOKUP(A107,'2更新的资产数据表'!C:G,5,FALSE) -> 34563 | F107: =VLOOKUP(A107,提前还款!B:B,1,FALSE) -> #N/A | G107: =VLOOKUP(A107,信托逾期反馈!A:A,1,FALSE) -> #N/A
A108: 101130125068 | B108: =VLOOKUP(A108,'3已发行数据0610（明道云数据）'!B:N,13,FALSE) -> 信托1号 | C108: =VLOOKUP(A108,'3已发行数据0610（明道云数据）'!B:D,3,FALSE) -> 北京 | D108: =VLOOKUP(A108,房源最后还款日!A:B,2,FALSE) -> 46178 | E108: =VLOOKUP(A108,'2更新的资产数据表'!C:G,5,FALSE) -> 44060 | F108: =VLOOKUP(A108,提前还款!B:B,1,FALSE) -> #N/A | G108: =VLOOKUP(A108,信托逾期反馈!A:A,1,FALSE) -> #N/A
A109: 101130133766 | B109: =VLOOKUP(A109,'3已发行数据0610（明道云数据）'!B:N,13,FALSE) -> 信托1号 | C109: =VLOOKUP(A109,'3已发行数据0610（明道云数据）'!B:D,3,FALSE) -> 北京 | D109: =VLOOKUP(A109,房源最后还款日!A:B,2,FALSE) -> 46157 | E109: =VLOOKUP(A109,'2更新的资产数据表'!C:G,5,FALSE) -> 54236.67 | F109: =VLOOKUP(A109,提前还款!B:B,1,FALSE) -> #N/A | G109: =VLOOKUP(A109,信托逾期反馈!A:A,1,FALSE) -> #N/A
A110: 101130133837 | B110: =VLOOKUP(A110,'3已发行数据0610（明道云数据）'!B:N,13,FALSE) -> 信托1号 | C110: =VLOOKUP(A110,'3已发行数据0610（明道云数据）'!B:D,3,FALSE) -> 北京 | D110: =VLOOKUP(A110,房源最后还款日!A:B,2,FALSE) -> 46185 | E110: =VLOOKUP(A110,'2更新的资产数据表'!C:G,5,FALSE) -> 35525 | F110: =VLOOKUP(A110,提前还款!B:B,1,FALSE) -> #N/A | G110: =VLOOKUP(A110,信托逾期反馈!A:A,1,FALSE) -> #N/A
A111: 101130154248 | B111: =VLOOKUP(A111,'3已发行数据0610（明道云数据）'!B:N,13,FALSE) -> 信托2号 | C111: =VLOOKUP(A111,'3已发行数据0610（明道云数据）'!B:D,3,FALSE) -> 北京 | D111: =VLOOKUP(A111,房源最后还款日!A:B,2,FALSE) -> 46171 | E111: =VLOOKUP(A111,'2更新的资产数据表'!C:G,5,FALSE) -> 53132 | F111: =VLOOKUP(A111,提前还款!B:B,1,FALSE) -> #N/A | G111: =VLOOKUP(A111,信托逾期反馈!A:A,1,FALSE) -> #N/A
A112: 101130177828 | B112: =VLOOKUP(A112,'3已发行数据0610（明道云数据）'!B:N,13,FALSE) -> 信托2号 | C112: =VLOOKUP(A112,'3已发行数据0610（明道云数据）'!B:D,3,FALSE) -> 北京 | D112: =VLOOKUP(A112,房源最后还款日!A:B,2,FALSE) -> 46171 | E112: =VLOOKUP(A112,'2更新的资产数据表'!C:G,5,FALSE) -> 132320 | F112: =VLOOKUP(A112,提前还款!B:B,1,FALSE) -> #N/A | G112: =VLOOKUP(A112,信托逾期反馈!A:A,1,FALSE) -> #N/A
A113: 101130181968 | B113: =VLOOKUP(A113,'3已发行数据0610（明道云数据）'!B:N,13,FALSE) -> 信托2号 | C113: =VLOOKUP(A113,'3已发行数据0610（明道云数据）'!B:D,3,FALSE) -> 北京 | D113: =VLOOKUP(A113,房源最后还款日!A:B,2,FALSE) -> 46171 | E113: =VLOOKUP(A113,'2更新的资产数据表'!C:G,5,FALSE) -> 84738.67 | F113: =VLOOKUP(A113,提前还款!B:B,1,FALSE) -> #N/A | G113: =VLOOKUP(A113,信托逾期反馈!A:A,1,FALSE) -> #N/A
...

Sheet 信托逾期反馈
A1: 房源编号 | B1: 最新一次付款日 | C1: 所属城市 | D1: 发行批次 | E1: 未回款明细 | F1: 原因 | G1: 解决方式
A2: 107112757529 | B2: =VLOOKUP(A2,逾期自检0618!A:D,2,FALSE) -> 信托1号 | C2: =VLOOKUP(A2,'3已发行数据0610（明道云数据）'!B:N,3,FALSE) -> 上海 | D2: =VLOOKUP(A2,'3已发行数据0610（明道云数据）'!B:N,13,FALSE) -> 信托1号 | E2: 0403~0605(10周) | F2: 解约重签，新房源107114866922， | G2: 待手动结算付款
A3: 107112235776 | B3: =VLOOKUP(A3,逾期自检0618!A:D,2,FALSE) -> 信托1号 | C3: =VLOOKUP(A3,'3已发行数据0610（明道云数据）'!B:N,3,FALSE) -> 上海 | D3: =VLOOKUP(A3,'3已发行数据0610（明道云数据）'!B:N,13,FALSE) -> 信托1号 | E3: 0403~0605(10周) | F3: 解约重签，新房源107114962154 | G3: 付款异常，待系统问题解决过后，手动结算付款（冠唯解约）
A4: 107112699615 | B4: =VLOOKUP(A4,逾期自检0618!A:D,2,FALSE) -> 信托1号 | C4: =VLOOKUP(A4,'3已发行数据0610（明道云数据）'!B:N,3,FALSE) -> 上海 | D4: =VLOOKUP(A4,'3已发行数据0610（明道云数据）'!B:N,13,FALSE) -> 信托1号 | E4: 0403~0605(10周) | F4: 解约账单未支付 | G4: 逾期，需要置换
A5: 107112622529 | B5: =VLOOKUP(A5,逾期自检0618!A:D,2,FALSE) -> 信托1号 | C5: =VLOOKUP(A5,'3已发行数据0610（明道云数据）'!B:N,3,FALSE) -> 上海 | D5: =VLOOKUP(A5,'3已发行数据0610（明道云数据）'!B:N,13,FALSE) -> 信托1号 | E5: 0403~0605(10周) | F5: 已现金支付 | G5: 待手动结算付款
A6: 107112700446 | B6: =VLOOKUP(A6,逾期自检0618!A:D,2,FALSE) -> 信托1号 | C6: =VLOOKUP(A6,'3已发行数据0610（明道云数据）'!B:N,3,FALSE) -> 上海 | D6: =VLOOKUP(A6,'3已发行数据0610（明道云数据）'!B:N,13,FALSE) -> 信托1号 | E6: 0403~0605(10周) | F6: 解约账单已付 | G6: 待手动结算付款
A7: 107112901979 | B7: =VLOOKUP(A7,逾期自检0618!A:D,2,FALSE) -> 信托1号 | C7: =VLOOKUP(A7,'3已发行数据0610（明道云数据）'!B:N,3,FALSE) -> 上海 | D7: =VLOOKUP(A7,'3已发行数据0610（明道云数据）'!B:N,13,FALSE) -> 信托1号 | E7: 0403、0417~0605(8周) | F7: 空置，6.6已代扣 | G7: 4月10日已付款，需要确认信托收款状态；6月6日已付款，本周结算付款
A8: 107112617499 | B8: =VLOOKUP(A8,逾期自检0618!A:D,2,FALSE) -> 信托1号 | C8: =VLOOKUP(A8,'3已发行数据0610（明道云数据）'!B:N,3,FALSE) -> 上海 | D8: =VLOOKUP(A8,'3已发行数据0610（明道云数据）'!B:N,13,FALSE) -> 信托1号 | E8: 0403~0417(3周)、0430~0605(6周) | F8: 正常扣款中 | G8: 4月24日有付款，需要确认信托收款状态；5月付款异常，待系统问题解决过后，手动结算付款
A9: 107112318319 | B9: =VLOOKUP(A9,逾期自检0618!A:D,2,FALSE) -> 信托1号 | C9: =VLOOKUP(A9,'3已发行数据0610（明道云数据）'!B:N,3,FALSE) -> 上海 | D9: =VLOOKUP(A9,'3已发行数据0610（明道云数据）'!B:N,13,FALSE) -> 信托1号 | E9: 0410~0424(3周)、0508~0605(5周) | F9: 正常扣款中 | G9: 5月1日有付款，需要确认信托收款状态；5月付款异常，待系统问题解决过后，手动结算付款
A10: 107112191225 | B10: =VLOOKUP(A10,逾期自检0618!A:D,2,FALSE) -> 信托1号 | C10: =VLOOKUP(A10,'3已发行数据0610（明道云数据）'!B:N,3,FALSE) -> 上海 | D10: =VLOOKUP(A10,'3已发行数据0610（明道云数据）'!B:N,13,FALSE) -> 信托1号 | E10: 0403~0424(4周)、0508~0605(5周) | F10: 待出租 | G10: 5月1日有付款，需要确认信托收款状态；出租中，出租后正常付款结算
A11: 107112290433 | B11: =VLOOKUP(A11,逾期自检0618!A:D,2,FALSE) -> 信托1号 | C11: =VLOOKUP(A11,'3已发行数据0610（明道云数据）'!B:N,3,FALSE) -> 上海 | D11: =VLOOKUP(A11,'3已发行数据0610（明道云数据）'!B:N,13,FALSE) -> 信托1号 | E11: 0410~0424(3周)、0508~0605(5周) | F11: 正常扣款中 | G11: 5月1日有付款，需要确认信托收款状态；5月付款异常，待系统问题解决过后，手动结算付款
A12: 101130798182 | B12: =VLOOKUP(A12,逾期自检0618!A:D,2,FALSE) -> 信托1号 | C12: =VLOOKUP(A12,'3已发行数据0610（明道云数据）'!B:N,3,FALSE) -> 北京 | D12: =VLOOKUP(A12,'3已发行数据0610（明道云数据）'!B:N,13,FALSE) -> 信托1号 | E12: 0403~0605(10周) | F12: 解约重签，新房源号101135047520 | G12: 待手动结算付款
A13: 101130093956 | B13: =VLOOKUP(A13,逾期自检0618!A:D,2,FALSE) -> 信托1号 | C13: =VLOOKUP(A13,'3已发行数据0610（明道云数据）'!B:N,3,FALSE) -> 北京 | D13: =VLOOKUP(A13,'3已发行数据0610（明道云数据）'!B:N,13,FALSE) -> 信托1号 | E13: 0403~0424(4周)、0508~0605(5周) | F13: 解约后支付了账单 | G13: 待手动结算付款
... A29: 101133578658 | B29: =VLOOKUP(A29,逾期自检0618!A:D,2,FALSE) -> 信托3号 | C29: =VLOOKUP(A29,'3已发行数据0610（明道云数据）'!B:N,3,FALSE) -> 北京 | D29: =VLOOKUP(A29,'3已发行数据0610（明道云数据）'!B:N,13,FALSE) -> 信托3号 | E29: 0508~0605(5周) | F29: 正常代扣 | G29: 待手动结算付款
A30: 107112427808 | B30: 107112427808-单一001 | C30: 上海 | D30: 176000 | E30: 0 | F30: 176000
A31: 101133789300 | B31: 101133789300-单一001 | C31: 北京 | D31: 23960 | E31: 0 | F31: 23960
A32: 101132799241 | B32: 101132799241-单一001 | C32: 北京 | D32: 22393 | E32: 0 | F32: 22393
A33: 101134229290 | B33: 101134229290-单一001 | C33: 北京 | D33: 36617 | E33: 0 | F33: 36617
A34: 101132506745 | B34: 101132506745-单一001 | C34: 北京 | D34: 23074 | E34: 0 | F34: 23074
A35: 101127311840 | B35: 101127311840-单一001 | C35: 北京 | D35: 49999.84 | E35: 0 | F35: 49999.84 | G35: 5月29日已经有回款
A36: 101127524235 | B36: 101127524235-单一001 | C36: 北京 | D36: 64845 | E36: 0 | F36: 64845 | G36: 5月22日已经有回款
A37: 107112396048 | B37: 107112396048-单一001 | C37: 上海 | D37: 184540 | E37: 0 | F37: 184540 | G37: 6月5日已经有回款

Sheet 结算系统待清理
A1: 预计代扣周期-最初 | B1: 房源编码 | C1: 房源地址 | D1: 所属城市 | E1: 品牌 | F1: 签约日期 | G1: 实际成交价（应收账款合同金额） | H1: 代扣金额 | I1: 装修付款形式 | J1: 业主付款金额 | K1: 施工方名称 | L1: 入池批次 | M1: 信托计划期数 | N1: 当前信托计划（已发行）
B2: 107112825000 | C2: 上海市闵行区浦申路633弄19号501 | D2: 上海 | E2: 山念 | F2: 45806 | G2: 180000 | I2: 业主付款 | J2: 180000 | K2: 上海庆苑建筑装饰集团有限公司 | L2: 第三批预备池 | M2: 第三批预备池
B3: 107112665590 | C3: 上海静安北市场小区国庆路3弄02甲单元0703 | D3: 上海 | E3: 山念 | I3: 租金代扣 | K3: 上海美速家建筑装饰有限公司
B4: 101130069266 | C4: 西城区新街口外大街甲8号21-1门8号 | D4: 北京 | E4: 焕新租 | F4: 45791 | G4: 90000 | H4: 90000 | I4: 租金代扣 | K4: 北京省心装工程管理有限公司 | L4: 第三批预备池 | M4: 第三批预备池
B5: 107113121321 | C5: 上海市浦东新区龙居路150弄23号304室 | D5: 上海 | E5: 山念 | F5: 45815 | G5: 85000 | H5: 0 | I5: 业主付款 | J5: 85000 | K5: 上海沪怡佳装饰设计工程有限公司 | L5: 第三批预备池 | M5: 第三批预备池
B6: 107112370763 | C6: 上海市闵行区保利联发光合臻园25号1602 | D6: 上海 | E6: 山念 | F6: 45739 | G6: 17000 | I6: 业主付款 | J6: 17000 | K6: 南京和艺优装饰工程有限公司 | L6: 第三批预备池 | M6: 第三批预备池
B7: 107112379310 | C7: 上海市浦东新区东育路1665弄5号701室 | D7: 上海 | E7: 山念 | F7: 45738 | G7: 114000 | I7: 业主付款 | J7: 114000 | K7: 上海庆苑建筑装饰集团有限公司 | L7: 第三批预备池 | M7: 第三批预备池
B8: 107112379019 | C8: 上海杨浦民星二村民星二村04号楼民星二村04单元0504 | D8: 上海 | E8: 山念 | F8: 45738 | G8: 80000 | H8: 0 | I8: 业主付款 | J8: 80000 | K8: 上海美速家建筑装饰有限公司 | L8: 第三批预备池 | M8: 第三批预备池
B9: 107112336027 | C9: 上海市浦东新区257弄15号单元1402室(东区) | D9: 上海 | E9: 怡穗 | F9: 45736 | G9: 27380 | I9: 业主付款 | J9: 0 | K9: 上海欣暄装饰工程设计有限公司 | L9: 第三批预备池 | M9: 第三批预备池
B10: 107111994631 | C10: 上海市闵行区绿莲路99弄6号401 | D10: 上海 | E10: 山念 | F10: 45731 | G10: 14998 | I10: 业主付款 | J10: 14998 | K10: 南京和艺优装饰工程有限公司 | L10: 第三批预备池 | M10: 第三批预备池
B11: 107111839361 | C11: 上海市徐汇区马赛花园80弄2号902 | D11: 上海 | E11: 山念 | F11: 45731 | G11: 8458 | I11: 业主付款 | J11: 8458 | K11: 南京和艺优装饰工程有限公司 | L11: 第三批预备池 | M11: 第三批预备池
B12: 107112260445 | C12: 上海市长宁区中园小区8号501 | D12: 上海 | E12: 山念 | F12: 45728 | G12: 75000 | I12: 业主付款 | J12: 75000 | K12: 上海沪慧荣建筑装饰有限公司 | L12: 第三批预备池 | M12: 第三批预备池
B13: 107112224014 | C13: 上海市徐汇区漕溪一村8号104 | D13: 上海 | E13: 山念 | F13: 45727 | G13: 5025 | I13: 业主付款 | J13: 5025 | K13: 南京和艺优装饰工程有限公司 | L13: 第三批预备池 | M13: 第三批预备池
B14: 107112814492 | C14: 上海市闵行区吴中路830弄5号501 | D14: 上海 | E14: 山念 | F14: 45846 | G14: 11506 | I14: 业主付款 | J14: 11506 | K14: 南京和艺优装饰工程有限公司 | L14: 第三批预备池 | M14: 第三批预备池
B15: 107112205779 | C15: 上海市浦东新区海洋一路777弄(科澜观邸)8号1402室 | D15: 上海 | E15: 山念 | F15: 45721 | G15: 27761 | H15: 0 | I15: 业主付款 | J15: 27761 | K15: 上海庆苑建筑装饰集团有限公司 | L15: 第三批预备池 | M15: 第三批预备池
B16: 107112157342 | C16: 上海市长宁区新泾三村 31 号 601 | D16: 上海 | E16: 山念 | F16: 45720 | G16: 80888 | I16: 业主付款 | J16: 80888 | K16: 上海沪慧荣建筑装饰有限公司 | L16: 第三批预备池 | M16: 第三批预备池
B17: 101129973542 | C17: 海淀区曙光花园望山园3号楼306 | D17: 北京 | E17: 怡穗 | F17: 45698 | G17: 154153 | I17: 业主付款 | J17: 154153 | K17: 中筑宏图（北京）建设工程有限公司 | L17: 第三批预备池 | M17: 第三批预备池
B18: 11111 | C18: 北京市西城区后桃园胡同10号楼1层3门311室 | D18: 北京 | E18: 怡穗 | I18: 业主付款 | J18: 92000 | K18: 天津熙市建筑工程有限公司
B19: 107111564790 | C19: 上海市浦东新区南泉路1111弄15号601室 | D19: 上海 | E19: 怡穗 | F19: 45640 | G19: 81000 | I19: 业主付款 | J19: 81000 | K19: 上海欣暄装饰工程设计有限公司 | L19: 第三批预备池 | M19: 第三批预备池
B20: 107112317233 | C20: 上海市浦东新区梅园七街坊乳山路237弄6号401室 | D20: 上海 | E20: 山念 | F20: 45775 | G20: 10870 | H20: 0 | I20: 业主付款 | J20: 10870 | K20: 上海庆苑建筑装饰集团有限公司 | L20: 第三批预备池 | M20: 第三批预备池
B21: 107112904680 | C21: 上海市闵行区天安一号20号902 | D21: 上海 | E21: 怡穗 | F21: 45794 | G21: 33620 | H21: 0 | I21: 业主付款 | J21: 33620 | K21: 南京和艺优装饰工程有限公司 | L21: 第三批预备池 | M21: 第三批预备池
B22: 101129559202 | C22: 北京市海淀区交大东路41号院1号楼1164 | D22: 北京 | E22: 焕新租 | F22: 45791 | G22: 140000 | H22: 0 | I22: 租金代扣 | J22: 0 | K22: 北京省心装工程管理有限公司
A23: 25 | B23: 107114104632 | C23: 上海杨浦控江二村107弄小区27号楼27单元0105 | D23: 上海 | F23: 45925 | G23: 77397 | H23: 77397 | I23: 租金代扣 | K23: 上海筑家家建筑装饰有限公司 | L23: 第四批预备池 | M23: 第四批预备池
A24: 25 | B24: 107114226545 | C24: 上海市虹口区车站南路407弄1号302室 | D24: 上海 | E24: 悦居 | F24: 45944 | G24: 105000 | H24: 105000 | I24: 租金代扣 | K24: 上海筑家家建筑装饰有限公司 | L24: 第四批预备池 | M24: 第四批预备池
A25: 25 | B25: 107114191687 | C25: 上海杨浦政立路580弄2号403室 | D25: 上海 | E25: 山念 | F25: 45943 | G25: 98916 | H25: 98916 | I25: 租金代扣 | K25: 上海筑家家建筑装饰有限公司 | L25: 第四批预备池 | M25: 第四批预备池
A26: 25 | B26: 107114187663 | C26: 上海杨浦开鲁五村8号501室 | D26: 上海 | E26: 悦居 | F26: 45941 | G26: 100724 | H26: 100724 | I26: 租金代扣 | K26: 上海筑家家建筑装饰有限公司 | L26: 第四批预备池 | M26: 第四批预备池
A27: 9 | B27: 101134624801 | C27: 北京市朝阳区芳园里13号楼5门73 | D27: 北京 | E27: 舒里简逸 | F27: 45997 | G27: 26000 | H27: 26000 | I27: 租金代扣 | K27: 北京米屋科技有限公司北京第一分公司 | L27: 第四批预备池 | M27: 第四批预备池
A28: 25 | B28: 107114386253 | C28: 上海杨浦延吉五村延吉五村51号楼51单元0103 | D28: 上海 | E28: 悦居 | F28: 45965 | G28: 109000 | H28: 109000 | I28: 租金代扣 | K28: 上海筑家家建筑装饰有限公司 | L28: 第四批预备池 | M28: 第四批预备池
B29: 101129360184 | C29: 北京西城佟麟阁路62号院10号楼12层2门1204 | D29: 北京 | E29: 焕新租 | F29: 45735 | G29: 73000 | H29: 0 | I29: 租金代扣 | J29: 0 | K29: 北京省心装工程管理有限公司 | L29: 第三批预备池 | M29: 第三批预备池
A30: 11 | B30: 107114287129 | C30: 上海市浦东新区棠梨路66弄13号502 | D30: 上海 | E30: 山念 | F30: 45956 | G30: 20000 | H30: 20000 | I30: 租金代扣 | K30: 上海弘曳建筑装饰工程有限公司 | L30: 第四批预备池 | M30: 第四批预备池
